2022-04-18 21:27:17,175 Scheduler started
2022-04-18 21:27:17,550 Scheduler started
2022-04-18 21:27:17,801 Scheduler started
2022-04-18 21:27:17,889 Scheduler started
2022-04-18 21:27:18,059 Scheduler started
2022-04-18 21:27:18,068 Scheduler started
2022-04-18 21:27:18,097 Scheduler started
2022-04-18 21:27:18,158 Scheduler started
2022-04-18 21:27:18,172 Scheduler started
2022-04-18 21:55:51,572 Scheduler started
2022-04-18 21:55:52,008 Scheduler started
2022-04-18 21:55:52,195 Scheduler started
2022-04-18 21:55:52,337 Scheduler started
2022-04-18 21:55:52,408 Scheduler started
2022-04-18 21:55:52,461 Scheduler started
2022-04-18 21:55:52,463 Scheduler started
2022-04-18 21:55:52,476 Scheduler started
2022-04-18 21:55:52,494 Scheduler started
2022-04-18 21:56:17,720 Scheduler started
2022-04-18 21:56:18,125 Scheduler started
2022-04-18 21:56:18,381 Scheduler started
2022-04-18 21:56:18,467 Scheduler started
2022-04-18 21:56:18,465 Scheduler started
2022-04-18 21:56:18,494 Scheduler started
2022-04-18 21:56:18,510 Scheduler started
2022-04-18 21:56:18,516 Scheduler started
2022-04-18 21:56:18,534 Scheduler started
2022-04-26 23:01:50,233 Scheduler started
2022-04-26 23:01:50,807 Scheduler started
2022-04-26 23:01:51,274 Scheduler started
2022-04-26 23:01:51,717 Scheduler started
2022-04-26 23:01:51,731 Scheduler started
2022-04-26 23:01:51,747 Scheduler started
2022-04-26 23:01:51,765 Scheduler started
2022-04-26 23:01:51,775 Scheduler started
2022-04-26 23:01:51,795 Scheduler started
2022-04-27 12:06:09,813 Scheduler started
2022-04-27 12:06:10,507 Scheduler started
2022-04-27 12:06:11,059 Scheduler started
2022-04-27 12:06:11,170 Scheduler started
2022-04-27 12:06:11,284 Scheduler started
2022-04-27 12:06:11,293 Scheduler started
2022-04-27 12:06:11,355 Scheduler started
2022-04-27 12:06:11,379 Scheduler started
2022-04-27 12:06:11,495 Scheduler started
2022-04-27 20:33:28,759 Exception on /ad [GET]
Traceback (most recent call last):
  File "/Library/Frameworks/Python.framework/Versions/3.6/lib/python3.6/site-packages/sqlalchemy/engine/base.py", line 2336, in _wrap_pool_connect
    return fn()
  File "/Library/Frameworks/Python.framework/Versions/3.6/lib/python3.6/site-packages/sqlalchemy/pool/base.py", line 364, in connect
    return _ConnectionFairy._checkout(self)
  File "/Library/Frameworks/Python.framework/Versions/3.6/lib/python3.6/site-packages/sqlalchemy/pool/base.py", line 778, in _checkout
    fairy = _ConnectionRecord.checkout(pool)
  File "/Library/Frameworks/Python.framework/Versions/3.6/lib/python3.6/site-packages/sqlalchemy/pool/base.py", line 495, in checkout
    rec = pool._do_get()
  File "/Library/Frameworks/Python.framework/Versions/3.6/lib/python3.6/site-packages/sqlalchemy/pool/impl.py", line 241, in _do_get
    return self._create_connection()
  File "/Library/Frameworks/Python.framework/Versions/3.6/lib/python3.6/site-packages/sqlalchemy/pool/base.py", line 309, in _create_connection
    return _ConnectionRecord(self)
  File "/Library/Frameworks/Python.framework/Versions/3.6/lib/python3.6/site-packages/sqlalchemy/pool/base.py", line 440, in __init__
    self.__connect(first_connect_check=True)
  File "/Library/Frameworks/Python.framework/Versions/3.6/lib/python3.6/site-packages/sqlalchemy/pool/base.py", line 661, in __connect
    pool.logger.debug("Error on connect(): %s", e)
  File "/Library/Frameworks/Python.framework/Versions/3.6/lib/python3.6/site-packages/sqlalchemy/util/langhelpers.py", line 70, in __exit__
    with_traceback=exc_tb,
  File "/Library/Frameworks/Python.framework/Versions/3.6/lib/python3.6/site-packages/sqlalchemy/util/compat.py", line 182, in raise_
    raise exception
  File "/Library/Frameworks/Python.framework/Versions/3.6/lib/python3.6/site-packages/sqlalchemy/pool/base.py", line 656, in __connect
    connection = pool._invoke_creator(self)
  File "/Library/Frameworks/Python.framework/Versions/3.6/lib/python3.6/site-packages/sqlalchemy/engine/strategies.py", line 114, in connect
    return dialect.connect(*cargs, **cparams)
  File "/Library/Frameworks/Python.framework/Versions/3.6/lib/python3.6/site-packages/sqlalchemy/engine/default.py", line 508, in connect
    return self.dbapi.connect(*cargs, **cparams)
sqlite3.OperationalError: unable to open database file

The above exception was the direct cause of the following exception:

Traceback (most recent call last):
  File "/Library/Frameworks/Python.framework/Versions/3.6/lib/python3.6/site-packages/flask/app.py", line 2447, in wsgi_app
    response = self.full_dispatch_request()
  File "/Library/Frameworks/Python.framework/Versions/3.6/lib/python3.6/site-packages/flask/app.py", line 1952, in full_dispatch_request
    rv = self.handle_user_exception(e)
  File "/Library/Frameworks/Python.framework/Versions/3.6/lib/python3.6/site-packages/flask/app.py", line 1821, in handle_user_exception
    reraise(exc_type, exc_value, tb)
  File "/Library/Frameworks/Python.framework/Versions/3.6/lib/python3.6/site-packages/flask/_compat.py", line 39, in reraise
    raise value
  File "/Library/Frameworks/Python.framework/Versions/3.6/lib/python3.6/site-packages/flask/app.py", line 1950, in full_dispatch_request
    rv = self.dispatch_request()
  File "/Library/Frameworks/Python.framework/Versions/3.6/lib/python3.6/site-packages/flask/app.py", line 1936, in dispatch_request
    return self.view_functions[rule.endpoint](**req.view_args)
  File "/Library/Frameworks/Python.framework/Versions/3.6/lib/python3.6/site-packages/psiturk/user_utils.py", line 23, in new_func
    resp = make_response(func(*args, **kwargs))
  File "/Library/Frameworks/Python.framework/Versions/3.6/lib/python3.6/site-packages/psiturk/experiment.py", line 342, in advertisement
    filter(Participant.workerid == worker_id).\
  File "/Library/Frameworks/Python.framework/Versions/3.6/lib/python3.6/site-packages/sqlalchemy/orm/query.py", line 3803, in count
    return self.from_self(col).scalar()
  File "/Library/Frameworks/Python.framework/Versions/3.6/lib/python3.6/site-packages/sqlalchemy/orm/query.py", line 3523, in scalar
    ret = self.one()
  File "/Library/Frameworks/Python.framework/Versions/3.6/lib/python3.6/site-packages/sqlalchemy/orm/query.py", line 3490, in one
    ret = self.one_or_none()
  File "/Library/Frameworks/Python.framework/Versions/3.6/lib/python3.6/site-packages/sqlalchemy/orm/query.py", line 3459, in one_or_none
    ret = list(self)
  File "/Library/Frameworks/Python.framework/Versions/3.6/lib/python3.6/site-packages/sqlalchemy/orm/query.py", line 3535, in __iter__
    return self._execute_and_instances(context)
  File "/Library/Frameworks/Python.framework/Versions/3.6/lib/python3.6/site-packages/sqlalchemy/orm/query.py", line 3557, in _execute_and_instances
    querycontext, self._connection_from_session, close_with_result=True
  File "/Library/Frameworks/Python.framework/Versions/3.6/lib/python3.6/site-packages/sqlalchemy/orm/query.py", line 3572, in _get_bind_args
    mapper=self._bind_mapper(), clause=querycontext.statement, **kw
  File "/Library/Frameworks/Python.framework/Versions/3.6/lib/python3.6/site-packages/sqlalchemy/orm/query.py", line 3550, in _connection_from_session
    conn = self.session.connection(**kw)
  File "/Library/Frameworks/Python.framework/Versions/3.6/lib/python3.6/site-packages/sqlalchemy/orm/session.py", line 1145, in connection
    execution_options=execution_options,
  File "/Library/Frameworks/Python.framework/Versions/3.6/lib/python3.6/site-packages/sqlalchemy/orm/session.py", line 1151, in _connection_for_bind
    engine, execution_options
  File "/Library/Frameworks/Python.framework/Versions/3.6/lib/python3.6/site-packages/sqlalchemy/orm/session.py", line 433, in _connection_for_bind
    conn = bind._contextual_connect()
  File "/Library/Frameworks/Python.framework/Versions/3.6/lib/python3.6/site-packages/sqlalchemy/engine/base.py", line 2302, in _contextual_connect
    self._wrap_pool_connect(self.pool.connect, None),
  File "/Library/Frameworks/Python.framework/Versions/3.6/lib/python3.6/site-packages/sqlalchemy/engine/base.py", line 2340, in _wrap_pool_connect
    e, dialect, self
  File "/Library/Frameworks/Python.framework/Versions/3.6/lib/python3.6/site-packages/sqlalchemy/engine/base.py", line 1584, in _handle_dbapi_exception_noconnection
    sqlalchemy_exception, with_traceback=exc_info[2], from_=e
  File "/Library/Frameworks/Python.framework/Versions/3.6/lib/python3.6/site-packages/sqlalchemy/util/compat.py", line 182, in raise_
    raise exception
  File "/Library/Frameworks/Python.framework/Versions/3.6/lib/python3.6/site-packages/sqlalchemy/engine/base.py", line 2336, in _wrap_pool_connect
    return fn()
  File "/Library/Frameworks/Python.framework/Versions/3.6/lib/python3.6/site-packages/sqlalchemy/pool/base.py", line 364, in connect
    return _ConnectionFairy._checkout(self)
  File "/Library/Frameworks/Python.framework/Versions/3.6/lib/python3.6/site-packages/sqlalchemy/pool/base.py", line 778, in _checkout
    fairy = _ConnectionRecord.checkout(pool)
  File "/Library/Frameworks/Python.framework/Versions/3.6/lib/python3.6/site-packages/sqlalchemy/pool/base.py", line 495, in checkout
    rec = pool._do_get()
  File "/Library/Frameworks/Python.framework/Versions/3.6/lib/python3.6/site-packages/sqlalchemy/pool/impl.py", line 241, in _do_get
    return self._create_connection()
  File "/Library/Frameworks/Python.framework/Versions/3.6/lib/python3.6/site-packages/sqlalchemy/pool/base.py", line 309, in _create_connection
    return _ConnectionRecord(self)
  File "/Library/Frameworks/Python.framework/Versions/3.6/lib/python3.6/site-packages/sqlalchemy/pool/base.py", line 440, in __init__
    self.__connect(first_connect_check=True)
  File "/Library/Frameworks/Python.framework/Versions/3.6/lib/python3.6/site-packages/sqlalchemy/pool/base.py", line 661, in __connect
    pool.logger.debug("Error on connect(): %s", e)
  File "/Library/Frameworks/Python.framework/Versions/3.6/lib/python3.6/site-packages/sqlalchemy/util/langhelpers.py", line 70, in __exit__
    with_traceback=exc_tb,
  File "/Library/Frameworks/Python.framework/Versions/3.6/lib/python3.6/site-packages/sqlalchemy/util/compat.py", line 182, in raise_
    raise exception
  File "/Library/Frameworks/Python.framework/Versions/3.6/lib/python3.6/site-packages/sqlalchemy/pool/base.py", line 656, in __connect
    connection = pool._invoke_creator(self)
  File "/Library/Frameworks/Python.framework/Versions/3.6/lib/python3.6/site-packages/sqlalchemy/engine/strategies.py", line 114, in connect
    return dialect.connect(*cargs, **cparams)
  File "/Library/Frameworks/Python.framework/Versions/3.6/lib/python3.6/site-packages/sqlalchemy/engine/default.py", line 508, in connect
    return self.dbapi.connect(*cargs, **cparams)
sqlalchemy.exc.OperationalError: (sqlite3.OperationalError) unable to open database file
(Background on this error at: http://sqlalche.me/e/13/e3q8)
2022-04-27 20:33:33,592 Exception on /ad [GET]
Traceback (most recent call last):
  File "/Library/Frameworks/Python.framework/Versions/3.6/lib/python3.6/site-packages/sqlalchemy/engine/base.py", line 2336, in _wrap_pool_connect
    return fn()
  File "/Library/Frameworks/Python.framework/Versions/3.6/lib/python3.6/site-packages/sqlalchemy/pool/base.py", line 364, in connect
    return _ConnectionFairy._checkout(self)
  File "/Library/Frameworks/Python.framework/Versions/3.6/lib/python3.6/site-packages/sqlalchemy/pool/base.py", line 778, in _checkout
    fairy = _ConnectionRecord.checkout(pool)
  File "/Library/Frameworks/Python.framework/Versions/3.6/lib/python3.6/site-packages/sqlalchemy/pool/base.py", line 495, in checkout
    rec = pool._do_get()
  File "/Library/Frameworks/Python.framework/Versions/3.6/lib/python3.6/site-packages/sqlalchemy/pool/impl.py", line 241, in _do_get
    return self._create_connection()
  File "/Library/Frameworks/Python.framework/Versions/3.6/lib/python3.6/site-packages/sqlalchemy/pool/base.py", line 309, in _create_connection
    return _ConnectionRecord(self)
  File "/Library/Frameworks/Python.framework/Versions/3.6/lib/python3.6/site-packages/sqlalchemy/pool/base.py", line 440, in __init__
    self.__connect(first_connect_check=True)
  File "/Library/Frameworks/Python.framework/Versions/3.6/lib/python3.6/site-packages/sqlalchemy/pool/base.py", line 661, in __connect
    pool.logger.debug("Error on connect(): %s", e)
  File "/Library/Frameworks/Python.framework/Versions/3.6/lib/python3.6/site-packages/sqlalchemy/util/langhelpers.py", line 70, in __exit__
    with_traceback=exc_tb,
  File "/Library/Frameworks/Python.framework/Versions/3.6/lib/python3.6/site-packages/sqlalchemy/util/compat.py", line 182, in raise_
    raise exception
  File "/Library/Frameworks/Python.framework/Versions/3.6/lib/python3.6/site-packages/sqlalchemy/pool/base.py", line 656, in __connect
    connection = pool._invoke_creator(self)
  File "/Library/Frameworks/Python.framework/Versions/3.6/lib/python3.6/site-packages/sqlalchemy/engine/strategies.py", line 114, in connect
    return dialect.connect(*cargs, **cparams)
  File "/Library/Frameworks/Python.framework/Versions/3.6/lib/python3.6/site-packages/sqlalchemy/engine/default.py", line 508, in connect
    return self.dbapi.connect(*cargs, **cparams)
sqlite3.OperationalError: unable to open database file

The above exception was the direct cause of the following exception:

Traceback (most recent call last):
  File "/Library/Frameworks/Python.framework/Versions/3.6/lib/python3.6/site-packages/flask/app.py", line 2447, in wsgi_app
    response = self.full_dispatch_request()
  File "/Library/Frameworks/Python.framework/Versions/3.6/lib/python3.6/site-packages/flask/app.py", line 1952, in full_dispatch_request
    rv = self.handle_user_exception(e)
  File "/Library/Frameworks/Python.framework/Versions/3.6/lib/python3.6/site-packages/flask/app.py", line 1821, in handle_user_exception
    reraise(exc_type, exc_value, tb)
  File "/Library/Frameworks/Python.framework/Versions/3.6/lib/python3.6/site-packages/flask/_compat.py", line 39, in reraise
    raise value
  File "/Library/Frameworks/Python.framework/Versions/3.6/lib/python3.6/site-packages/flask/app.py", line 1950, in full_dispatch_request
    rv = self.dispatch_request()
  File "/Library/Frameworks/Python.framework/Versions/3.6/lib/python3.6/site-packages/flask/app.py", line 1936, in dispatch_request
    return self.view_functions[rule.endpoint](**req.view_args)
  File "/Library/Frameworks/Python.framework/Versions/3.6/lib/python3.6/site-packages/psiturk/user_utils.py", line 23, in new_func
    resp = make_response(func(*args, **kwargs))
  File "/Library/Frameworks/Python.framework/Versions/3.6/lib/python3.6/site-packages/psiturk/experiment.py", line 342, in advertisement
    filter(Participant.workerid == worker_id).\
  File "/Library/Frameworks/Python.framework/Versions/3.6/lib/python3.6/site-packages/sqlalchemy/orm/query.py", line 3803, in count
    return self.from_self(col).scalar()
  File "/Library/Frameworks/Python.framework/Versions/3.6/lib/python3.6/site-packages/sqlalchemy/orm/query.py", line 3523, in scalar
    ret = self.one()
  File "/Library/Frameworks/Python.framework/Versions/3.6/lib/python3.6/site-packages/sqlalchemy/orm/query.py", line 3490, in one
    ret = self.one_or_none()
  File "/Library/Frameworks/Python.framework/Versions/3.6/lib/python3.6/site-packages/sqlalchemy/orm/query.py", line 3459, in one_or_none
    ret = list(self)
  File "/Library/Frameworks/Python.framework/Versions/3.6/lib/python3.6/site-packages/sqlalchemy/orm/query.py", line 3535, in __iter__
    return self._execute_and_instances(context)
  File "/Library/Frameworks/Python.framework/Versions/3.6/lib/python3.6/site-packages/sqlalchemy/orm/query.py", line 3557, in _execute_and_instances
    querycontext, self._connection_from_session, close_with_result=True
  File "/Library/Frameworks/Python.framework/Versions/3.6/lib/python3.6/site-packages/sqlalchemy/orm/query.py", line 3572, in _get_bind_args
    mapper=self._bind_mapper(), clause=querycontext.statement, **kw
  File "/Library/Frameworks/Python.framework/Versions/3.6/lib/python3.6/site-packages/sqlalchemy/orm/query.py", line 3550, in _connection_from_session
    conn = self.session.connection(**kw)
  File "/Library/Frameworks/Python.framework/Versions/3.6/lib/python3.6/site-packages/sqlalchemy/orm/session.py", line 1145, in connection
    execution_options=execution_options,
  File "/Library/Frameworks/Python.framework/Versions/3.6/lib/python3.6/site-packages/sqlalchemy/orm/session.py", line 1151, in _connection_for_bind
    engine, execution_options
  File "/Library/Frameworks/Python.framework/Versions/3.6/lib/python3.6/site-packages/sqlalchemy/orm/session.py", line 433, in _connection_for_bind
    conn = bind._contextual_connect()
  File "/Library/Frameworks/Python.framework/Versions/3.6/lib/python3.6/site-packages/sqlalchemy/engine/base.py", line 2302, in _contextual_connect
    self._wrap_pool_connect(self.pool.connect, None),
  File "/Library/Frameworks/Python.framework/Versions/3.6/lib/python3.6/site-packages/sqlalchemy/engine/base.py", line 2340, in _wrap_pool_connect
    e, dialect, self
  File "/Library/Frameworks/Python.framework/Versions/3.6/lib/python3.6/site-packages/sqlalchemy/engine/base.py", line 1584, in _handle_dbapi_exception_noconnection
    sqlalchemy_exception, with_traceback=exc_info[2], from_=e
  File "/Library/Frameworks/Python.framework/Versions/3.6/lib/python3.6/site-packages/sqlalchemy/util/compat.py", line 182, in raise_
    raise exception
  File "/Library/Frameworks/Python.framework/Versions/3.6/lib/python3.6/site-packages/sqlalchemy/engine/base.py", line 2336, in _wrap_pool_connect
    return fn()
  File "/Library/Frameworks/Python.framework/Versions/3.6/lib/python3.6/site-packages/sqlalchemy/pool/base.py", line 364, in connect
    return _ConnectionFairy._checkout(self)
  File "/Library/Frameworks/Python.framework/Versions/3.6/lib/python3.6/site-packages/sqlalchemy/pool/base.py", line 778, in _checkout
    fairy = _ConnectionRecord.checkout(pool)
  File "/Library/Frameworks/Python.framework/Versions/3.6/lib/python3.6/site-packages/sqlalchemy/pool/base.py", line 495, in checkout
    rec = pool._do_get()
  File "/Library/Frameworks/Python.framework/Versions/3.6/lib/python3.6/site-packages/sqlalchemy/pool/impl.py", line 241, in _do_get
    return self._create_connection()
  File "/Library/Frameworks/Python.framework/Versions/3.6/lib/python3.6/site-packages/sqlalchemy/pool/base.py", line 309, in _create_connection
    return _ConnectionRecord(self)
  File "/Library/Frameworks/Python.framework/Versions/3.6/lib/python3.6/site-packages/sqlalchemy/pool/base.py", line 440, in __init__
    self.__connect(first_connect_check=True)
  File "/Library/Frameworks/Python.framework/Versions/3.6/lib/python3.6/site-packages/sqlalchemy/pool/base.py", line 661, in __connect
    pool.logger.debug("Error on connect(): %s", e)
  File "/Library/Frameworks/Python.framework/Versions/3.6/lib/python3.6/site-packages/sqlalchemy/util/langhelpers.py", line 70, in __exit__
    with_traceback=exc_tb,
  File "/Library/Frameworks/Python.framework/Versions/3.6/lib/python3.6/site-packages/sqlalchemy/util/compat.py", line 182, in raise_
    raise exception
  File "/Library/Frameworks/Python.framework/Versions/3.6/lib/python3.6/site-packages/sqlalchemy/pool/base.py", line 656, in __connect
    connection = pool._invoke_creator(self)
  File "/Library/Frameworks/Python.framework/Versions/3.6/lib/python3.6/site-packages/sqlalchemy/engine/strategies.py", line 114, in connect
    return dialect.connect(*cargs, **cparams)
  File "/Library/Frameworks/Python.framework/Versions/3.6/lib/python3.6/site-packages/sqlalchemy/engine/default.py", line 508, in connect
    return self.dbapi.connect(*cargs, **cparams)
sqlalchemy.exc.OperationalError: (sqlite3.OperationalError) unable to open database file
(Background on this error at: http://sqlalche.me/e/13/e3q8)
2022-04-27 20:33:42,143 Exception on /ad [GET]
Traceback (most recent call last):
  File "/Library/Frameworks/Python.framework/Versions/3.6/lib/python3.6/site-packages/sqlalchemy/engine/base.py", line 2336, in _wrap_pool_connect
    return fn()
  File "/Library/Frameworks/Python.framework/Versions/3.6/lib/python3.6/site-packages/sqlalchemy/pool/base.py", line 364, in connect
    return _ConnectionFairy._checkout(self)
  File "/Library/Frameworks/Python.framework/Versions/3.6/lib/python3.6/site-packages/sqlalchemy/pool/base.py", line 778, in _checkout
    fairy = _ConnectionRecord.checkout(pool)
  File "/Library/Frameworks/Python.framework/Versions/3.6/lib/python3.6/site-packages/sqlalchemy/pool/base.py", line 495, in checkout
    rec = pool._do_get()
  File "/Library/Frameworks/Python.framework/Versions/3.6/lib/python3.6/site-packages/sqlalchemy/pool/impl.py", line 241, in _do_get
    return self._create_connection()
  File "/Library/Frameworks/Python.framework/Versions/3.6/lib/python3.6/site-packages/sqlalchemy/pool/base.py", line 309, in _create_connection
    return _ConnectionRecord(self)
  File "/Library/Frameworks/Python.framework/Versions/3.6/lib/python3.6/site-packages/sqlalchemy/pool/base.py", line 440, in __init__
    self.__connect(first_connect_check=True)
  File "/Library/Frameworks/Python.framework/Versions/3.6/lib/python3.6/site-packages/sqlalchemy/pool/base.py", line 661, in __connect
    pool.logger.debug("Error on connect(): %s", e)
  File "/Library/Frameworks/Python.framework/Versions/3.6/lib/python3.6/site-packages/sqlalchemy/util/langhelpers.py", line 70, in __exit__
    with_traceback=exc_tb,
  File "/Library/Frameworks/Python.framework/Versions/3.6/lib/python3.6/site-packages/sqlalchemy/util/compat.py", line 182, in raise_
    raise exception
  File "/Library/Frameworks/Python.framework/Versions/3.6/lib/python3.6/site-packages/sqlalchemy/pool/base.py", line 656, in __connect
    connection = pool._invoke_creator(self)
  File "/Library/Frameworks/Python.framework/Versions/3.6/lib/python3.6/site-packages/sqlalchemy/engine/strategies.py", line 114, in connect
    return dialect.connect(*cargs, **cparams)
  File "/Library/Frameworks/Python.framework/Versions/3.6/lib/python3.6/site-packages/sqlalchemy/engine/default.py", line 508, in connect
    return self.dbapi.connect(*cargs, **cparams)
sqlite3.OperationalError: unable to open database file

The above exception was the direct cause of the following exception:

Traceback (most recent call last):
  File "/Library/Frameworks/Python.framework/Versions/3.6/lib/python3.6/site-packages/flask/app.py", line 2447, in wsgi_app
    response = self.full_dispatch_request()
  File "/Library/Frameworks/Python.framework/Versions/3.6/lib/python3.6/site-packages/flask/app.py", line 1952, in full_dispatch_request
    rv = self.handle_user_exception(e)
  File "/Library/Frameworks/Python.framework/Versions/3.6/lib/python3.6/site-packages/flask/app.py", line 1821, in handle_user_exception
    reraise(exc_type, exc_value, tb)
  File "/Library/Frameworks/Python.framework/Versions/3.6/lib/python3.6/site-packages/flask/_compat.py", line 39, in reraise
    raise value
  File "/Library/Frameworks/Python.framework/Versions/3.6/lib/python3.6/site-packages/flask/app.py", line 1950, in full_dispatch_request
    rv = self.dispatch_request()
  File "/Library/Frameworks/Python.framework/Versions/3.6/lib/python3.6/site-packages/flask/app.py", line 1936, in dispatch_request
    return self.view_functions[rule.endpoint](**req.view_args)
  File "/Library/Frameworks/Python.framework/Versions/3.6/lib/python3.6/site-packages/psiturk/user_utils.py", line 23, in new_func
    resp = make_response(func(*args, **kwargs))
  File "/Library/Frameworks/Python.framework/Versions/3.6/lib/python3.6/site-packages/psiturk/experiment.py", line 342, in advertisement
    filter(Participant.workerid == worker_id).\
  File "/Library/Frameworks/Python.framework/Versions/3.6/lib/python3.6/site-packages/sqlalchemy/orm/query.py", line 3803, in count
    return self.from_self(col).scalar()
  File "/Library/Frameworks/Python.framework/Versions/3.6/lib/python3.6/site-packages/sqlalchemy/orm/query.py", line 3523, in scalar
    ret = self.one()
  File "/Library/Frameworks/Python.framework/Versions/3.6/lib/python3.6/site-packages/sqlalchemy/orm/query.py", line 3490, in one
    ret = self.one_or_none()
  File "/Library/Frameworks/Python.framework/Versions/3.6/lib/python3.6/site-packages/sqlalchemy/orm/query.py", line 3459, in one_or_none
    ret = list(self)
  File "/Library/Frameworks/Python.framework/Versions/3.6/lib/python3.6/site-packages/sqlalchemy/orm/query.py", line 3535, in __iter__
    return self._execute_and_instances(context)
  File "/Library/Frameworks/Python.framework/Versions/3.6/lib/python3.6/site-packages/sqlalchemy/orm/query.py", line 3557, in _execute_and_instances
    querycontext, self._connection_from_session, close_with_result=True
  File "/Library/Frameworks/Python.framework/Versions/3.6/lib/python3.6/site-packages/sqlalchemy/orm/query.py", line 3572, in _get_bind_args
    mapper=self._bind_mapper(), clause=querycontext.statement, **kw
  File "/Library/Frameworks/Python.framework/Versions/3.6/lib/python3.6/site-packages/sqlalchemy/orm/query.py", line 3550, in _connection_from_session
    conn = self.session.connection(**kw)
  File "/Library/Frameworks/Python.framework/Versions/3.6/lib/python3.6/site-packages/sqlalchemy/orm/session.py", line 1145, in connection
    execution_options=execution_options,
  File "/Library/Frameworks/Python.framework/Versions/3.6/lib/python3.6/site-packages/sqlalchemy/orm/session.py", line 1151, in _connection_for_bind
    engine, execution_options
  File "/Library/Frameworks/Python.framework/Versions/3.6/lib/python3.6/site-packages/sqlalchemy/orm/session.py", line 433, in _connection_for_bind
    conn = bind._contextual_connect()
  File "/Library/Frameworks/Python.framework/Versions/3.6/lib/python3.6/site-packages/sqlalchemy/engine/base.py", line 2302, in _contextual_connect
    self._wrap_pool_connect(self.pool.connect, None),
  File "/Library/Frameworks/Python.framework/Versions/3.6/lib/python3.6/site-packages/sqlalchemy/engine/base.py", line 2340, in _wrap_pool_connect
    e, dialect, self
  File "/Library/Frameworks/Python.framework/Versions/3.6/lib/python3.6/site-packages/sqlalchemy/engine/base.py", line 1584, in _handle_dbapi_exception_noconnection
    sqlalchemy_exception, with_traceback=exc_info[2], from_=e
  File "/Library/Frameworks/Python.framework/Versions/3.6/lib/python3.6/site-packages/sqlalchemy/util/compat.py", line 182, in raise_
    raise exception
  File "/Library/Frameworks/Python.framework/Versions/3.6/lib/python3.6/site-packages/sqlalchemy/engine/base.py", line 2336, in _wrap_pool_connect
    return fn()
  File "/Library/Frameworks/Python.framework/Versions/3.6/lib/python3.6/site-packages/sqlalchemy/pool/base.py", line 364, in connect
    return _ConnectionFairy._checkout(self)
  File "/Library/Frameworks/Python.framework/Versions/3.6/lib/python3.6/site-packages/sqlalchemy/pool/base.py", line 778, in _checkout
    fairy = _ConnectionRecord.checkout(pool)
  File "/Library/Frameworks/Python.framework/Versions/3.6/lib/python3.6/site-packages/sqlalchemy/pool/base.py", line 495, in checkout
    rec = pool._do_get()
  File "/Library/Frameworks/Python.framework/Versions/3.6/lib/python3.6/site-packages/sqlalchemy/pool/impl.py", line 241, in _do_get
    return self._create_connection()
  File "/Library/Frameworks/Python.framework/Versions/3.6/lib/python3.6/site-packages/sqlalchemy/pool/base.py", line 309, in _create_connection
    return _ConnectionRecord(self)
  File "/Library/Frameworks/Python.framework/Versions/3.6/lib/python3.6/site-packages/sqlalchemy/pool/base.py", line 440, in __init__
    self.__connect(first_connect_check=True)
  File "/Library/Frameworks/Python.framework/Versions/3.6/lib/python3.6/site-packages/sqlalchemy/pool/base.py", line 661, in __connect
    pool.logger.debug("Error on connect(): %s", e)
  File "/Library/Frameworks/Python.framework/Versions/3.6/lib/python3.6/site-packages/sqlalchemy/util/langhelpers.py", line 70, in __exit__
    with_traceback=exc_tb,
  File "/Library/Frameworks/Python.framework/Versions/3.6/lib/python3.6/site-packages/sqlalchemy/util/compat.py", line 182, in raise_
    raise exception
  File "/Library/Frameworks/Python.framework/Versions/3.6/lib/python3.6/site-packages/sqlalchemy/pool/base.py", line 656, in __connect
    connection = pool._invoke_creator(self)
  File "/Library/Frameworks/Python.framework/Versions/3.6/lib/python3.6/site-packages/sqlalchemy/engine/strategies.py", line 114, in connect
    return dialect.connect(*cargs, **cparams)
  File "/Library/Frameworks/Python.framework/Versions/3.6/lib/python3.6/site-packages/sqlalchemy/engine/default.py", line 508, in connect
    return self.dbapi.connect(*cargs, **cparams)
sqlalchemy.exc.OperationalError: (sqlite3.OperationalError) unable to open database file
(Background on this error at: http://sqlalche.me/e/13/e3q8)
[2022-04-27 20:39:03 +0800] [56960] [INFO] Starting gunicorn 20.0.4
[2022-04-27 20:39:03 +0800] [56960] [INFO] Listening at: http://0.0.0.0:50003 (56960)
[2022-04-27 20:39:03 +0800] [56960] [INFO] Using worker: gevent
[2022-04-27 20:39:03 +0800] [56966] [INFO] Booting worker with pid: 56966
[2022-04-27 20:39:03 +0800] [56967] [INFO] Booting worker with pid: 56967
[2022-04-27 20:39:03 +0800] [56968] [INFO] Booting worker with pid: 56968
[2022-04-27 20:39:03 +0800] [56969] [INFO] Booting worker with pid: 56969
[2022-04-27 20:39:03 +0800] [56970] [INFO] Booting worker with pid: 56970
[2022-04-27 20:39:03 +0800] [56971] [INFO] Booting worker with pid: 56971
[2022-04-27 20:39:03 +0800] [56972] [INFO] Booting worker with pid: 56972
[2022-04-27 20:39:03 +0800] [56973] [INFO] Booting worker with pid: 56973
[2022-04-27 20:39:03 +0800] [56974] [INFO] Booting worker with pid: 56974
2022-04-27 20:39:06,857 Starting scheduler in 'paused' mode -- it will not run any tasks, but it can be used to create, modify, or delete tasks.
2022-04-27 20:39:06,861 Scheduler started
2022-04-27 20:39:06,864 /Library/Frameworks/Python.framework/Versions/3.6/lib/python3.6/site-packages/psiturk/psiturk_js/psiturk.js
2022-04-27 20:39:07,104 Starting scheduler in 'paused' mode -- it will not run any tasks, but it can be used to create, modify, or delete tasks.
2022-04-27 20:39:07,178 Scheduler started
2022-04-27 20:39:07,180 /Library/Frameworks/Python.framework/Versions/3.6/lib/python3.6/site-packages/psiturk/psiturk_js/psiturk.js
2022-04-27 20:39:07,438 Starting scheduler in 'paused' mode -- it will not run any tasks, but it can be used to create, modify, or delete tasks.
2022-04-27 20:39:07,452 Scheduler started
2022-04-27 20:39:07,460 /Library/Frameworks/Python.framework/Versions/3.6/lib/python3.6/site-packages/psiturk/psiturk_js/psiturk.js
2022-04-27 20:39:07,800 Starting scheduler in 'paused' mode -- it will not run any tasks, but it can be used to create, modify, or delete tasks.
2022-04-27 20:39:07,804 Scheduler started
2022-04-27 20:39:07,811 /Library/Frameworks/Python.framework/Versions/3.6/lib/python3.6/site-packages/psiturk/psiturk_js/psiturk.js
2022-04-27 20:39:08,069 Starting scheduler in 'paused' mode -- it will not run any tasks, but it can be used to create, modify, or delete tasks.
2022-04-27 20:39:08,074 Scheduler started
2022-04-27 20:39:08,076 /Library/Frameworks/Python.framework/Versions/3.6/lib/python3.6/site-packages/psiturk/psiturk_js/psiturk.js
2022-04-27 20:39:08,078 Starting scheduler in 'paused' mode -- it will not run any tasks, but it can be used to create, modify, or delete tasks.
2022-04-27 20:39:08,087 Scheduler started
2022-04-27 20:39:08,091 /Library/Frameworks/Python.framework/Versions/3.6/lib/python3.6/site-packages/psiturk/psiturk_js/psiturk.js
2022-04-27 20:39:08,095 Starting scheduler in 'paused' mode -- it will not run any tasks, but it can be used to create, modify, or delete tasks.
2022-04-27 20:39:08,111 Scheduler started
2022-04-27 20:39:08,113 /Library/Frameworks/Python.framework/Versions/3.6/lib/python3.6/site-packages/psiturk/psiturk_js/psiturk.js
2022-04-27 20:39:08,177 Starting scheduler in 'paused' mode -- it will not run any tasks, but it can be used to create, modify, or delete tasks.
2022-04-27 20:39:08,180 Scheduler started
2022-04-27 20:39:08,181 Starting scheduler in 'paused' mode -- it will not run any tasks, but it can be used to create, modify, or delete tasks.
2022-04-27 20:39:08,185 /Library/Frameworks/Python.framework/Versions/3.6/lib/python3.6/site-packages/psiturk/psiturk_js/psiturk.js
2022-04-27 20:39:08,197 Scheduler started
2022-04-27 20:39:08,199 /Library/Frameworks/Python.framework/Versions/3.6/lib/python3.6/site-packages/psiturk/psiturk_js/psiturk.js
2022-04-27 20:39:10,650 Accessing /exp: debug5TL4O6 debugBY1QVM debugOXVKP5 
2022-04-27 20:39:10,654 given Counter({(0, 0): 0}) chose (0, 0)
2022-04-27 20:39:10,856 GET /sync route with id: debugOXVKP5:debugBY1QVM
2022-04-27 20:39:22,432 PUT /sync route with id: debugOXVKP5:debugBY1QVM
2022-04-27 20:39:22,433 Accessing /inexp
2022-04-27 20:39:22,443 saved data for debugOXVKP5:debugBY1QVM (current trial: 5)
2022-04-27 20:40:35,987 Accessing /exp: debug5TL4O6 debugBY1QVM debugOXVKP5 
2022-04-27 20:40:36,528 GET /sync route with id: debugOXVKP5:debugBY1QVM
2022-04-27 20:40:41,492 Accessing /exp: debug5TL4O6 debugBY1QVM debugOXVKP5 
2022-04-27 20:40:41,651 GET /sync route with id: debugOXVKP5:debugBY1QVM
2022-04-27 20:40:50,777 Accessing /exp: debug5TL4O6 debugBY1QVM debugOXVKP5 
2022-04-27 20:40:51,139 GET /sync route with id: debugOXVKP5:debugBY1QVM
2022-04-27 20:40:55,553 Accessing /exp: debug5TL4O6 debugBY1QVM debugOXVKP5 
2022-04-27 20:40:55,663 GET /sync route with id: debugOXVKP5:debugBY1QVM
2022-04-27 20:41:03,352 Accessing /exp: debug5TL4O6 debugBY1QVM debugOXVKP5 
2022-04-27 20:41:03,724 GET /sync route with id: debugOXVKP5:debugBY1QVM
2022-04-27 20:41:05,498 Accessing /exp: debug5TL4O6 debugBY1QVM debugOXVKP5 
2022-04-27 20:41:05,724 GET /sync route with id: debugOXVKP5:debugBY1QVM
2022-04-27 20:41:08,602 Accessing /exp: debug5TL4O6 debugBY1QVM debugOXVKP5 
2022-04-27 20:41:08,743 GET /sync route with id: debugOXVKP5:debugBY1QVM
2022-04-27 20:41:50,349 Accessing /exp: debug5TL4O6 debugBY1QVM debugOXVKP5 
2022-04-27 20:41:50,494 GET /sync route with id: debugOXVKP5:debugBY1QVM
2022-04-27 20:41:54,320 Accessing /inexp
2022-04-27 20:41:54,321 PUT /sync route with id: debugOXVKP5:debugBY1QVM
2022-04-27 20:41:54,347 saved data for debugOXVKP5:debugBY1QVM (current trial: 10)
2022-04-27 20:43:33,581 Accessing /exp: debug5TL4O6 debugBY1QVM debugOXVKP5 
2022-04-27 20:43:33,905 GET /sync route with id: debugOXVKP5:debugBY1QVM
2022-04-27 20:43:37,706 PUT /sync route with id: debugOXVKP5:debugBY1QVM
2022-04-27 20:43:37,714 saved data for debugOXVKP5:debugBY1QVM (current trial: 15)
2022-04-27 20:43:37,718 Accessing /inexp
2022-04-27 20:45:05,068 Accessing /exp: debug5TL4O6 debugBY1QVM debugOXVKP5 
2022-04-27 20:45:06,313 GET /sync route with id: debugOXVKP5:debugBY1QVM
2022-04-27 20:45:09,907 Accessing /inexp
2022-04-27 20:45:09,908 PUT /sync route with id: debugOXVKP5:debugBY1QVM
2022-04-27 20:45:09,941 saved data for debugOXVKP5:debugBY1QVM (current trial: 20)
2022-04-27 20:46:38,015 Accessing /exp: debug5TL4O6 debugBY1QVM debugOXVKP5 
2022-04-27 20:46:38,324 GET /sync route with id: debugOXVKP5:debugBY1QVM
2022-04-27 20:46:40,790 Accessing /inexp
2022-04-27 20:46:40,791 PUT /sync route with id: debugOXVKP5:debugBY1QVM
2022-04-27 20:46:40,809 saved data for debugOXVKP5:debugBY1QVM (current trial: 25)
2022-04-27 20:48:20,975 Accessing /exp: debug5TL4O6 debugBY1QVM debugOXVKP5 
2022-04-27 20:48:21,262 GET /sync route with id: debugOXVKP5:debugBY1QVM
2022-04-27 20:48:48,412 Accessing /exp: debug5TL4O6 debugBY1QVM debugOXVKP5 
2022-04-27 20:48:48,567 GET /sync route with id: debugOXVKP5:debugBY1QVM
2022-04-27 20:48:49,520 PUT /sync route with id: debugOXVKP5:debugBY1QVM
2022-04-27 20:48:49,520 Accessing /inexp
2022-04-27 20:48:49,528 saved data for debugOXVKP5:debugBY1QVM (current trial: 27)
2022-04-27 20:49:13,737 Accessing /exp: debug5TL4O6 debugBY1QVM debugOXVKP5 
2022-04-27 20:49:13,878 GET /sync route with id: debugOXVKP5:debugBY1QVM
2022-04-27 20:49:17,723 PUT /sync route with id: debugOXVKP5:debugBY1QVM
2022-04-27 20:49:17,726 Accessing /inexp
2022-04-27 20:49:17,740 saved data for debugOXVKP5:debugBY1QVM (current trial: 29)
2022-04-27 20:49:54,260 Accessing /exp: debug5TL4O6 debugBY1QVM debugOXVKP5 
2022-04-27 20:49:54,643 GET /sync route with id: debugOXVKP5:debugBY1QVM
2022-04-27 20:49:56,299 PUT /sync route with id: debugOXVKP5:debugBY1QVM
2022-04-27 20:49:56,299 Accessing /inexp
2022-04-27 20:49:56,317 saved data for debugOXVKP5:debugBY1QVM (current trial: 31)
2022-04-27 20:51:45,070 Accessing /exp: debug5TL4O6 debugBY1QVM debugOXVKP5 
2022-04-27 20:51:45,642 GET /sync route with id: debugOXVKP5:debugBY1QVM
2022-04-27 20:51:46,468 PUT /sync route with id: debugOXVKP5:debugBY1QVM
2022-04-27 20:51:46,477 saved data for debugOXVKP5:debugBY1QVM (current trial: 33)
2022-04-27 20:51:46,485 Accessing /inexp
2022-04-27 20:54:56,846 Accessing /exp: debug5TL4O6 debugBY1QVM debugOXVKP5 
2022-04-27 20:54:57,039 GET /sync route with id: debugOXVKP5:debugBY1QVM
2022-04-27 20:54:59,709 Accessing /inexp
2022-04-27 20:54:59,709 PUT /sync route with id: debugOXVKP5:debugBY1QVM
2022-04-27 20:54:59,724 saved data for debugOXVKP5:debugBY1QVM (current trial: 35)
2022-04-27 20:55:49,001 Accessing /exp: debug5TL4O6 debugBY1QVM debugOXVKP5 
2022-04-27 20:56:08,352 Accessing /exp: debug5TL4O6 debugBY1QVM debugOXVKP5 
2022-04-27 20:56:08,702 GET /sync route with id: debugOXVKP5:debugBY1QVM
2022-04-27 20:56:09,597 Accessing /exp: debug5TL4O6 debugBY1QVM debugOXVKP5 
2022-04-27 20:56:09,881 GET /sync route with id: debugOXVKP5:debugBY1QVM
2022-04-27 20:56:10,518 PUT /sync route with id: debugOXVKP5:debugBY1QVM
2022-04-27 20:56:10,528 Accessing /inexp
2022-04-27 20:56:10,529 saved data for debugOXVKP5:debugBY1QVM (current trial: 37)
2022-04-27 20:56:31,854 Accessing /exp: debug5TL4O6 debugBY1QVM debugOXVKP5 
2022-04-27 20:56:32,135 GET /sync route with id: debugOXVKP5:debugBY1QVM
2022-04-27 20:56:33,868 PUT /sync route with id: debugOXVKP5:debugBY1QVM
2022-04-27 20:56:33,869 Accessing /inexp
2022-04-27 20:56:33,913 saved data for debugOXVKP5:debugBY1QVM (current trial: 39)
2022-04-27 20:57:37,736 Accessing /exp: debug5TL4O6 debugBY1QVM debugOXVKP5 
2022-04-27 20:57:38,144 GET /sync route with id: debugOXVKP5:debugBY1QVM
2022-04-27 20:57:39,186 PUT /sync route with id: debugOXVKP5:debugBY1QVM
2022-04-27 20:57:39,200 saved data for debugOXVKP5:debugBY1QVM (current trial: 41)
2022-04-27 20:57:39,202 Accessing /inexp
2022-04-27 20:58:17,156 Accessing /exp: debug5TL4O6 debugBY1QVM debugOXVKP5 
2022-04-27 20:58:17,457 GET /sync route with id: debugOXVKP5:debugBY1QVM
2022-04-27 20:58:18,852 Accessing /inexp
2022-04-27 20:58:18,852 PUT /sync route with id: debugOXVKP5:debugBY1QVM
2022-04-27 20:58:18,876 saved data for debugOXVKP5:debugBY1QVM (current trial: 43)
2022-04-27 21:00:02,185 Accessing /exp: debug5TL4O6 debugBY1QVM debugOXVKP5 
2022-04-27 21:01:00,635 Accessing /exp: debug5TL4O6 debugBY1QVM debugOXVKP5 
2022-04-27 21:01:01,122 GET /sync route with id: debugOXVKP5:debugBY1QVM
2022-04-27 21:02:03,767 Accessing /exp: debug5TL4O6 debugBY1QVM debugOXVKP5 
2022-04-27 21:02:04,323 GET /sync route with id: debugOXVKP5:debugBY1QVM
2022-04-27 21:02:08,065 Accessing /inexp
2022-04-27 21:02:08,065 PUT /sync route with id: debugOXVKP5:debugBY1QVM
2022-04-27 21:02:08,086 saved data for debugOXVKP5:debugBY1QVM (current trial: 45)
2022-04-27 21:02:10,541 Accessing /exp: debug5TL4O6 debugBY1QVM debugOXVKP5 
2022-04-27 21:02:10,798 GET /sync route with id: debugOXVKP5:debugBY1QVM
2022-04-27 21:02:18,291 Accessing /exp: debug5TL4O6 debugBY1QVM debugOXVKP5 
2022-04-27 21:02:18,593 GET /sync route with id: debugOXVKP5:debugBY1QVM
2022-04-27 21:03:16,392 Accessing /exp: debug5TL4O6 debugBY1QVM debugOXVKP5 
2022-04-27 21:03:16,935 GET /sync route with id: debugOXVKP5:debugBY1QVM
2022-04-27 21:03:48,985 Accessing /exp: debug5TL4O6 debugBY1QVM debugOXVKP5 
2022-04-27 21:03:49,344 GET /sync route with id: debugOXVKP5:debugBY1QVM
2022-04-27 21:03:51,252 PUT /sync route with id: debugOXVKP5:debugBY1QVM
2022-04-27 21:03:51,262 saved data for debugOXVKP5:debugBY1QVM (current trial: 47)
2022-04-27 21:03:51,270 Accessing /inexp
2022-04-27 21:04:50,343 Accessing /exp: debug5TL4O6 debugBY1QVM debugOXVKP5 
2022-04-27 21:04:50,638 GET /sync route with id: debugOXVKP5:debugBY1QVM
2022-04-27 22:23:39,427 Accessing /exp: debug5TL4O6 debugBY1QVM debugOXVKP5 
2022-04-27 22:23:39,919 GET /sync route with id: debugOXVKP5:debugBY1QVM
2022-04-27 22:23:45,353 Accessing /exp: debug5TL4O6 debugBY1QVM debugOXVKP5 
2022-04-27 22:23:45,626 GET /sync route with id: debugOXVKP5:debugBY1QVM
2022-04-27 22:25:28,873 Accessing /exp: debug5TL4O6 debugBY1QVM debugOXVKP5 
2022-04-27 22:26:11,627 Accessing /exp: debug5TL4O6 debugBY1QVM debugOXVKP5 
2022-04-27 22:26:12,118 GET /sync route with id: debugOXVKP5:debugBY1QVM
2022-04-27 22:28:35,095 Accessing /exp: debug5TL4O6 debugBY1QVM debugOXVKP5 
2022-04-27 22:28:35,628 GET /sync route with id: debugOXVKP5:debugBY1QVM
2022-04-27 22:28:57,398 Accessing /exp: debug5TL4O6 debugBY1QVM debugOXVKP5 
2022-04-27 22:28:57,738 GET /sync route with id: debugOXVKP5:debugBY1QVM
2022-04-27 22:29:14,019 Accessing /exp: debug5TL4O6 debugBY1QVM debugOXVKP5 
2022-04-27 22:29:14,184 GET /sync route with id: debugOXVKP5:debugBY1QVM
2022-04-27 22:30:54,500 Accessing /exp: debug5TL4O6 debugBY1QVM debugOXVKP5 
2022-04-27 22:30:54,899 GET /sync route with id: debugOXVKP5:debugBY1QVM
2022-04-27 22:31:54,751 Accessing /exp: debug5TL4O6 debugBY1QVM debugOXVKP5 
2022-04-27 22:31:55,249 GET /sync route with id: debugOXVKP5:debugBY1QVM
2022-04-27 22:32:03,571 Accessing /exp: debug5TL4O6 debugBY1QVM debugOXVKP5 
2022-04-27 22:32:03,863 GET /sync route with id: debugOXVKP5:debugBY1QVM
2022-04-27 22:32:08,845 Accessing /exp: debug5TL4O6 debugBY1QVM debugOXVKP5 
2022-04-27 22:32:09,187 GET /sync route with id: debugOXVKP5:debugBY1QVM
2022-04-27 22:32:14,489 Accessing /exp: debug5TL4O6 debugBY1QVM debugOXVKP5 
2022-04-27 22:32:14,756 GET /sync route with id: debugOXVKP5:debugBY1QVM
2022-04-27 22:32:25,754 Accessing /exp: debug5TL4O6 debugBY1QVM debugOXVKP5 
2022-04-27 22:32:25,889 GET /sync route with id: debugOXVKP5:debugBY1QVM
2022-04-27 22:33:58,893 Accessing /exp: debug5TL4O6 debugBY1QVM debugOXVKP5 
2022-04-27 22:33:59,124 GET /sync route with id: debugOXVKP5:debugBY1QVM
2022-04-27 22:35:40,428 Accessing /exp: debug5TL4O6 debugBY1QVM debugOXVKP5 
2022-04-27 22:35:40,647 GET /sync route with id: debugOXVKP5:debugBY1QVM
2022-04-27 22:36:06,106 Accessing /exp: debugLSPC4S debugOVM3MC debugU4EJ4M 
2022-04-27 22:36:06,119 given Counter({(0, 0): 0}) chose (0, 0)
2022-04-27 22:36:06,334 GET /sync route with id: debugU4EJ4M:debugOVM3MC
2022-04-27 22:36:56,338 Accessing /exp: debugLSPC4S debugOVM3MC debugU4EJ4M 
[2022-04-27 22:37:25 +0800] [56960] [INFO] Handling signal: term
[2022-04-27 22:37:25 +0800] [56969] [INFO] Worker exiting (pid: 56969)
[2022-04-27 22:37:25 +0800] [56972] [INFO] Worker exiting (pid: 56972)
[2022-04-27 22:37:25 +0800] [56967] [INFO] Worker exiting (pid: 56967)
[2022-04-27 22:37:25 +0800] [56970] [INFO] Worker exiting (pid: 56970)
[2022-04-27 22:37:26 +0800] [56968] [INFO] Worker exiting (pid: 56968)
[2022-04-27 22:37:26 +0800] [56966] [INFO] Worker exiting (pid: 56966)
[2022-04-27 22:37:26 +0800] [56974] [INFO] Worker exiting (pid: 56974)
[2022-04-27 22:37:26 +0800] [56973] [INFO] Worker exiting (pid: 56973)
[2022-04-27 22:37:26 +0800] [56971] [INFO] Worker exiting (pid: 56971)
[2022-04-27 22:37:26 +0800] [56960] [INFO] Shutting down: Master
[2022-04-27 22:37:33 +0800] [68720] [INFO] Starting gunicorn 20.0.4
[2022-04-27 22:37:33 +0800] [68720] [INFO] Listening at: http://0.0.0.0:50003 (68720)
[2022-04-27 22:37:33 +0800] [68720] [INFO] Using worker: gevent
[2022-04-27 22:37:33 +0800] [68728] [INFO] Booting worker with pid: 68728
[2022-04-27 22:37:33 +0800] [68729] [INFO] Booting worker with pid: 68729
[2022-04-27 22:37:33 +0800] [68730] [INFO] Booting worker with pid: 68730
[2022-04-27 22:37:33 +0800] [68731] [INFO] Booting worker with pid: 68731
[2022-04-27 22:37:33 +0800] [68732] [INFO] Booting worker with pid: 68732
[2022-04-27 22:37:33 +0800] [68733] [INFO] Booting worker with pid: 68733
[2022-04-27 22:37:33 +0800] [68734] [INFO] Booting worker with pid: 68734
[2022-04-27 22:37:33 +0800] [68735] [INFO] Booting worker with pid: 68735
[2022-04-27 22:37:33 +0800] [68736] [INFO] Booting worker with pid: 68736
2022-04-27 22:37:36,491 Starting scheduler in 'paused' mode -- it will not run any tasks, but it can be used to create, modify, or delete tasks.
2022-04-27 22:37:36,495 Scheduler started
2022-04-27 22:37:36,498 /Library/Frameworks/Python.framework/Versions/3.6/lib/python3.6/site-packages/psiturk/psiturk_js/psiturk.js
2022-04-27 22:37:37,028 Starting scheduler in 'paused' mode -- it will not run any tasks, but it can be used to create, modify, or delete tasks.
2022-04-27 22:37:37,034 Scheduler started
2022-04-27 22:37:37,037 /Library/Frameworks/Python.framework/Versions/3.6/lib/python3.6/site-packages/psiturk/psiturk_js/psiturk.js
2022-04-27 22:37:37,294 Starting scheduler in 'paused' mode -- it will not run any tasks, but it can be used to create, modify, or delete tasks.
2022-04-27 22:37:37,297 Scheduler started
2022-04-27 22:37:37,301 /Library/Frameworks/Python.framework/Versions/3.6/lib/python3.6/site-packages/psiturk/psiturk_js/psiturk.js
2022-04-27 22:37:37,455 Starting scheduler in 'paused' mode -- it will not run any tasks, but it can be used to create, modify, or delete tasks.
2022-04-27 22:37:37,461 Scheduler started
2022-04-27 22:37:37,464 /Library/Frameworks/Python.framework/Versions/3.6/lib/python3.6/site-packages/psiturk/psiturk_js/psiturk.js
2022-04-27 22:37:37,539 Starting scheduler in 'paused' mode -- it will not run any tasks, but it can be used to create, modify, or delete tasks.
2022-04-27 22:37:37,543 Scheduler started
2022-04-27 22:37:37,545 /Library/Frameworks/Python.framework/Versions/3.6/lib/python3.6/site-packages/psiturk/psiturk_js/psiturk.js
2022-04-27 22:37:37,556 Starting scheduler in 'paused' mode -- it will not run any tasks, but it can be used to create, modify, or delete tasks.
2022-04-27 22:37:37,560 Scheduler started
2022-04-27 22:37:37,562 /Library/Frameworks/Python.framework/Versions/3.6/lib/python3.6/site-packages/psiturk/psiturk_js/psiturk.js
2022-04-27 22:37:37,562 Starting scheduler in 'paused' mode -- it will not run any tasks, but it can be used to create, modify, or delete tasks.
2022-04-27 22:37:37,568 Scheduler started
2022-04-27 22:37:37,571 /Library/Frameworks/Python.framework/Versions/3.6/lib/python3.6/site-packages/psiturk/psiturk_js/psiturk.js
2022-04-27 22:37:37,610 Starting scheduler in 'paused' mode -- it will not run any tasks, but it can be used to create, modify, or delete tasks.
2022-04-27 22:37:37,612 Scheduler started
2022-04-27 22:37:37,614 /Library/Frameworks/Python.framework/Versions/3.6/lib/python3.6/site-packages/psiturk/psiturk_js/psiturk.js
2022-04-27 22:37:37,639 Starting scheduler in 'paused' mode -- it will not run any tasks, but it can be used to create, modify, or delete tasks.
2022-04-27 22:37:37,642 Scheduler started
2022-04-27 22:37:37,644 /Library/Frameworks/Python.framework/Versions/3.6/lib/python3.6/site-packages/psiturk/psiturk_js/psiturk.js
2022-04-27 22:37:41,352 Accessing /exp: debugSBH9H4 debugOI8PAC debugX97VM7 
2022-04-27 22:37:41,360 given Counter({(0, 0): 1}) chose (0, 0)
2022-04-27 22:37:58,597 Accessing /exp: debugSBH9H4 debugOI8PAC debugX97VM7 
2022-04-27 22:37:58,865 GET /sync route with id: debugX97VM7:debugOI8PAC
2022-04-27 22:40:59,297 Accessing /exp: debugSBH9H4 debugOI8PAC debugX97VM7 
2022-04-27 22:40:59,904 GET /sync route with id: debugX97VM7:debugOI8PAC
2022-04-27 22:41:02,141 PUT /sync route with id: debugX97VM7:debugOI8PAC
2022-04-27 22:41:02,141 Accessing /inexp
2022-04-27 22:41:02,165 saved data for debugX97VM7:debugOI8PAC (current trial: 2)
2022-04-27 22:42:17,075 Accessing /exp: debugSBH9H4 debugOI8PAC debugX97VM7 
2022-04-27 22:42:17,542 GET /sync route with id: debugX97VM7:debugOI8PAC
2022-04-27 22:42:19,778 PUT /sync route with id: debugX97VM7:debugOI8PAC
2022-04-27 22:42:19,779 Accessing /inexp
2022-04-27 22:42:19,796 saved data for debugX97VM7:debugOI8PAC (current trial: 4)
2022-04-27 22:44:33,936 Accessing /exp: debugSBH9H4 debugOI8PAC debugX97VM7 
2022-04-27 22:44:34,292 GET /sync route with id: debugX97VM7:debugOI8PAC
2022-04-27 22:44:37,282 PUT /sync route with id: debugX97VM7:debugOI8PAC
2022-04-27 22:44:37,294 saved data for debugX97VM7:debugOI8PAC (current trial: 6)
2022-04-27 22:44:37,297 Accessing /inexp
2022-04-27 22:45:47,795 Accessing /exp: debugSBH9H4 debugOI8PAC debugX97VM7 
2022-04-27 22:45:48,147 GET /sync route with id: debugX97VM7:debugOI8PAC
2022-04-27 22:45:49,559 PUT /sync route with id: debugX97VM7:debugOI8PAC
2022-04-27 22:45:49,565 saved data for debugX97VM7:debugOI8PAC (current trial: 8)
2022-04-27 22:45:49,568 Accessing /inexp
2022-04-27 22:46:14,270 Accessing /exp: debugSBH9H4 debugOI8PAC debugX97VM7 
2022-04-27 22:46:14,506 GET /sync route with id: debugX97VM7:debugOI8PAC
2022-04-27 22:46:15,809 PUT /sync route with id: debugX97VM7:debugOI8PAC
2022-04-27 22:46:15,822 saved data for debugX97VM7:debugOI8PAC (current trial: 10)
2022-04-27 22:46:15,826 Accessing /inexp
2022-04-27 22:47:21,153 PUT /sync route with id: debugX97VM7:debugOI8PAC
2022-04-27 22:47:21,162 saved data for debugX97VM7:debugOI8PAC (current trial: 16)
2022-04-27 22:47:26,013 PUT /sync route with id: debugX97VM7:debugOI8PAC
2022-04-27 22:47:26,020 saved data for debugX97VM7:debugOI8PAC (current trial: 17)
2022-04-27 22:49:35,577 Accessing /exp: debugSBH9H4 debugOI8PAC debugX97VM7 
2022-04-27 22:49:36,053 GET /sync route with id: debugX97VM7:debugOI8PAC
2022-04-27 22:49:38,184 PUT /sync route with id: debugX97VM7:debugOI8PAC
2022-04-27 22:49:38,184 Accessing /inexp
2022-04-27 22:49:38,203 saved data for debugX97VM7:debugOI8PAC (current trial: 19)
2022-04-27 22:50:02,830 Accessing /exp: debugSBH9H4 debugOI8PAC debugX97VM7 
2022-04-27 22:50:03,155 GET /sync route with id: debugX97VM7:debugOI8PAC
2022-04-27 22:50:05,574 PUT /sync route with id: debugX97VM7:debugOI8PAC
2022-04-27 22:50:05,574 Accessing /inexp
2022-04-27 22:50:05,589 saved data for debugX97VM7:debugOI8PAC (current trial: 21)
2022-04-27 22:50:28,280 Accessing /exp: debugSBH9H4 debugOI8PAC debugX97VM7 
2022-04-27 22:50:28,536 GET /sync route with id: debugX97VM7:debugOI8PAC
2022-04-27 22:50:31,386 Accessing /inexp
2022-04-27 22:50:31,387 PUT /sync route with id: debugX97VM7:debugOI8PAC
2022-04-27 22:50:31,401 saved data for debugX97VM7:debugOI8PAC (current trial: 23)
[2022-04-27 22:53:04 +0800] [68720] [CRITICAL] WORKER TIMEOUT (pid:68728)
[2022-04-27 22:53:04 +0800] [10463] [CRITICAL] WORKER TIMEOUT (pid:10467)
[2022-04-27 22:53:05 +0800] [68728] [INFO] Worker exiting (pid: 68728)
[2022-04-27 22:53:06 +0800] [68720] [INFO] Handling signal: winch
[2022-04-27 22:53:10 +0800] [70042] [INFO] Booting worker with pid: 70042
2022-04-27 22:53:14,462 Starting scheduler in 'paused' mode -- it will not run any tasks, but it can be used to create, modify, or delete tasks.
2022-04-27 22:53:14,466 Starting scheduler in 'paused' mode -- it will not run any tasks, but it can be used to create, modify, or delete tasks.
2022-04-27 22:53:14,475 Scheduler started
2022-04-27 22:53:14,475 Scheduler started
2022-04-27 22:53:14,478 /Library/Frameworks/Python.framework/Versions/3.6/lib/python3.6/site-packages/psiturk/psiturk_js/psiturk.js
2022-04-27 22:53:14,478 /Library/Frameworks/Python.framework/Versions/3.6/lib/python3.6/site-packages/psiturk/psiturk_js/psiturk.js
[2022-04-27 22:56:04 +0800] [68720] [INFO] Handling signal: winch
2022-04-27 22:58:18,997 Accessing /exp: debugSBH9H4 debugOI8PAC debugX97VM7 
2022-04-27 22:58:19,705 GET /sync route with id: debugX97VM7:debugOI8PAC
2022-04-27 22:58:21,255 PUT /sync route with id: debugX97VM7:debugOI8PAC
2022-04-27 22:58:21,256 Accessing /inexp
2022-04-27 22:58:21,295 saved data for debugX97VM7:debugOI8PAC (current trial: 25)
2022-04-27 22:58:30,059 Accessing /exp: debugSBH9H4 debugOI8PAC debugX97VM7 
2022-04-27 22:58:35,445 Accessing /exp: debugSBH9H4 debugOI8PAC debugX97VM7 
2022-04-27 22:58:42,289 Accessing /exp: debugSBH9H4 debugOI8PAC debugX97VM7 
2022-04-27 22:58:42,626 GET /sync route with id: debugX97VM7:debugOI8PAC
2022-04-27 22:58:44,234 PUT /sync route with id: debugX97VM7:debugOI8PAC
2022-04-27 22:58:44,249 saved data for debugX97VM7:debugOI8PAC (current trial: 27)
2022-04-27 22:58:44,253 Accessing /inexp
2022-04-27 22:59:42,251 Accessing /exp: debugSBH9H4 debugOI8PAC debugX97VM7 
2022-04-27 22:59:42,621 GET /sync route with id: debugX97VM7:debugOI8PAC
2022-04-27 22:59:44,234 PUT /sync route with id: debugX97VM7:debugOI8PAC
2022-04-27 22:59:44,234 Accessing /inexp
2022-04-27 22:59:44,270 saved data for debugX97VM7:debugOI8PAC (current trial: 29)
2022-04-27 23:00:27,663 Accessing /exp: debugSBH9H4 debugOI8PAC debugX97VM7 
2022-04-27 23:00:28,329 GET /sync route with id: debugX97VM7:debugOI8PAC
2022-04-27 23:00:29,762 PUT /sync route with id: debugX97VM7:debugOI8PAC
2022-04-27 23:00:29,778 saved data for debugX97VM7:debugOI8PAC (current trial: 31)
2022-04-27 23:00:29,781 Accessing /inexp
2022-04-27 23:02:45,137 Accessing /exp: debugSBH9H4 debugOI8PAC debugX97VM7 
2022-04-27 23:02:45,486 GET /sync route with id: debugX97VM7:debugOI8PAC
2022-04-27 23:02:53,243 Accessing /exp: debugSBH9H4 debugOI8PAC debugX97VM7 
2022-04-27 23:02:53,539 GET /sync route with id: debugX97VM7:debugOI8PAC
2022-04-27 23:04:13,381 Accessing /exp: debugSBH9H4 debugOI8PAC debugX97VM7 
2022-04-27 23:04:13,755 GET /sync route with id: debugX97VM7:debugOI8PAC
2022-04-27 23:04:15,893 Accessing /exp: debugSBH9H4 debugOI8PAC debugX97VM7 
2022-04-27 23:04:16,250 GET /sync route with id: debugX97VM7:debugOI8PAC
2022-04-27 23:04:26,307 Accessing /exp: debugSBH9H4 debugOI8PAC debugX97VM7 
2022-04-27 23:04:35,977 Accessing /exp: debugSBH9H4 debugOI8PAC debugX97VM7 
2022-04-27 23:04:36,285 GET /sync route with id: debugX97VM7:debugOI8PAC
2022-04-27 23:04:38,531 PUT /sync route with id: debugX97VM7:debugOI8PAC
2022-04-27 23:04:38,531 Accessing /inexp
2022-04-27 23:04:38,565 saved data for debugX97VM7:debugOI8PAC (current trial: 33)
2022-04-27 23:04:56,400 Accessing /exp: debugSBH9H4 debugOI8PAC debugX97VM7 
2022-04-27 23:05:02,278 Accessing /exp: debugSBH9H4 debugOI8PAC debugX97VM7 
2022-04-27 23:05:02,562 GET /sync route with id: debugX97VM7:debugOI8PAC
2022-04-27 23:05:04,424 Accessing /exp: debugSBH9H4 debugOI8PAC debugX97VM7 
2022-04-27 23:05:04,693 GET /sync route with id: debugX97VM7:debugOI8PAC
2022-04-27 23:06:24,092 Accessing /exp: debugSBH9H4 debugOI8PAC debugX97VM7 
2022-04-27 23:06:24,580 GET /sync route with id: debugX97VM7:debugOI8PAC
2022-04-27 23:06:57,412 Accessing /exp: debugSBH9H4 debugOI8PAC debugX97VM7 
2022-04-27 23:06:57,747 GET /sync route with id: debugX97VM7:debugOI8PAC
2022-04-27 23:07:03,394 Accessing /exp: debugSBH9H4 debugOI8PAC debugX97VM7 
2022-04-27 23:07:04,025 GET /sync route with id: debugX97VM7:debugOI8PAC
2022-04-27 23:07:16,348 Accessing /exp: debugSBH9H4 debugOI8PAC debugX97VM7 
2022-04-27 23:07:16,725 GET /sync route with id: debugX97VM7:debugOI8PAC
2022-04-27 23:08:59,399 Accessing /exp: debugSBH9H4 debugOI8PAC debugX97VM7 
2022-04-27 23:09:00,219 GET /sync route with id: debugX97VM7:debugOI8PAC
2022-04-27 23:09:07,553 Accessing /exp: debugSBH9H4 debugOI8PAC debugX97VM7 
2022-04-27 23:09:07,846 GET /sync route with id: debugX97VM7:debugOI8PAC
2022-04-27 23:09:11,604 Accessing /exp: debugSBH9H4 debugOI8PAC debugX97VM7 
2022-04-27 23:09:11,914 GET /sync route with id: debugX97VM7:debugOI8PAC
2022-04-27 23:09:23,479 Accessing /exp: debugSBH9H4 debugOI8PAC debugX97VM7 
2022-04-27 23:09:23,766 GET /sync route with id: debugX97VM7:debugOI8PAC
2022-04-27 23:10:34,336 Accessing /exp: debugSBH9H4 debugOI8PAC debugX97VM7 
2022-04-27 23:10:34,755 GET /sync route with id: debugX97VM7:debugOI8PAC
2022-04-27 23:11:18,759 Accessing /exp: debugSBH9H4 debugOI8PAC debugX97VM7 
2022-04-27 23:11:19,155 GET /sync route with id: debugX97VM7:debugOI8PAC
2022-04-27 23:11:36,073 Accessing /exp: debugSBH9H4 debugOI8PAC debugX97VM7 
2022-04-27 23:11:36,365 GET /sync route with id: debugX97VM7:debugOI8PAC
2022-04-27 23:11:56,357 Accessing /exp: debugSBH9H4 debugOI8PAC debugX97VM7 
2022-04-27 23:11:56,645 GET /sync route with id: debugX97VM7:debugOI8PAC
2022-04-27 23:12:01,356 Accessing /exp: debugSBH9H4 debugOI8PAC debugX97VM7 
2022-04-27 23:12:01,631 GET /sync route with id: debugX97VM7:debugOI8PAC
2022-04-27 23:12:46,464 Accessing /exp: debugSBH9H4 debugOI8PAC debugX97VM7 
2022-04-27 23:12:46,793 GET /sync route with id: debugX97VM7:debugOI8PAC
2022-04-27 23:12:52,653 Accessing /exp: debugSBH9H4 debugOI8PAC debugX97VM7 
2022-04-27 23:12:52,970 GET /sync route with id: debugX97VM7:debugOI8PAC
2022-04-27 23:13:48,012 Accessing /exp: debugSBH9H4 debugOI8PAC debugX97VM7 
2022-04-27 23:13:48,423 GET /sync route with id: debugX97VM7:debugOI8PAC
2022-04-27 23:14:23,543 Accessing /exp: debugSBH9H4 debugOI8PAC debugX97VM7 
2022-04-27 23:14:23,768 GET /sync route with id: debugX97VM7:debugOI8PAC
2022-04-27 23:15:19,884 Accessing /exp: debugSBH9H4 debugOI8PAC debugX97VM7 
2022-04-27 23:15:20,185 GET /sync route with id: debugX97VM7:debugOI8PAC
2022-04-27 23:15:47,411 Accessing /exp: debugSBH9H4 debugOI8PAC debugX97VM7 
2022-04-27 23:15:47,708 GET /sync route with id: debugX97VM7:debugOI8PAC
2022-04-27 23:17:47,868 Accessing /exp: debugSBH9H4 debugOI8PAC debugX97VM7 
2022-04-27 23:17:48,218 GET /sync route with id: debugX97VM7:debugOI8PAC
2022-04-27 23:19:05,306 Accessing /exp: debugSBH9H4 debugOI8PAC debugX97VM7 
2022-04-27 23:19:18,804 Accessing /exp: debugSBH9H4 debugOI8PAC debugX97VM7 
2022-04-27 23:20:12,034 Accessing /exp: debugSBH9H4 debugOI8PAC debugX97VM7 
2022-04-27 23:20:16,855 Accessing /exp: debugSBH9H4 debugOI8PAC debugX97VM7 
2022-04-27 23:20:26,670 Accessing /exp: debugSBH9H4 debugOI8PAC debugX97VM7 
2022-04-27 23:20:43,110 Accessing /exp: debugSBH9H4 debugOI8PAC debugX97VM7 
2022-04-27 23:20:43,429 GET /sync route with id: debugX97VM7:debugOI8PAC
2022-04-27 23:21:43,024 Accessing /exp: debugSBH9H4 debugOI8PAC debugX97VM7 
2022-04-27 23:21:43,533 GET /sync route with id: debugX97VM7:debugOI8PAC
2022-04-27 23:22:21,589 Accessing /exp: debugSBH9H4 debugOI8PAC debugX97VM7 
2022-04-27 23:22:21,922 GET /sync route with id: debugX97VM7:debugOI8PAC
2022-04-27 23:22:33,562 Accessing /exp: debugSBH9H4 debugOI8PAC debugX97VM7 
2022-04-27 23:22:33,932 GET /sync route with id: debugX97VM7:debugOI8PAC
2022-04-27 23:23:44,507 Accessing /exp: debugSBH9H4 debugOI8PAC debugX97VM7 
2022-04-27 23:23:44,972 GET /sync route with id: debugX97VM7:debugOI8PAC
2022-04-27 23:23:47,560 Accessing /exp: debugSBH9H4 debugOI8PAC debugX97VM7 
2022-04-27 23:23:48,106 GET /sync route with id: debugX97VM7:debugOI8PAC
2022-04-27 23:23:52,175 PUT /sync route with id: debugX97VM7:debugOI8PAC
2022-04-27 23:23:52,176 Accessing /inexp
2022-04-27 23:23:52,237 saved data for debugX97VM7:debugOI8PAC (current trial: 35)
2022-04-27 23:24:26,960 Accessing /exp: debugSBH9H4 debugOI8PAC debugX97VM7 
2022-04-27 23:24:27,491 GET /sync route with id: debugX97VM7:debugOI8PAC
2022-04-27 23:24:32,574 Accessing /exp: debugSBH9H4 debugOI8PAC debugX97VM7 
2022-04-27 23:24:32,831 GET /sync route with id: debugX97VM7:debugOI8PAC
2022-04-27 23:24:49,766 Accessing /exp: debugSBH9H4 debugOI8PAC debugX97VM7 
2022-04-27 23:24:50,068 GET /sync route with id: debugX97VM7:debugOI8PAC
2022-04-27 23:34:41,606 Accessing /exp: debugSBH9H4 debugOI8PAC debugX97VM7 
2022-04-27 23:34:41,631 Exception on /exp [GET]
Traceback (most recent call last):
  File "/Library/Frameworks/Python.framework/Versions/3.6/lib/python3.6/site-packages/sqlalchemy/engine/base.py", line 1277, in _execute_context
    cursor, statement, parameters, context
  File "/Library/Frameworks/Python.framework/Versions/3.6/lib/python3.6/site-packages/sqlalchemy/engine/default.py", line 608, in do_execute
    cursor.execute(statement, parameters)
sqlite3.OperationalError: no such table: commitment_experiment

The above exception was the direct cause of the following exception:

Traceback (most recent call last):
  File "/Library/Frameworks/Python.framework/Versions/3.6/lib/python3.6/site-packages/flask/app.py", line 2447, in wsgi_app
    response = self.full_dispatch_request()
  File "/Library/Frameworks/Python.framework/Versions/3.6/lib/python3.6/site-packages/flask/app.py", line 1952, in full_dispatch_request
    rv = self.handle_user_exception(e)
  File "/Library/Frameworks/Python.framework/Versions/3.6/lib/python3.6/site-packages/flask/app.py", line 1821, in handle_user_exception
    reraise(exc_type, exc_value, tb)
  File "/Library/Frameworks/Python.framework/Versions/3.6/lib/python3.6/site-packages/flask/_compat.py", line 39, in reraise
    raise value
  File "/Library/Frameworks/Python.framework/Versions/3.6/lib/python3.6/site-packages/flask/app.py", line 1950, in full_dispatch_request
    rv = self.dispatch_request()
  File "/Library/Frameworks/Python.framework/Versions/3.6/lib/python3.6/site-packages/flask/app.py", line 1936, in dispatch_request
    return self.view_functions[rule.endpoint](**req.view_args)
  File "/Library/Frameworks/Python.framework/Versions/3.6/lib/python3.6/site-packages/psiturk/user_utils.py", line 23, in new_func
    resp = make_response(func(*args, **kwargs))
  File "/Library/Frameworks/Python.framework/Versions/3.6/lib/python3.6/site-packages/psiturk/experiment.py", line 454, in start_exp
    filter(Participant.workerid == worker_id).\
  File "/Library/Frameworks/Python.framework/Versions/3.6/lib/python3.6/site-packages/sqlalchemy/orm/query.py", line 3373, in all
    return list(self)
  File "/Library/Frameworks/Python.framework/Versions/3.6/lib/python3.6/site-packages/sqlalchemy/orm/query.py", line 3535, in __iter__
    return self._execute_and_instances(context)
  File "/Library/Frameworks/Python.framework/Versions/3.6/lib/python3.6/site-packages/sqlalchemy/orm/query.py", line 3560, in _execute_and_instances
    result = conn.execute(querycontext.statement, self._params)
  File "/Library/Frameworks/Python.framework/Versions/3.6/lib/python3.6/site-packages/sqlalchemy/engine/base.py", line 1011, in execute
    return meth(self, multiparams, params)
  File "/Library/Frameworks/Python.framework/Versions/3.6/lib/python3.6/site-packages/sqlalchemy/sql/elements.py", line 298, in _execute_on_connection
    return connection._execute_clauseelement(self, multiparams, params)
  File "/Library/Frameworks/Python.framework/Versions/3.6/lib/python3.6/site-packages/sqlalchemy/engine/base.py", line 1130, in _execute_clauseelement
    distilled_params,
  File "/Library/Frameworks/Python.framework/Versions/3.6/lib/python3.6/site-packages/sqlalchemy/engine/base.py", line 1317, in _execute_context
    e, statement, parameters, cursor, context
  File "/Library/Frameworks/Python.framework/Versions/3.6/lib/python3.6/site-packages/sqlalchemy/engine/base.py", line 1511, in _handle_dbapi_exception
    sqlalchemy_exception, with_traceback=exc_info[2], from_=e
  File "/Library/Frameworks/Python.framework/Versions/3.6/lib/python3.6/site-packages/sqlalchemy/util/compat.py", line 182, in raise_
    raise exception
  File "/Library/Frameworks/Python.framework/Versions/3.6/lib/python3.6/site-packages/sqlalchemy/engine/base.py", line 1277, in _execute_context
    cursor, statement, parameters, context
  File "/Library/Frameworks/Python.framework/Versions/3.6/lib/python3.6/site-packages/sqlalchemy/engine/default.py", line 608, in do_execute
    cursor.execute(statement, parameters)
sqlalchemy.exc.OperationalError: (sqlite3.OperationalError) no such table: commitment_experiment
[SQL: SELECT commitment_experiment.uniqueid AS commitment_experiment_uniqueid, commitment_experiment.assignmentid AS commitment_experiment_assignmentid, commitment_experiment.workerid AS commitment_experiment_workerid, commitment_experiment.hitid AS commitment_experiment_hitid, commitment_experiment.ipaddress AS commitment_experiment_ipaddress, commitment_experiment.browser AS commitment_experiment_browser, commitment_experiment.platform AS commitment_experiment_platform, commitment_experiment.language AS commitment_experiment_language, commitment_experiment.cond AS commitment_experiment_cond, commitment_experiment.counterbalance AS commitment_experiment_counterbalance, commitment_experiment.codeversion AS commitment_experiment_codeversion, commitment_experiment.beginhit AS commitment_experiment_beginhit, commitment_experiment.beginexp AS commitment_experiment_beginexp, commitment_experiment.endhit AS commitment_experiment_endhit, commitment_experiment.bonus AS commitment_experiment_bonus, commitment_experiment.status AS commitment_experiment_status, commitment_experiment.mode AS commitment_experiment_mode 
FROM commitment_experiment 
WHERE commitment_experiment.workerid = ?]
[parameters: ('debugX97VM7',)]
(Background on this error at: http://sqlalche.me/e/13/e3q8)
2022-04-27 23:34:46,023 Accessing /exp: debugSBH9H4 debugOI8PAC debugX97VM7 
2022-04-27 23:34:46,039 Exception on /exp [GET]
Traceback (most recent call last):
  File "/Library/Frameworks/Python.framework/Versions/3.6/lib/python3.6/site-packages/sqlalchemy/engine/base.py", line 1277, in _execute_context
    cursor, statement, parameters, context
  File "/Library/Frameworks/Python.framework/Versions/3.6/lib/python3.6/site-packages/sqlalchemy/engine/default.py", line 608, in do_execute
    cursor.execute(statement, parameters)
sqlite3.OperationalError: no such table: commitment_experiment

The above exception was the direct cause of the following exception:

Traceback (most recent call last):
  File "/Library/Frameworks/Python.framework/Versions/3.6/lib/python3.6/site-packages/flask/app.py", line 2447, in wsgi_app
    response = self.full_dispatch_request()
  File "/Library/Frameworks/Python.framework/Versions/3.6/lib/python3.6/site-packages/flask/app.py", line 1952, in full_dispatch_request
    rv = self.handle_user_exception(e)
  File "/Library/Frameworks/Python.framework/Versions/3.6/lib/python3.6/site-packages/flask/app.py", line 1821, in handle_user_exception
    reraise(exc_type, exc_value, tb)
  File "/Library/Frameworks/Python.framework/Versions/3.6/lib/python3.6/site-packages/flask/_compat.py", line 39, in reraise
    raise value
  File "/Library/Frameworks/Python.framework/Versions/3.6/lib/python3.6/site-packages/flask/app.py", line 1950, in full_dispatch_request
    rv = self.dispatch_request()
  File "/Library/Frameworks/Python.framework/Versions/3.6/lib/python3.6/site-packages/flask/app.py", line 1936, in dispatch_request
    return self.view_functions[rule.endpoint](**req.view_args)
  File "/Library/Frameworks/Python.framework/Versions/3.6/lib/python3.6/site-packages/psiturk/user_utils.py", line 23, in new_func
    resp = make_response(func(*args, **kwargs))
  File "/Library/Frameworks/Python.framework/Versions/3.6/lib/python3.6/site-packages/psiturk/experiment.py", line 454, in start_exp
    filter(Participant.workerid == worker_id).\
  File "/Library/Frameworks/Python.framework/Versions/3.6/lib/python3.6/site-packages/sqlalchemy/orm/query.py", line 3373, in all
    return list(self)
  File "/Library/Frameworks/Python.framework/Versions/3.6/lib/python3.6/site-packages/sqlalchemy/orm/query.py", line 3535, in __iter__
    return self._execute_and_instances(context)
  File "/Library/Frameworks/Python.framework/Versions/3.6/lib/python3.6/site-packages/sqlalchemy/orm/query.py", line 3560, in _execute_and_instances
    result = conn.execute(querycontext.statement, self._params)
  File "/Library/Frameworks/Python.framework/Versions/3.6/lib/python3.6/site-packages/sqlalchemy/engine/base.py", line 1011, in execute
    return meth(self, multiparams, params)
  File "/Library/Frameworks/Python.framework/Versions/3.6/lib/python3.6/site-packages/sqlalchemy/sql/elements.py", line 298, in _execute_on_connection
    return connection._execute_clauseelement(self, multiparams, params)
  File "/Library/Frameworks/Python.framework/Versions/3.6/lib/python3.6/site-packages/sqlalchemy/engine/base.py", line 1130, in _execute_clauseelement
    distilled_params,
  File "/Library/Frameworks/Python.framework/Versions/3.6/lib/python3.6/site-packages/sqlalchemy/engine/base.py", line 1317, in _execute_context
    e, statement, parameters, cursor, context
  File "/Library/Frameworks/Python.framework/Versions/3.6/lib/python3.6/site-packages/sqlalchemy/engine/base.py", line 1511, in _handle_dbapi_exception
    sqlalchemy_exception, with_traceback=exc_info[2], from_=e
  File "/Library/Frameworks/Python.framework/Versions/3.6/lib/python3.6/site-packages/sqlalchemy/util/compat.py", line 182, in raise_
    raise exception
  File "/Library/Frameworks/Python.framework/Versions/3.6/lib/python3.6/site-packages/sqlalchemy/engine/base.py", line 1277, in _execute_context
    cursor, statement, parameters, context
  File "/Library/Frameworks/Python.framework/Versions/3.6/lib/python3.6/site-packages/sqlalchemy/engine/default.py", line 608, in do_execute
    cursor.execute(statement, parameters)
sqlalchemy.exc.OperationalError: (sqlite3.OperationalError) no such table: commitment_experiment
[SQL: SELECT commitment_experiment.uniqueid AS commitment_experiment_uniqueid, commitment_experiment.assignmentid AS commitment_experiment_assignmentid, commitment_experiment.workerid AS commitment_experiment_workerid, commitment_experiment.hitid AS commitment_experiment_hitid, commitment_experiment.ipaddress AS commitment_experiment_ipaddress, commitment_experiment.browser AS commitment_experiment_browser, commitment_experiment.platform AS commitment_experiment_platform, commitment_experiment.language AS commitment_experiment_language, commitment_experiment.cond AS commitment_experiment_cond, commitment_experiment.counterbalance AS commitment_experiment_counterbalance, commitment_experiment.codeversion AS commitment_experiment_codeversion, commitment_experiment.beginhit AS commitment_experiment_beginhit, commitment_experiment.beginexp AS commitment_experiment_beginexp, commitment_experiment.endhit AS commitment_experiment_endhit, commitment_experiment.bonus AS commitment_experiment_bonus, commitment_experiment.status AS commitment_experiment_status, commitment_experiment.mode AS commitment_experiment_mode 
FROM commitment_experiment 
WHERE commitment_experiment.workerid = ?]
[parameters: ('debugX97VM7',)]
(Background on this error at: http://sqlalche.me/e/13/e3q8)
2022-04-27 23:35:01,899 Accessing /exp: debugSBH9H4 debugOI8PAC debugX97VM7 
2022-04-27 23:35:01,942 Exception on /exp [GET]
Traceback (most recent call last):
  File "/Library/Frameworks/Python.framework/Versions/3.6/lib/python3.6/site-packages/sqlalchemy/engine/base.py", line 1277, in _execute_context
    cursor, statement, parameters, context
  File "/Library/Frameworks/Python.framework/Versions/3.6/lib/python3.6/site-packages/sqlalchemy/engine/default.py", line 608, in do_execute
    cursor.execute(statement, parameters)
sqlite3.OperationalError: no such table: commitment_experiment

The above exception was the direct cause of the following exception:

Traceback (most recent call last):
  File "/Library/Frameworks/Python.framework/Versions/3.6/lib/python3.6/site-packages/flask/app.py", line 2447, in wsgi_app
    response = self.full_dispatch_request()
  File "/Library/Frameworks/Python.framework/Versions/3.6/lib/python3.6/site-packages/flask/app.py", line 1952, in full_dispatch_request
    rv = self.handle_user_exception(e)
  File "/Library/Frameworks/Python.framework/Versions/3.6/lib/python3.6/site-packages/flask/app.py", line 1821, in handle_user_exception
    reraise(exc_type, exc_value, tb)
  File "/Library/Frameworks/Python.framework/Versions/3.6/lib/python3.6/site-packages/flask/_compat.py", line 39, in reraise
    raise value
  File "/Library/Frameworks/Python.framework/Versions/3.6/lib/python3.6/site-packages/flask/app.py", line 1950, in full_dispatch_request
    rv = self.dispatch_request()
  File "/Library/Frameworks/Python.framework/Versions/3.6/lib/python3.6/site-packages/flask/app.py", line 1936, in dispatch_request
    return self.view_functions[rule.endpoint](**req.view_args)
  File "/Library/Frameworks/Python.framework/Versions/3.6/lib/python3.6/site-packages/psiturk/user_utils.py", line 23, in new_func
    resp = make_response(func(*args, **kwargs))
  File "/Library/Frameworks/Python.framework/Versions/3.6/lib/python3.6/site-packages/psiturk/experiment.py", line 454, in start_exp
    filter(Participant.workerid == worker_id).\
  File "/Library/Frameworks/Python.framework/Versions/3.6/lib/python3.6/site-packages/sqlalchemy/orm/query.py", line 3373, in all
    return list(self)
  File "/Library/Frameworks/Python.framework/Versions/3.6/lib/python3.6/site-packages/sqlalchemy/orm/query.py", line 3535, in __iter__
    return self._execute_and_instances(context)
  File "/Library/Frameworks/Python.framework/Versions/3.6/lib/python3.6/site-packages/sqlalchemy/orm/query.py", line 3560, in _execute_and_instances
    result = conn.execute(querycontext.statement, self._params)
  File "/Library/Frameworks/Python.framework/Versions/3.6/lib/python3.6/site-packages/sqlalchemy/engine/base.py", line 1011, in execute
    return meth(self, multiparams, params)
  File "/Library/Frameworks/Python.framework/Versions/3.6/lib/python3.6/site-packages/sqlalchemy/sql/elements.py", line 298, in _execute_on_connection
    return connection._execute_clauseelement(self, multiparams, params)
  File "/Library/Frameworks/Python.framework/Versions/3.6/lib/python3.6/site-packages/sqlalchemy/engine/base.py", line 1130, in _execute_clauseelement
    distilled_params,
  File "/Library/Frameworks/Python.framework/Versions/3.6/lib/python3.6/site-packages/sqlalchemy/engine/base.py", line 1317, in _execute_context
    e, statement, parameters, cursor, context
  File "/Library/Frameworks/Python.framework/Versions/3.6/lib/python3.6/site-packages/sqlalchemy/engine/base.py", line 1511, in _handle_dbapi_exception
    sqlalchemy_exception, with_traceback=exc_info[2], from_=e
  File "/Library/Frameworks/Python.framework/Versions/3.6/lib/python3.6/site-packages/sqlalchemy/util/compat.py", line 182, in raise_
    raise exception
  File "/Library/Frameworks/Python.framework/Versions/3.6/lib/python3.6/site-packages/sqlalchemy/engine/base.py", line 1277, in _execute_context
    cursor, statement, parameters, context
  File "/Library/Frameworks/Python.framework/Versions/3.6/lib/python3.6/site-packages/sqlalchemy/engine/default.py", line 608, in do_execute
    cursor.execute(statement, parameters)
sqlalchemy.exc.OperationalError: (sqlite3.OperationalError) no such table: commitment_experiment
[SQL: SELECT commitment_experiment.uniqueid AS commitment_experiment_uniqueid, commitment_experiment.assignmentid AS commitment_experiment_assignmentid, commitment_experiment.workerid AS commitment_experiment_workerid, commitment_experiment.hitid AS commitment_experiment_hitid, commitment_experiment.ipaddress AS commitment_experiment_ipaddress, commitment_experiment.browser AS commitment_experiment_browser, commitment_experiment.platform AS commitment_experiment_platform, commitment_experiment.language AS commitment_experiment_language, commitment_experiment.cond AS commitment_experiment_cond, commitment_experiment.counterbalance AS commitment_experiment_counterbalance, commitment_experiment.codeversion AS commitment_experiment_codeversion, commitment_experiment.beginhit AS commitment_experiment_beginhit, commitment_experiment.beginexp AS commitment_experiment_beginexp, commitment_experiment.endhit AS commitment_experiment_endhit, commitment_experiment.bonus AS commitment_experiment_bonus, commitment_experiment.status AS commitment_experiment_status, commitment_experiment.mode AS commitment_experiment_mode 
FROM commitment_experiment 
WHERE commitment_experiment.workerid = ?]
[parameters: ('debugX97VM7',)]
(Background on this error at: http://sqlalche.me/e/13/e3q8)
2022-04-27 23:35:10,484 Accessing /exp: debugSBH9H4 debugOI8PAC debugX97VM7 
2022-04-27 23:35:10,504 Exception on /exp [GET]
Traceback (most recent call last):
  File "/Library/Frameworks/Python.framework/Versions/3.6/lib/python3.6/site-packages/sqlalchemy/engine/base.py", line 1277, in _execute_context
    cursor, statement, parameters, context
  File "/Library/Frameworks/Python.framework/Versions/3.6/lib/python3.6/site-packages/sqlalchemy/engine/default.py", line 608, in do_execute
    cursor.execute(statement, parameters)
sqlite3.OperationalError: no such table: commitment_experiment

The above exception was the direct cause of the following exception:

Traceback (most recent call last):
  File "/Library/Frameworks/Python.framework/Versions/3.6/lib/python3.6/site-packages/flask/app.py", line 2447, in wsgi_app
    response = self.full_dispatch_request()
  File "/Library/Frameworks/Python.framework/Versions/3.6/lib/python3.6/site-packages/flask/app.py", line 1952, in full_dispatch_request
    rv = self.handle_user_exception(e)
  File "/Library/Frameworks/Python.framework/Versions/3.6/lib/python3.6/site-packages/flask/app.py", line 1821, in handle_user_exception
    reraise(exc_type, exc_value, tb)
  File "/Library/Frameworks/Python.framework/Versions/3.6/lib/python3.6/site-packages/flask/_compat.py", line 39, in reraise
    raise value
  File "/Library/Frameworks/Python.framework/Versions/3.6/lib/python3.6/site-packages/flask/app.py", line 1950, in full_dispatch_request
    rv = self.dispatch_request()
  File "/Library/Frameworks/Python.framework/Versions/3.6/lib/python3.6/site-packages/flask/app.py", line 1936, in dispatch_request
    return self.view_functions[rule.endpoint](**req.view_args)
  File "/Library/Frameworks/Python.framework/Versions/3.6/lib/python3.6/site-packages/psiturk/user_utils.py", line 23, in new_func
    resp = make_response(func(*args, **kwargs))
  File "/Library/Frameworks/Python.framework/Versions/3.6/lib/python3.6/site-packages/psiturk/experiment.py", line 454, in start_exp
    filter(Participant.workerid == worker_id).\
  File "/Library/Frameworks/Python.framework/Versions/3.6/lib/python3.6/site-packages/sqlalchemy/orm/query.py", line 3373, in all
    return list(self)
  File "/Library/Frameworks/Python.framework/Versions/3.6/lib/python3.6/site-packages/sqlalchemy/orm/query.py", line 3535, in __iter__
    return self._execute_and_instances(context)
  File "/Library/Frameworks/Python.framework/Versions/3.6/lib/python3.6/site-packages/sqlalchemy/orm/query.py", line 3560, in _execute_and_instances
    result = conn.execute(querycontext.statement, self._params)
  File "/Library/Frameworks/Python.framework/Versions/3.6/lib/python3.6/site-packages/sqlalchemy/engine/base.py", line 1011, in execute
    return meth(self, multiparams, params)
  File "/Library/Frameworks/Python.framework/Versions/3.6/lib/python3.6/site-packages/sqlalchemy/sql/elements.py", line 298, in _execute_on_connection
    return connection._execute_clauseelement(self, multiparams, params)
  File "/Library/Frameworks/Python.framework/Versions/3.6/lib/python3.6/site-packages/sqlalchemy/engine/base.py", line 1130, in _execute_clauseelement
    distilled_params,
  File "/Library/Frameworks/Python.framework/Versions/3.6/lib/python3.6/site-packages/sqlalchemy/engine/base.py", line 1317, in _execute_context
    e, statement, parameters, cursor, context
  File "/Library/Frameworks/Python.framework/Versions/3.6/lib/python3.6/site-packages/sqlalchemy/engine/base.py", line 1511, in _handle_dbapi_exception
    sqlalchemy_exception, with_traceback=exc_info[2], from_=e
  File "/Library/Frameworks/Python.framework/Versions/3.6/lib/python3.6/site-packages/sqlalchemy/util/compat.py", line 182, in raise_
    raise exception
  File "/Library/Frameworks/Python.framework/Versions/3.6/lib/python3.6/site-packages/sqlalchemy/engine/base.py", line 1277, in _execute_context
    cursor, statement, parameters, context
  File "/Library/Frameworks/Python.framework/Versions/3.6/lib/python3.6/site-packages/sqlalchemy/engine/default.py", line 608, in do_execute
    cursor.execute(statement, parameters)
sqlalchemy.exc.OperationalError: (sqlite3.OperationalError) no such table: commitment_experiment
[SQL: SELECT commitment_experiment.uniqueid AS commitment_experiment_uniqueid, commitment_experiment.assignmentid AS commitment_experiment_assignmentid, commitment_experiment.workerid AS commitment_experiment_workerid, commitment_experiment.hitid AS commitment_experiment_hitid, commitment_experiment.ipaddress AS commitment_experiment_ipaddress, commitment_experiment.browser AS commitment_experiment_browser, commitment_experiment.platform AS commitment_experiment_platform, commitment_experiment.language AS commitment_experiment_language, commitment_experiment.cond AS commitment_experiment_cond, commitment_experiment.counterbalance AS commitment_experiment_counterbalance, commitment_experiment.codeversion AS commitment_experiment_codeversion, commitment_experiment.beginhit AS commitment_experiment_beginhit, commitment_experiment.beginexp AS commitment_experiment_beginexp, commitment_experiment.endhit AS commitment_experiment_endhit, commitment_experiment.bonus AS commitment_experiment_bonus, commitment_experiment.status AS commitment_experiment_status, commitment_experiment.mode AS commitment_experiment_mode 
FROM commitment_experiment 
WHERE commitment_experiment.workerid = ?]
[parameters: ('debugX97VM7',)]
(Background on this error at: http://sqlalche.me/e/13/e3q8)
2022-04-27 23:35:11,385 Accessing /exp: debugSBH9H4 debugOI8PAC debugX97VM7 
2022-04-27 23:35:11,388 Exception on /exp [GET]
Traceback (most recent call last):
  File "/Library/Frameworks/Python.framework/Versions/3.6/lib/python3.6/site-packages/sqlalchemy/engine/base.py", line 1277, in _execute_context
    cursor, statement, parameters, context
  File "/Library/Frameworks/Python.framework/Versions/3.6/lib/python3.6/site-packages/sqlalchemy/engine/default.py", line 608, in do_execute
    cursor.execute(statement, parameters)
sqlite3.OperationalError: no such table: commitment_experiment

The above exception was the direct cause of the following exception:

Traceback (most recent call last):
  File "/Library/Frameworks/Python.framework/Versions/3.6/lib/python3.6/site-packages/flask/app.py", line 2447, in wsgi_app
    response = self.full_dispatch_request()
  File "/Library/Frameworks/Python.framework/Versions/3.6/lib/python3.6/site-packages/flask/app.py", line 1952, in full_dispatch_request
    rv = self.handle_user_exception(e)
  File "/Library/Frameworks/Python.framework/Versions/3.6/lib/python3.6/site-packages/flask/app.py", line 1821, in handle_user_exception
    reraise(exc_type, exc_value, tb)
  File "/Library/Frameworks/Python.framework/Versions/3.6/lib/python3.6/site-packages/flask/_compat.py", line 39, in reraise
    raise value
  File "/Library/Frameworks/Python.framework/Versions/3.6/lib/python3.6/site-packages/flask/app.py", line 1950, in full_dispatch_request
    rv = self.dispatch_request()
  File "/Library/Frameworks/Python.framework/Versions/3.6/lib/python3.6/site-packages/flask/app.py", line 1936, in dispatch_request
    return self.view_functions[rule.endpoint](**req.view_args)
  File "/Library/Frameworks/Python.framework/Versions/3.6/lib/python3.6/site-packages/psiturk/user_utils.py", line 23, in new_func
    resp = make_response(func(*args, **kwargs))
  File "/Library/Frameworks/Python.framework/Versions/3.6/lib/python3.6/site-packages/psiturk/experiment.py", line 454, in start_exp
    filter(Participant.workerid == worker_id).\
  File "/Library/Frameworks/Python.framework/Versions/3.6/lib/python3.6/site-packages/sqlalchemy/orm/query.py", line 3373, in all
    return list(self)
  File "/Library/Frameworks/Python.framework/Versions/3.6/lib/python3.6/site-packages/sqlalchemy/orm/query.py", line 3535, in __iter__
    return self._execute_and_instances(context)
  File "/Library/Frameworks/Python.framework/Versions/3.6/lib/python3.6/site-packages/sqlalchemy/orm/query.py", line 3560, in _execute_and_instances
    result = conn.execute(querycontext.statement, self._params)
  File "/Library/Frameworks/Python.framework/Versions/3.6/lib/python3.6/site-packages/sqlalchemy/engine/base.py", line 1011, in execute
    return meth(self, multiparams, params)
  File "/Library/Frameworks/Python.framework/Versions/3.6/lib/python3.6/site-packages/sqlalchemy/sql/elements.py", line 298, in _execute_on_connection
    return connection._execute_clauseelement(self, multiparams, params)
  File "/Library/Frameworks/Python.framework/Versions/3.6/lib/python3.6/site-packages/sqlalchemy/engine/base.py", line 1130, in _execute_clauseelement
    distilled_params,
  File "/Library/Frameworks/Python.framework/Versions/3.6/lib/python3.6/site-packages/sqlalchemy/engine/base.py", line 1317, in _execute_context
    e, statement, parameters, cursor, context
  File "/Library/Frameworks/Python.framework/Versions/3.6/lib/python3.6/site-packages/sqlalchemy/engine/base.py", line 1511, in _handle_dbapi_exception
    sqlalchemy_exception, with_traceback=exc_info[2], from_=e
  File "/Library/Frameworks/Python.framework/Versions/3.6/lib/python3.6/site-packages/sqlalchemy/util/compat.py", line 182, in raise_
    raise exception
  File "/Library/Frameworks/Python.framework/Versions/3.6/lib/python3.6/site-packages/sqlalchemy/engine/base.py", line 1277, in _execute_context
    cursor, statement, parameters, context
  File "/Library/Frameworks/Python.framework/Versions/3.6/lib/python3.6/site-packages/sqlalchemy/engine/default.py", line 608, in do_execute
    cursor.execute(statement, parameters)
sqlalchemy.exc.OperationalError: (sqlite3.OperationalError) no such table: commitment_experiment
[SQL: SELECT commitment_experiment.uniqueid AS commitment_experiment_uniqueid, commitment_experiment.assignmentid AS commitment_experiment_assignmentid, commitment_experiment.workerid AS commitment_experiment_workerid, commitment_experiment.hitid AS commitment_experiment_hitid, commitment_experiment.ipaddress AS commitment_experiment_ipaddress, commitment_experiment.browser AS commitment_experiment_browser, commitment_experiment.platform AS commitment_experiment_platform, commitment_experiment.language AS commitment_experiment_language, commitment_experiment.cond AS commitment_experiment_cond, commitment_experiment.counterbalance AS commitment_experiment_counterbalance, commitment_experiment.codeversion AS commitment_experiment_codeversion, commitment_experiment.beginhit AS commitment_experiment_beginhit, commitment_experiment.beginexp AS commitment_experiment_beginexp, commitment_experiment.endhit AS commitment_experiment_endhit, commitment_experiment.bonus AS commitment_experiment_bonus, commitment_experiment.status AS commitment_experiment_status, commitment_experiment.mode AS commitment_experiment_mode 
FROM commitment_experiment 
WHERE commitment_experiment.workerid = ?]
[parameters: ('debugX97VM7',)]
(Background on this error at: http://sqlalche.me/e/13/e3q8)
2022-04-27 23:35:18,211 Accessing /exp: debugSBH9H4 debugOI8PAC debugX97VM7 
2022-04-27 23:35:18,260 Exception on /exp [GET]
Traceback (most recent call last):
  File "/Library/Frameworks/Python.framework/Versions/3.6/lib/python3.6/site-packages/sqlalchemy/engine/base.py", line 1277, in _execute_context
    cursor, statement, parameters, context
  File "/Library/Frameworks/Python.framework/Versions/3.6/lib/python3.6/site-packages/sqlalchemy/engine/default.py", line 608, in do_execute
    cursor.execute(statement, parameters)
sqlite3.OperationalError: no such table: commitment_experiment

The above exception was the direct cause of the following exception:

Traceback (most recent call last):
  File "/Library/Frameworks/Python.framework/Versions/3.6/lib/python3.6/site-packages/flask/app.py", line 2447, in wsgi_app
    response = self.full_dispatch_request()
  File "/Library/Frameworks/Python.framework/Versions/3.6/lib/python3.6/site-packages/flask/app.py", line 1952, in full_dispatch_request
    rv = self.handle_user_exception(e)
  File "/Library/Frameworks/Python.framework/Versions/3.6/lib/python3.6/site-packages/flask/app.py", line 1821, in handle_user_exception
    reraise(exc_type, exc_value, tb)
  File "/Library/Frameworks/Python.framework/Versions/3.6/lib/python3.6/site-packages/flask/_compat.py", line 39, in reraise
    raise value
  File "/Library/Frameworks/Python.framework/Versions/3.6/lib/python3.6/site-packages/flask/app.py", line 1950, in full_dispatch_request
    rv = self.dispatch_request()
  File "/Library/Frameworks/Python.framework/Versions/3.6/lib/python3.6/site-packages/flask/app.py", line 1936, in dispatch_request
    return self.view_functions[rule.endpoint](**req.view_args)
  File "/Library/Frameworks/Python.framework/Versions/3.6/lib/python3.6/site-packages/psiturk/user_utils.py", line 23, in new_func
    resp = make_response(func(*args, **kwargs))
  File "/Library/Frameworks/Python.framework/Versions/3.6/lib/python3.6/site-packages/psiturk/experiment.py", line 454, in start_exp
    filter(Participant.workerid == worker_id).\
  File "/Library/Frameworks/Python.framework/Versions/3.6/lib/python3.6/site-packages/sqlalchemy/orm/query.py", line 3373, in all
    return list(self)
  File "/Library/Frameworks/Python.framework/Versions/3.6/lib/python3.6/site-packages/sqlalchemy/orm/query.py", line 3535, in __iter__
    return self._execute_and_instances(context)
  File "/Library/Frameworks/Python.framework/Versions/3.6/lib/python3.6/site-packages/sqlalchemy/orm/query.py", line 3560, in _execute_and_instances
    result = conn.execute(querycontext.statement, self._params)
  File "/Library/Frameworks/Python.framework/Versions/3.6/lib/python3.6/site-packages/sqlalchemy/engine/base.py", line 1011, in execute
    return meth(self, multiparams, params)
  File "/Library/Frameworks/Python.framework/Versions/3.6/lib/python3.6/site-packages/sqlalchemy/sql/elements.py", line 298, in _execute_on_connection
    return connection._execute_clauseelement(self, multiparams, params)
  File "/Library/Frameworks/Python.framework/Versions/3.6/lib/python3.6/site-packages/sqlalchemy/engine/base.py", line 1130, in _execute_clauseelement
    distilled_params,
  File "/Library/Frameworks/Python.framework/Versions/3.6/lib/python3.6/site-packages/sqlalchemy/engine/base.py", line 1317, in _execute_context
    e, statement, parameters, cursor, context
  File "/Library/Frameworks/Python.framework/Versions/3.6/lib/python3.6/site-packages/sqlalchemy/engine/base.py", line 1511, in _handle_dbapi_exception
    sqlalchemy_exception, with_traceback=exc_info[2], from_=e
  File "/Library/Frameworks/Python.framework/Versions/3.6/lib/python3.6/site-packages/sqlalchemy/util/compat.py", line 182, in raise_
    raise exception
  File "/Library/Frameworks/Python.framework/Versions/3.6/lib/python3.6/site-packages/sqlalchemy/engine/base.py", line 1277, in _execute_context
    cursor, statement, parameters, context
  File "/Library/Frameworks/Python.framework/Versions/3.6/lib/python3.6/site-packages/sqlalchemy/engine/default.py", line 608, in do_execute
    cursor.execute(statement, parameters)
sqlalchemy.exc.OperationalError: (sqlite3.OperationalError) no such table: commitment_experiment
[SQL: SELECT commitment_experiment.uniqueid AS commitment_experiment_uniqueid, commitment_experiment.assignmentid AS commitment_experiment_assignmentid, commitment_experiment.workerid AS commitment_experiment_workerid, commitment_experiment.hitid AS commitment_experiment_hitid, commitment_experiment.ipaddress AS commitment_experiment_ipaddress, commitment_experiment.browser AS commitment_experiment_browser, commitment_experiment.platform AS commitment_experiment_platform, commitment_experiment.language AS commitment_experiment_language, commitment_experiment.cond AS commitment_experiment_cond, commitment_experiment.counterbalance AS commitment_experiment_counterbalance, commitment_experiment.codeversion AS commitment_experiment_codeversion, commitment_experiment.beginhit AS commitment_experiment_beginhit, commitment_experiment.beginexp AS commitment_experiment_beginexp, commitment_experiment.endhit AS commitment_experiment_endhit, commitment_experiment.bonus AS commitment_experiment_bonus, commitment_experiment.status AS commitment_experiment_status, commitment_experiment.mode AS commitment_experiment_mode 
FROM commitment_experiment 
WHERE commitment_experiment.workerid = ?]
[parameters: ('debugX97VM7',)]
(Background on this error at: http://sqlalche.me/e/13/e3q8)
2022-04-27 23:35:19,260 Accessing /exp: debugSBH9H4 debugOI8PAC debugX97VM7 
2022-04-27 23:35:19,267 Exception on /exp [GET]
Traceback (most recent call last):
  File "/Library/Frameworks/Python.framework/Versions/3.6/lib/python3.6/site-packages/sqlalchemy/engine/base.py", line 1277, in _execute_context
    cursor, statement, parameters, context
  File "/Library/Frameworks/Python.framework/Versions/3.6/lib/python3.6/site-packages/sqlalchemy/engine/default.py", line 608, in do_execute
    cursor.execute(statement, parameters)
sqlite3.OperationalError: no such table: commitment_experiment

The above exception was the direct cause of the following exception:

Traceback (most recent call last):
  File "/Library/Frameworks/Python.framework/Versions/3.6/lib/python3.6/site-packages/flask/app.py", line 2447, in wsgi_app
    response = self.full_dispatch_request()
  File "/Library/Frameworks/Python.framework/Versions/3.6/lib/python3.6/site-packages/flask/app.py", line 1952, in full_dispatch_request
    rv = self.handle_user_exception(e)
  File "/Library/Frameworks/Python.framework/Versions/3.6/lib/python3.6/site-packages/flask/app.py", line 1821, in handle_user_exception
    reraise(exc_type, exc_value, tb)
  File "/Library/Frameworks/Python.framework/Versions/3.6/lib/python3.6/site-packages/flask/_compat.py", line 39, in reraise
    raise value
  File "/Library/Frameworks/Python.framework/Versions/3.6/lib/python3.6/site-packages/flask/app.py", line 1950, in full_dispatch_request
    rv = self.dispatch_request()
  File "/Library/Frameworks/Python.framework/Versions/3.6/lib/python3.6/site-packages/flask/app.py", line 1936, in dispatch_request
    return self.view_functions[rule.endpoint](**req.view_args)
  File "/Library/Frameworks/Python.framework/Versions/3.6/lib/python3.6/site-packages/psiturk/user_utils.py", line 23, in new_func
    resp = make_response(func(*args, **kwargs))
  File "/Library/Frameworks/Python.framework/Versions/3.6/lib/python3.6/site-packages/psiturk/experiment.py", line 454, in start_exp
    filter(Participant.workerid == worker_id).\
  File "/Library/Frameworks/Python.framework/Versions/3.6/lib/python3.6/site-packages/sqlalchemy/orm/query.py", line 3373, in all
    return list(self)
  File "/Library/Frameworks/Python.framework/Versions/3.6/lib/python3.6/site-packages/sqlalchemy/orm/query.py", line 3535, in __iter__
    return self._execute_and_instances(context)
  File "/Library/Frameworks/Python.framework/Versions/3.6/lib/python3.6/site-packages/sqlalchemy/orm/query.py", line 3560, in _execute_and_instances
    result = conn.execute(querycontext.statement, self._params)
  File "/Library/Frameworks/Python.framework/Versions/3.6/lib/python3.6/site-packages/sqlalchemy/engine/base.py", line 1011, in execute
    return meth(self, multiparams, params)
  File "/Library/Frameworks/Python.framework/Versions/3.6/lib/python3.6/site-packages/sqlalchemy/sql/elements.py", line 298, in _execute_on_connection
    return connection._execute_clauseelement(self, multiparams, params)
  File "/Library/Frameworks/Python.framework/Versions/3.6/lib/python3.6/site-packages/sqlalchemy/engine/base.py", line 1130, in _execute_clauseelement
    distilled_params,
  File "/Library/Frameworks/Python.framework/Versions/3.6/lib/python3.6/site-packages/sqlalchemy/engine/base.py", line 1317, in _execute_context
    e, statement, parameters, cursor, context
  File "/Library/Frameworks/Python.framework/Versions/3.6/lib/python3.6/site-packages/sqlalchemy/engine/base.py", line 1511, in _handle_dbapi_exception
    sqlalchemy_exception, with_traceback=exc_info[2], from_=e
  File "/Library/Frameworks/Python.framework/Versions/3.6/lib/python3.6/site-packages/sqlalchemy/util/compat.py", line 182, in raise_
    raise exception
  File "/Library/Frameworks/Python.framework/Versions/3.6/lib/python3.6/site-packages/sqlalchemy/engine/base.py", line 1277, in _execute_context
    cursor, statement, parameters, context
  File "/Library/Frameworks/Python.framework/Versions/3.6/lib/python3.6/site-packages/sqlalchemy/engine/default.py", line 608, in do_execute
    cursor.execute(statement, parameters)
sqlalchemy.exc.OperationalError: (sqlite3.OperationalError) no such table: commitment_experiment
[SQL: SELECT commitment_experiment.uniqueid AS commitment_experiment_uniqueid, commitment_experiment.assignmentid AS commitment_experiment_assignmentid, commitment_experiment.workerid AS commitment_experiment_workerid, commitment_experiment.hitid AS commitment_experiment_hitid, commitment_experiment.ipaddress AS commitment_experiment_ipaddress, commitment_experiment.browser AS commitment_experiment_browser, commitment_experiment.platform AS commitment_experiment_platform, commitment_experiment.language AS commitment_experiment_language, commitment_experiment.cond AS commitment_experiment_cond, commitment_experiment.counterbalance AS commitment_experiment_counterbalance, commitment_experiment.codeversion AS commitment_experiment_codeversion, commitment_experiment.beginhit AS commitment_experiment_beginhit, commitment_experiment.beginexp AS commitment_experiment_beginexp, commitment_experiment.endhit AS commitment_experiment_endhit, commitment_experiment.bonus AS commitment_experiment_bonus, commitment_experiment.status AS commitment_experiment_status, commitment_experiment.mode AS commitment_experiment_mode 
FROM commitment_experiment 
WHERE commitment_experiment.workerid = ?]
[parameters: ('debugX97VM7',)]
(Background on this error at: http://sqlalche.me/e/13/e3q8)
2022-04-27 23:35:22,342 Accessing /exp: debugSBH9H4 debugOI8PAC debugX97VM7 
2022-04-27 23:35:22,365 Exception on /exp [GET]
Traceback (most recent call last):
  File "/Library/Frameworks/Python.framework/Versions/3.6/lib/python3.6/site-packages/sqlalchemy/engine/base.py", line 1277, in _execute_context
    cursor, statement, parameters, context
  File "/Library/Frameworks/Python.framework/Versions/3.6/lib/python3.6/site-packages/sqlalchemy/engine/default.py", line 608, in do_execute
    cursor.execute(statement, parameters)
sqlite3.OperationalError: no such table: commitment_experiment

The above exception was the direct cause of the following exception:

Traceback (most recent call last):
  File "/Library/Frameworks/Python.framework/Versions/3.6/lib/python3.6/site-packages/flask/app.py", line 2447, in wsgi_app
    response = self.full_dispatch_request()
  File "/Library/Frameworks/Python.framework/Versions/3.6/lib/python3.6/site-packages/flask/app.py", line 1952, in full_dispatch_request
    rv = self.handle_user_exception(e)
  File "/Library/Frameworks/Python.framework/Versions/3.6/lib/python3.6/site-packages/flask/app.py", line 1821, in handle_user_exception
    reraise(exc_type, exc_value, tb)
  File "/Library/Frameworks/Python.framework/Versions/3.6/lib/python3.6/site-packages/flask/_compat.py", line 39, in reraise
    raise value
  File "/Library/Frameworks/Python.framework/Versions/3.6/lib/python3.6/site-packages/flask/app.py", line 1950, in full_dispatch_request
    rv = self.dispatch_request()
  File "/Library/Frameworks/Python.framework/Versions/3.6/lib/python3.6/site-packages/flask/app.py", line 1936, in dispatch_request
    return self.view_functions[rule.endpoint](**req.view_args)
  File "/Library/Frameworks/Python.framework/Versions/3.6/lib/python3.6/site-packages/psiturk/user_utils.py", line 23, in new_func
    resp = make_response(func(*args, **kwargs))
  File "/Library/Frameworks/Python.framework/Versions/3.6/lib/python3.6/site-packages/psiturk/experiment.py", line 454, in start_exp
    filter(Participant.workerid == worker_id).\
  File "/Library/Frameworks/Python.framework/Versions/3.6/lib/python3.6/site-packages/sqlalchemy/orm/query.py", line 3373, in all
    return list(self)
  File "/Library/Frameworks/Python.framework/Versions/3.6/lib/python3.6/site-packages/sqlalchemy/orm/query.py", line 3535, in __iter__
    return self._execute_and_instances(context)
  File "/Library/Frameworks/Python.framework/Versions/3.6/lib/python3.6/site-packages/sqlalchemy/orm/query.py", line 3560, in _execute_and_instances
    result = conn.execute(querycontext.statement, self._params)
  File "/Library/Frameworks/Python.framework/Versions/3.6/lib/python3.6/site-packages/sqlalchemy/engine/base.py", line 1011, in execute
    return meth(self, multiparams, params)
  File "/Library/Frameworks/Python.framework/Versions/3.6/lib/python3.6/site-packages/sqlalchemy/sql/elements.py", line 298, in _execute_on_connection
    return connection._execute_clauseelement(self, multiparams, params)
  File "/Library/Frameworks/Python.framework/Versions/3.6/lib/python3.6/site-packages/sqlalchemy/engine/base.py", line 1130, in _execute_clauseelement
    distilled_params,
  File "/Library/Frameworks/Python.framework/Versions/3.6/lib/python3.6/site-packages/sqlalchemy/engine/base.py", line 1317, in _execute_context
    e, statement, parameters, cursor, context
  File "/Library/Frameworks/Python.framework/Versions/3.6/lib/python3.6/site-packages/sqlalchemy/engine/base.py", line 1511, in _handle_dbapi_exception
    sqlalchemy_exception, with_traceback=exc_info[2], from_=e
  File "/Library/Frameworks/Python.framework/Versions/3.6/lib/python3.6/site-packages/sqlalchemy/util/compat.py", line 182, in raise_
    raise exception
  File "/Library/Frameworks/Python.framework/Versions/3.6/lib/python3.6/site-packages/sqlalchemy/engine/base.py", line 1277, in _execute_context
    cursor, statement, parameters, context
  File "/Library/Frameworks/Python.framework/Versions/3.6/lib/python3.6/site-packages/sqlalchemy/engine/default.py", line 608, in do_execute
    cursor.execute(statement, parameters)
sqlalchemy.exc.OperationalError: (sqlite3.OperationalError) no such table: commitment_experiment
[SQL: SELECT commitment_experiment.uniqueid AS commitment_experiment_uniqueid, commitment_experiment.assignmentid AS commitment_experiment_assignmentid, commitment_experiment.workerid AS commitment_experiment_workerid, commitment_experiment.hitid AS commitment_experiment_hitid, commitment_experiment.ipaddress AS commitment_experiment_ipaddress, commitment_experiment.browser AS commitment_experiment_browser, commitment_experiment.platform AS commitment_experiment_platform, commitment_experiment.language AS commitment_experiment_language, commitment_experiment.cond AS commitment_experiment_cond, commitment_experiment.counterbalance AS commitment_experiment_counterbalance, commitment_experiment.codeversion AS commitment_experiment_codeversion, commitment_experiment.beginhit AS commitment_experiment_beginhit, commitment_experiment.beginexp AS commitment_experiment_beginexp, commitment_experiment.endhit AS commitment_experiment_endhit, commitment_experiment.bonus AS commitment_experiment_bonus, commitment_experiment.status AS commitment_experiment_status, commitment_experiment.mode AS commitment_experiment_mode 
FROM commitment_experiment 
WHERE commitment_experiment.workerid = ?]
[parameters: ('debugX97VM7',)]
(Background on this error at: http://sqlalche.me/e/13/e3q8)
2022-04-27 23:35:35,883 Accessing /exp: debugSBH9H4 debugOI8PAC debugX97VM7 
2022-04-27 23:35:35,896 Exception on /exp [GET]
Traceback (most recent call last):
  File "/Library/Frameworks/Python.framework/Versions/3.6/lib/python3.6/site-packages/sqlalchemy/engine/base.py", line 1277, in _execute_context
    cursor, statement, parameters, context
  File "/Library/Frameworks/Python.framework/Versions/3.6/lib/python3.6/site-packages/sqlalchemy/engine/default.py", line 608, in do_execute
    cursor.execute(statement, parameters)
sqlite3.OperationalError: no such table: commitment_experiment

The above exception was the direct cause of the following exception:

Traceback (most recent call last):
  File "/Library/Frameworks/Python.framework/Versions/3.6/lib/python3.6/site-packages/flask/app.py", line 2447, in wsgi_app
    response = self.full_dispatch_request()
  File "/Library/Frameworks/Python.framework/Versions/3.6/lib/python3.6/site-packages/flask/app.py", line 1952, in full_dispatch_request
    rv = self.handle_user_exception(e)
  File "/Library/Frameworks/Python.framework/Versions/3.6/lib/python3.6/site-packages/flask/app.py", line 1821, in handle_user_exception
    reraise(exc_type, exc_value, tb)
  File "/Library/Frameworks/Python.framework/Versions/3.6/lib/python3.6/site-packages/flask/_compat.py", line 39, in reraise
    raise value
  File "/Library/Frameworks/Python.framework/Versions/3.6/lib/python3.6/site-packages/flask/app.py", line 1950, in full_dispatch_request
    rv = self.dispatch_request()
  File "/Library/Frameworks/Python.framework/Versions/3.6/lib/python3.6/site-packages/flask/app.py", line 1936, in dispatch_request
    return self.view_functions[rule.endpoint](**req.view_args)
  File "/Library/Frameworks/Python.framework/Versions/3.6/lib/python3.6/site-packages/psiturk/user_utils.py", line 23, in new_func
    resp = make_response(func(*args, **kwargs))
  File "/Library/Frameworks/Python.framework/Versions/3.6/lib/python3.6/site-packages/psiturk/experiment.py", line 454, in start_exp
    filter(Participant.workerid == worker_id).\
  File "/Library/Frameworks/Python.framework/Versions/3.6/lib/python3.6/site-packages/sqlalchemy/orm/query.py", line 3373, in all
    return list(self)
  File "/Library/Frameworks/Python.framework/Versions/3.6/lib/python3.6/site-packages/sqlalchemy/orm/query.py", line 3535, in __iter__
    return self._execute_and_instances(context)
  File "/Library/Frameworks/Python.framework/Versions/3.6/lib/python3.6/site-packages/sqlalchemy/orm/query.py", line 3560, in _execute_and_instances
    result = conn.execute(querycontext.statement, self._params)
  File "/Library/Frameworks/Python.framework/Versions/3.6/lib/python3.6/site-packages/sqlalchemy/engine/base.py", line 1011, in execute
    return meth(self, multiparams, params)
  File "/Library/Frameworks/Python.framework/Versions/3.6/lib/python3.6/site-packages/sqlalchemy/sql/elements.py", line 298, in _execute_on_connection
    return connection._execute_clauseelement(self, multiparams, params)
  File "/Library/Frameworks/Python.framework/Versions/3.6/lib/python3.6/site-packages/sqlalchemy/engine/base.py", line 1130, in _execute_clauseelement
    distilled_params,
  File "/Library/Frameworks/Python.framework/Versions/3.6/lib/python3.6/site-packages/sqlalchemy/engine/base.py", line 1317, in _execute_context
    e, statement, parameters, cursor, context
  File "/Library/Frameworks/Python.framework/Versions/3.6/lib/python3.6/site-packages/sqlalchemy/engine/base.py", line 1511, in _handle_dbapi_exception
    sqlalchemy_exception, with_traceback=exc_info[2], from_=e
  File "/Library/Frameworks/Python.framework/Versions/3.6/lib/python3.6/site-packages/sqlalchemy/util/compat.py", line 182, in raise_
    raise exception
  File "/Library/Frameworks/Python.framework/Versions/3.6/lib/python3.6/site-packages/sqlalchemy/engine/base.py", line 1277, in _execute_context
    cursor, statement, parameters, context
  File "/Library/Frameworks/Python.framework/Versions/3.6/lib/python3.6/site-packages/sqlalchemy/engine/default.py", line 608, in do_execute
    cursor.execute(statement, parameters)
sqlalchemy.exc.OperationalError: (sqlite3.OperationalError) no such table: commitment_experiment
[SQL: SELECT commitment_experiment.uniqueid AS commitment_experiment_uniqueid, commitment_experiment.assignmentid AS commitment_experiment_assignmentid, commitment_experiment.workerid AS commitment_experiment_workerid, commitment_experiment.hitid AS commitment_experiment_hitid, commitment_experiment.ipaddress AS commitment_experiment_ipaddress, commitment_experiment.browser AS commitment_experiment_browser, commitment_experiment.platform AS commitment_experiment_platform, commitment_experiment.language AS commitment_experiment_language, commitment_experiment.cond AS commitment_experiment_cond, commitment_experiment.counterbalance AS commitment_experiment_counterbalance, commitment_experiment.codeversion AS commitment_experiment_codeversion, commitment_experiment.beginhit AS commitment_experiment_beginhit, commitment_experiment.beginexp AS commitment_experiment_beginexp, commitment_experiment.endhit AS commitment_experiment_endhit, commitment_experiment.bonus AS commitment_experiment_bonus, commitment_experiment.status AS commitment_experiment_status, commitment_experiment.mode AS commitment_experiment_mode 
FROM commitment_experiment 
WHERE commitment_experiment.workerid = ?]
[parameters: ('debugX97VM7',)]
(Background on this error at: http://sqlalche.me/e/13/e3q8)
2022-04-27 23:35:40,689 Accessing /exp: debugSBH9H4 debugOI8PAC debugX97VM7 
2022-04-27 23:35:40,694 Exception on /exp [GET]
Traceback (most recent call last):
  File "/Library/Frameworks/Python.framework/Versions/3.6/lib/python3.6/site-packages/sqlalchemy/engine/base.py", line 1277, in _execute_context
    cursor, statement, parameters, context
  File "/Library/Frameworks/Python.framework/Versions/3.6/lib/python3.6/site-packages/sqlalchemy/engine/default.py", line 608, in do_execute
    cursor.execute(statement, parameters)
sqlite3.OperationalError: no such table: commitment_experiment

The above exception was the direct cause of the following exception:

Traceback (most recent call last):
  File "/Library/Frameworks/Python.framework/Versions/3.6/lib/python3.6/site-packages/flask/app.py", line 2447, in wsgi_app
    response = self.full_dispatch_request()
  File "/Library/Frameworks/Python.framework/Versions/3.6/lib/python3.6/site-packages/flask/app.py", line 1952, in full_dispatch_request
    rv = self.handle_user_exception(e)
  File "/Library/Frameworks/Python.framework/Versions/3.6/lib/python3.6/site-packages/flask/app.py", line 1821, in handle_user_exception
    reraise(exc_type, exc_value, tb)
  File "/Library/Frameworks/Python.framework/Versions/3.6/lib/python3.6/site-packages/flask/_compat.py", line 39, in reraise
    raise value
  File "/Library/Frameworks/Python.framework/Versions/3.6/lib/python3.6/site-packages/flask/app.py", line 1950, in full_dispatch_request
    rv = self.dispatch_request()
  File "/Library/Frameworks/Python.framework/Versions/3.6/lib/python3.6/site-packages/flask/app.py", line 1936, in dispatch_request
    return self.view_functions[rule.endpoint](**req.view_args)
  File "/Library/Frameworks/Python.framework/Versions/3.6/lib/python3.6/site-packages/psiturk/user_utils.py", line 23, in new_func
    resp = make_response(func(*args, **kwargs))
  File "/Library/Frameworks/Python.framework/Versions/3.6/lib/python3.6/site-packages/psiturk/experiment.py", line 454, in start_exp
    filter(Participant.workerid == worker_id).\
  File "/Library/Frameworks/Python.framework/Versions/3.6/lib/python3.6/site-packages/sqlalchemy/orm/query.py", line 3373, in all
    return list(self)
  File "/Library/Frameworks/Python.framework/Versions/3.6/lib/python3.6/site-packages/sqlalchemy/orm/query.py", line 3535, in __iter__
    return self._execute_and_instances(context)
  File "/Library/Frameworks/Python.framework/Versions/3.6/lib/python3.6/site-packages/sqlalchemy/orm/query.py", line 3560, in _execute_and_instances
    result = conn.execute(querycontext.statement, self._params)
  File "/Library/Frameworks/Python.framework/Versions/3.6/lib/python3.6/site-packages/sqlalchemy/engine/base.py", line 1011, in execute
    return meth(self, multiparams, params)
  File "/Library/Frameworks/Python.framework/Versions/3.6/lib/python3.6/site-packages/sqlalchemy/sql/elements.py", line 298, in _execute_on_connection
    return connection._execute_clauseelement(self, multiparams, params)
  File "/Library/Frameworks/Python.framework/Versions/3.6/lib/python3.6/site-packages/sqlalchemy/engine/base.py", line 1130, in _execute_clauseelement
    distilled_params,
  File "/Library/Frameworks/Python.framework/Versions/3.6/lib/python3.6/site-packages/sqlalchemy/engine/base.py", line 1317, in _execute_context
    e, statement, parameters, cursor, context
  File "/Library/Frameworks/Python.framework/Versions/3.6/lib/python3.6/site-packages/sqlalchemy/engine/base.py", line 1511, in _handle_dbapi_exception
    sqlalchemy_exception, with_traceback=exc_info[2], from_=e
  File "/Library/Frameworks/Python.framework/Versions/3.6/lib/python3.6/site-packages/sqlalchemy/util/compat.py", line 182, in raise_
    raise exception
  File "/Library/Frameworks/Python.framework/Versions/3.6/lib/python3.6/site-packages/sqlalchemy/engine/base.py", line 1277, in _execute_context
    cursor, statement, parameters, context
  File "/Library/Frameworks/Python.framework/Versions/3.6/lib/python3.6/site-packages/sqlalchemy/engine/default.py", line 608, in do_execute
    cursor.execute(statement, parameters)
sqlalchemy.exc.OperationalError: (sqlite3.OperationalError) no such table: commitment_experiment
[SQL: SELECT commitment_experiment.uniqueid AS commitment_experiment_uniqueid, commitment_experiment.assignmentid AS commitment_experiment_assignmentid, commitment_experiment.workerid AS commitment_experiment_workerid, commitment_experiment.hitid AS commitment_experiment_hitid, commitment_experiment.ipaddress AS commitment_experiment_ipaddress, commitment_experiment.browser AS commitment_experiment_browser, commitment_experiment.platform AS commitment_experiment_platform, commitment_experiment.language AS commitment_experiment_language, commitment_experiment.cond AS commitment_experiment_cond, commitment_experiment.counterbalance AS commitment_experiment_counterbalance, commitment_experiment.codeversion AS commitment_experiment_codeversion, commitment_experiment.beginhit AS commitment_experiment_beginhit, commitment_experiment.beginexp AS commitment_experiment_beginexp, commitment_experiment.endhit AS commitment_experiment_endhit, commitment_experiment.bonus AS commitment_experiment_bonus, commitment_experiment.status AS commitment_experiment_status, commitment_experiment.mode AS commitment_experiment_mode 
FROM commitment_experiment 
WHERE commitment_experiment.workerid = ?]
[parameters: ('debugX97VM7',)]
(Background on this error at: http://sqlalche.me/e/13/e3q8)
2022-04-27 23:35:45,723 Accessing /exp: debugSBH9H4 debugOI8PAC debugX97VM7 
2022-04-27 23:35:45,725 Exception on /exp [GET]
Traceback (most recent call last):
  File "/Library/Frameworks/Python.framework/Versions/3.6/lib/python3.6/site-packages/sqlalchemy/engine/base.py", line 1277, in _execute_context
    cursor, statement, parameters, context
  File "/Library/Frameworks/Python.framework/Versions/3.6/lib/python3.6/site-packages/sqlalchemy/engine/default.py", line 608, in do_execute
    cursor.execute(statement, parameters)
sqlite3.OperationalError: no such table: commitment_experiment

The above exception was the direct cause of the following exception:

Traceback (most recent call last):
  File "/Library/Frameworks/Python.framework/Versions/3.6/lib/python3.6/site-packages/flask/app.py", line 2447, in wsgi_app
    response = self.full_dispatch_request()
  File "/Library/Frameworks/Python.framework/Versions/3.6/lib/python3.6/site-packages/flask/app.py", line 1952, in full_dispatch_request
    rv = self.handle_user_exception(e)
  File "/Library/Frameworks/Python.framework/Versions/3.6/lib/python3.6/site-packages/flask/app.py", line 1821, in handle_user_exception
    reraise(exc_type, exc_value, tb)
  File "/Library/Frameworks/Python.framework/Versions/3.6/lib/python3.6/site-packages/flask/_compat.py", line 39, in reraise
    raise value
  File "/Library/Frameworks/Python.framework/Versions/3.6/lib/python3.6/site-packages/flask/app.py", line 1950, in full_dispatch_request
    rv = self.dispatch_request()
  File "/Library/Frameworks/Python.framework/Versions/3.6/lib/python3.6/site-packages/flask/app.py", line 1936, in dispatch_request
    return self.view_functions[rule.endpoint](**req.view_args)
  File "/Library/Frameworks/Python.framework/Versions/3.6/lib/python3.6/site-packages/psiturk/user_utils.py", line 23, in new_func
    resp = make_response(func(*args, **kwargs))
  File "/Library/Frameworks/Python.framework/Versions/3.6/lib/python3.6/site-packages/psiturk/experiment.py", line 454, in start_exp
    filter(Participant.workerid == worker_id).\
  File "/Library/Frameworks/Python.framework/Versions/3.6/lib/python3.6/site-packages/sqlalchemy/orm/query.py", line 3373, in all
    return list(self)
  File "/Library/Frameworks/Python.framework/Versions/3.6/lib/python3.6/site-packages/sqlalchemy/orm/query.py", line 3535, in __iter__
    return self._execute_and_instances(context)
  File "/Library/Frameworks/Python.framework/Versions/3.6/lib/python3.6/site-packages/sqlalchemy/orm/query.py", line 3560, in _execute_and_instances
    result = conn.execute(querycontext.statement, self._params)
  File "/Library/Frameworks/Python.framework/Versions/3.6/lib/python3.6/site-packages/sqlalchemy/engine/base.py", line 1011, in execute
    return meth(self, multiparams, params)
  File "/Library/Frameworks/Python.framework/Versions/3.6/lib/python3.6/site-packages/sqlalchemy/sql/elements.py", line 298, in _execute_on_connection
    return connection._execute_clauseelement(self, multiparams, params)
  File "/Library/Frameworks/Python.framework/Versions/3.6/lib/python3.6/site-packages/sqlalchemy/engine/base.py", line 1130, in _execute_clauseelement
    distilled_params,
  File "/Library/Frameworks/Python.framework/Versions/3.6/lib/python3.6/site-packages/sqlalchemy/engine/base.py", line 1317, in _execute_context
    e, statement, parameters, cursor, context
  File "/Library/Frameworks/Python.framework/Versions/3.6/lib/python3.6/site-packages/sqlalchemy/engine/base.py", line 1511, in _handle_dbapi_exception
    sqlalchemy_exception, with_traceback=exc_info[2], from_=e
  File "/Library/Frameworks/Python.framework/Versions/3.6/lib/python3.6/site-packages/sqlalchemy/util/compat.py", line 182, in raise_
    raise exception
  File "/Library/Frameworks/Python.framework/Versions/3.6/lib/python3.6/site-packages/sqlalchemy/engine/base.py", line 1277, in _execute_context
    cursor, statement, parameters, context
  File "/Library/Frameworks/Python.framework/Versions/3.6/lib/python3.6/site-packages/sqlalchemy/engine/default.py", line 608, in do_execute
    cursor.execute(statement, parameters)
sqlalchemy.exc.OperationalError: (sqlite3.OperationalError) no such table: commitment_experiment
[SQL: SELECT commitment_experiment.uniqueid AS commitment_experiment_uniqueid, commitment_experiment.assignmentid AS commitment_experiment_assignmentid, commitment_experiment.workerid AS commitment_experiment_workerid, commitment_experiment.hitid AS commitment_experiment_hitid, commitment_experiment.ipaddress AS commitment_experiment_ipaddress, commitment_experiment.browser AS commitment_experiment_browser, commitment_experiment.platform AS commitment_experiment_platform, commitment_experiment.language AS commitment_experiment_language, commitment_experiment.cond AS commitment_experiment_cond, commitment_experiment.counterbalance AS commitment_experiment_counterbalance, commitment_experiment.codeversion AS commitment_experiment_codeversion, commitment_experiment.beginhit AS commitment_experiment_beginhit, commitment_experiment.beginexp AS commitment_experiment_beginexp, commitment_experiment.endhit AS commitment_experiment_endhit, commitment_experiment.bonus AS commitment_experiment_bonus, commitment_experiment.status AS commitment_experiment_status, commitment_experiment.mode AS commitment_experiment_mode 
FROM commitment_experiment 
WHERE commitment_experiment.workerid = ?]
[parameters: ('debugX97VM7',)]
(Background on this error at: http://sqlalche.me/e/13/e3q8)
2022-04-27 23:35:53,965 Accessing /exp: debugSBH9H4 debugOI8PAC debugX97VM7 
2022-04-27 23:35:53,999 Exception on /exp [GET]
Traceback (most recent call last):
  File "/Library/Frameworks/Python.framework/Versions/3.6/lib/python3.6/site-packages/sqlalchemy/engine/base.py", line 1277, in _execute_context
    cursor, statement, parameters, context
  File "/Library/Frameworks/Python.framework/Versions/3.6/lib/python3.6/site-packages/sqlalchemy/engine/default.py", line 608, in do_execute
    cursor.execute(statement, parameters)
sqlite3.OperationalError: no such table: commitment_experiment

The above exception was the direct cause of the following exception:

Traceback (most recent call last):
  File "/Library/Frameworks/Python.framework/Versions/3.6/lib/python3.6/site-packages/flask/app.py", line 2447, in wsgi_app
    response = self.full_dispatch_request()
  File "/Library/Frameworks/Python.framework/Versions/3.6/lib/python3.6/site-packages/flask/app.py", line 1952, in full_dispatch_request
    rv = self.handle_user_exception(e)
  File "/Library/Frameworks/Python.framework/Versions/3.6/lib/python3.6/site-packages/flask/app.py", line 1821, in handle_user_exception
    reraise(exc_type, exc_value, tb)
  File "/Library/Frameworks/Python.framework/Versions/3.6/lib/python3.6/site-packages/flask/_compat.py", line 39, in reraise
    raise value
  File "/Library/Frameworks/Python.framework/Versions/3.6/lib/python3.6/site-packages/flask/app.py", line 1950, in full_dispatch_request
    rv = self.dispatch_request()
  File "/Library/Frameworks/Python.framework/Versions/3.6/lib/python3.6/site-packages/flask/app.py", line 1936, in dispatch_request
    return self.view_functions[rule.endpoint](**req.view_args)
  File "/Library/Frameworks/Python.framework/Versions/3.6/lib/python3.6/site-packages/psiturk/user_utils.py", line 23, in new_func
    resp = make_response(func(*args, **kwargs))
  File "/Library/Frameworks/Python.framework/Versions/3.6/lib/python3.6/site-packages/psiturk/experiment.py", line 454, in start_exp
    filter(Participant.workerid == worker_id).\
  File "/Library/Frameworks/Python.framework/Versions/3.6/lib/python3.6/site-packages/sqlalchemy/orm/query.py", line 3373, in all
    return list(self)
  File "/Library/Frameworks/Python.framework/Versions/3.6/lib/python3.6/site-packages/sqlalchemy/orm/query.py", line 3535, in __iter__
    return self._execute_and_instances(context)
  File "/Library/Frameworks/Python.framework/Versions/3.6/lib/python3.6/site-packages/sqlalchemy/orm/query.py", line 3560, in _execute_and_instances
    result = conn.execute(querycontext.statement, self._params)
  File "/Library/Frameworks/Python.framework/Versions/3.6/lib/python3.6/site-packages/sqlalchemy/engine/base.py", line 1011, in execute
    return meth(self, multiparams, params)
  File "/Library/Frameworks/Python.framework/Versions/3.6/lib/python3.6/site-packages/sqlalchemy/sql/elements.py", line 298, in _execute_on_connection
    return connection._execute_clauseelement(self, multiparams, params)
  File "/Library/Frameworks/Python.framework/Versions/3.6/lib/python3.6/site-packages/sqlalchemy/engine/base.py", line 1130, in _execute_clauseelement
    distilled_params,
  File "/Library/Frameworks/Python.framework/Versions/3.6/lib/python3.6/site-packages/sqlalchemy/engine/base.py", line 1317, in _execute_context
    e, statement, parameters, cursor, context
  File "/Library/Frameworks/Python.framework/Versions/3.6/lib/python3.6/site-packages/sqlalchemy/engine/base.py", line 1511, in _handle_dbapi_exception
    sqlalchemy_exception, with_traceback=exc_info[2], from_=e
  File "/Library/Frameworks/Python.framework/Versions/3.6/lib/python3.6/site-packages/sqlalchemy/util/compat.py", line 182, in raise_
    raise exception
  File "/Library/Frameworks/Python.framework/Versions/3.6/lib/python3.6/site-packages/sqlalchemy/engine/base.py", line 1277, in _execute_context
    cursor, statement, parameters, context
  File "/Library/Frameworks/Python.framework/Versions/3.6/lib/python3.6/site-packages/sqlalchemy/engine/default.py", line 608, in do_execute
    cursor.execute(statement, parameters)
sqlalchemy.exc.OperationalError: (sqlite3.OperationalError) no such table: commitment_experiment
[SQL: SELECT commitment_experiment.uniqueid AS commitment_experiment_uniqueid, commitment_experiment.assignmentid AS commitment_experiment_assignmentid, commitment_experiment.workerid AS commitment_experiment_workerid, commitment_experiment.hitid AS commitment_experiment_hitid, commitment_experiment.ipaddress AS commitment_experiment_ipaddress, commitment_experiment.browser AS commitment_experiment_browser, commitment_experiment.platform AS commitment_experiment_platform, commitment_experiment.language AS commitment_experiment_language, commitment_experiment.cond AS commitment_experiment_cond, commitment_experiment.counterbalance AS commitment_experiment_counterbalance, commitment_experiment.codeversion AS commitment_experiment_codeversion, commitment_experiment.beginhit AS commitment_experiment_beginhit, commitment_experiment.beginexp AS commitment_experiment_beginexp, commitment_experiment.endhit AS commitment_experiment_endhit, commitment_experiment.bonus AS commitment_experiment_bonus, commitment_experiment.status AS commitment_experiment_status, commitment_experiment.mode AS commitment_experiment_mode 
FROM commitment_experiment 
WHERE commitment_experiment.workerid = ?]
[parameters: ('debugX97VM7',)]
(Background on this error at: http://sqlalche.me/e/13/e3q8)
2022-04-27 23:35:57,059 Accessing /exp: debugSBH9H4 debugOI8PAC debugX97VM7 
2022-04-27 23:35:57,061 Exception on /exp [GET]
Traceback (most recent call last):
  File "/Library/Frameworks/Python.framework/Versions/3.6/lib/python3.6/site-packages/sqlalchemy/engine/base.py", line 1277, in _execute_context
    cursor, statement, parameters, context
  File "/Library/Frameworks/Python.framework/Versions/3.6/lib/python3.6/site-packages/sqlalchemy/engine/default.py", line 608, in do_execute
    cursor.execute(statement, parameters)
sqlite3.OperationalError: no such table: commitment_experiment

The above exception was the direct cause of the following exception:

Traceback (most recent call last):
  File "/Library/Frameworks/Python.framework/Versions/3.6/lib/python3.6/site-packages/flask/app.py", line 2447, in wsgi_app
    response = self.full_dispatch_request()
  File "/Library/Frameworks/Python.framework/Versions/3.6/lib/python3.6/site-packages/flask/app.py", line 1952, in full_dispatch_request
    rv = self.handle_user_exception(e)
  File "/Library/Frameworks/Python.framework/Versions/3.6/lib/python3.6/site-packages/flask/app.py", line 1821, in handle_user_exception
    reraise(exc_type, exc_value, tb)
  File "/Library/Frameworks/Python.framework/Versions/3.6/lib/python3.6/site-packages/flask/_compat.py", line 39, in reraise
    raise value
  File "/Library/Frameworks/Python.framework/Versions/3.6/lib/python3.6/site-packages/flask/app.py", line 1950, in full_dispatch_request
    rv = self.dispatch_request()
  File "/Library/Frameworks/Python.framework/Versions/3.6/lib/python3.6/site-packages/flask/app.py", line 1936, in dispatch_request
    return self.view_functions[rule.endpoint](**req.view_args)
  File "/Library/Frameworks/Python.framework/Versions/3.6/lib/python3.6/site-packages/psiturk/user_utils.py", line 23, in new_func
    resp = make_response(func(*args, **kwargs))
  File "/Library/Frameworks/Python.framework/Versions/3.6/lib/python3.6/site-packages/psiturk/experiment.py", line 454, in start_exp
    filter(Participant.workerid == worker_id).\
  File "/Library/Frameworks/Python.framework/Versions/3.6/lib/python3.6/site-packages/sqlalchemy/orm/query.py", line 3373, in all
    return list(self)
  File "/Library/Frameworks/Python.framework/Versions/3.6/lib/python3.6/site-packages/sqlalchemy/orm/query.py", line 3535, in __iter__
    return self._execute_and_instances(context)
  File "/Library/Frameworks/Python.framework/Versions/3.6/lib/python3.6/site-packages/sqlalchemy/orm/query.py", line 3560, in _execute_and_instances
    result = conn.execute(querycontext.statement, self._params)
  File "/Library/Frameworks/Python.framework/Versions/3.6/lib/python3.6/site-packages/sqlalchemy/engine/base.py", line 1011, in execute
    return meth(self, multiparams, params)
  File "/Library/Frameworks/Python.framework/Versions/3.6/lib/python3.6/site-packages/sqlalchemy/sql/elements.py", line 298, in _execute_on_connection
    return connection._execute_clauseelement(self, multiparams, params)
  File "/Library/Frameworks/Python.framework/Versions/3.6/lib/python3.6/site-packages/sqlalchemy/engine/base.py", line 1130, in _execute_clauseelement
    distilled_params,
  File "/Library/Frameworks/Python.framework/Versions/3.6/lib/python3.6/site-packages/sqlalchemy/engine/base.py", line 1317, in _execute_context
    e, statement, parameters, cursor, context
  File "/Library/Frameworks/Python.framework/Versions/3.6/lib/python3.6/site-packages/sqlalchemy/engine/base.py", line 1511, in _handle_dbapi_exception
    sqlalchemy_exception, with_traceback=exc_info[2], from_=e
  File "/Library/Frameworks/Python.framework/Versions/3.6/lib/python3.6/site-packages/sqlalchemy/util/compat.py", line 182, in raise_
    raise exception
  File "/Library/Frameworks/Python.framework/Versions/3.6/lib/python3.6/site-packages/sqlalchemy/engine/base.py", line 1277, in _execute_context
    cursor, statement, parameters, context
  File "/Library/Frameworks/Python.framework/Versions/3.6/lib/python3.6/site-packages/sqlalchemy/engine/default.py", line 608, in do_execute
    cursor.execute(statement, parameters)
sqlalchemy.exc.OperationalError: (sqlite3.OperationalError) no such table: commitment_experiment
[SQL: SELECT commitment_experiment.uniqueid AS commitment_experiment_uniqueid, commitment_experiment.assignmentid AS commitment_experiment_assignmentid, commitment_experiment.workerid AS commitment_experiment_workerid, commitment_experiment.hitid AS commitment_experiment_hitid, commitment_experiment.ipaddress AS commitment_experiment_ipaddress, commitment_experiment.browser AS commitment_experiment_browser, commitment_experiment.platform AS commitment_experiment_platform, commitment_experiment.language AS commitment_experiment_language, commitment_experiment.cond AS commitment_experiment_cond, commitment_experiment.counterbalance AS commitment_experiment_counterbalance, commitment_experiment.codeversion AS commitment_experiment_codeversion, commitment_experiment.beginhit AS commitment_experiment_beginhit, commitment_experiment.beginexp AS commitment_experiment_beginexp, commitment_experiment.endhit AS commitment_experiment_endhit, commitment_experiment.bonus AS commitment_experiment_bonus, commitment_experiment.status AS commitment_experiment_status, commitment_experiment.mode AS commitment_experiment_mode 
FROM commitment_experiment 
WHERE commitment_experiment.workerid = ?]
[parameters: ('debugX97VM7',)]
(Background on this error at: http://sqlalche.me/e/13/e3q8)
2022-04-27 23:36:03,408 Accessing /exp: debugSBH9H4 debugOI8PAC debugX97VM7 
2022-04-27 23:36:03,414 Exception on /exp [GET]
Traceback (most recent call last):
  File "/Library/Frameworks/Python.framework/Versions/3.6/lib/python3.6/site-packages/sqlalchemy/engine/base.py", line 1277, in _execute_context
    cursor, statement, parameters, context
  File "/Library/Frameworks/Python.framework/Versions/3.6/lib/python3.6/site-packages/sqlalchemy/engine/default.py", line 608, in do_execute
    cursor.execute(statement, parameters)
sqlite3.OperationalError: no such table: commitment_experiment

The above exception was the direct cause of the following exception:

Traceback (most recent call last):
  File "/Library/Frameworks/Python.framework/Versions/3.6/lib/python3.6/site-packages/flask/app.py", line 2447, in wsgi_app
    response = self.full_dispatch_request()
  File "/Library/Frameworks/Python.framework/Versions/3.6/lib/python3.6/site-packages/flask/app.py", line 1952, in full_dispatch_request
    rv = self.handle_user_exception(e)
  File "/Library/Frameworks/Python.framework/Versions/3.6/lib/python3.6/site-packages/flask/app.py", line 1821, in handle_user_exception
    reraise(exc_type, exc_value, tb)
  File "/Library/Frameworks/Python.framework/Versions/3.6/lib/python3.6/site-packages/flask/_compat.py", line 39, in reraise
    raise value
  File "/Library/Frameworks/Python.framework/Versions/3.6/lib/python3.6/site-packages/flask/app.py", line 1950, in full_dispatch_request
    rv = self.dispatch_request()
  File "/Library/Frameworks/Python.framework/Versions/3.6/lib/python3.6/site-packages/flask/app.py", line 1936, in dispatch_request
    return self.view_functions[rule.endpoint](**req.view_args)
  File "/Library/Frameworks/Python.framework/Versions/3.6/lib/python3.6/site-packages/psiturk/user_utils.py", line 23, in new_func
    resp = make_response(func(*args, **kwargs))
  File "/Library/Frameworks/Python.framework/Versions/3.6/lib/python3.6/site-packages/psiturk/experiment.py", line 454, in start_exp
    filter(Participant.workerid == worker_id).\
  File "/Library/Frameworks/Python.framework/Versions/3.6/lib/python3.6/site-packages/sqlalchemy/orm/query.py", line 3373, in all
    return list(self)
  File "/Library/Frameworks/Python.framework/Versions/3.6/lib/python3.6/site-packages/sqlalchemy/orm/query.py", line 3535, in __iter__
    return self._execute_and_instances(context)
  File "/Library/Frameworks/Python.framework/Versions/3.6/lib/python3.6/site-packages/sqlalchemy/orm/query.py", line 3560, in _execute_and_instances
    result = conn.execute(querycontext.statement, self._params)
  File "/Library/Frameworks/Python.framework/Versions/3.6/lib/python3.6/site-packages/sqlalchemy/engine/base.py", line 1011, in execute
    return meth(self, multiparams, params)
  File "/Library/Frameworks/Python.framework/Versions/3.6/lib/python3.6/site-packages/sqlalchemy/sql/elements.py", line 298, in _execute_on_connection
    return connection._execute_clauseelement(self, multiparams, params)
  File "/Library/Frameworks/Python.framework/Versions/3.6/lib/python3.6/site-packages/sqlalchemy/engine/base.py", line 1130, in _execute_clauseelement
    distilled_params,
  File "/Library/Frameworks/Python.framework/Versions/3.6/lib/python3.6/site-packages/sqlalchemy/engine/base.py", line 1317, in _execute_context
    e, statement, parameters, cursor, context
  File "/Library/Frameworks/Python.framework/Versions/3.6/lib/python3.6/site-packages/sqlalchemy/engine/base.py", line 1511, in _handle_dbapi_exception
    sqlalchemy_exception, with_traceback=exc_info[2], from_=e
  File "/Library/Frameworks/Python.framework/Versions/3.6/lib/python3.6/site-packages/sqlalchemy/util/compat.py", line 182, in raise_
    raise exception
  File "/Library/Frameworks/Python.framework/Versions/3.6/lib/python3.6/site-packages/sqlalchemy/engine/base.py", line 1277, in _execute_context
    cursor, statement, parameters, context
  File "/Library/Frameworks/Python.framework/Versions/3.6/lib/python3.6/site-packages/sqlalchemy/engine/default.py", line 608, in do_execute
    cursor.execute(statement, parameters)
sqlalchemy.exc.OperationalError: (sqlite3.OperationalError) no such table: commitment_experiment
[SQL: SELECT commitment_experiment.uniqueid AS commitment_experiment_uniqueid, commitment_experiment.assignmentid AS commitment_experiment_assignmentid, commitment_experiment.workerid AS commitment_experiment_workerid, commitment_experiment.hitid AS commitment_experiment_hitid, commitment_experiment.ipaddress AS commitment_experiment_ipaddress, commitment_experiment.browser AS commitment_experiment_browser, commitment_experiment.platform AS commitment_experiment_platform, commitment_experiment.language AS commitment_experiment_language, commitment_experiment.cond AS commitment_experiment_cond, commitment_experiment.counterbalance AS commitment_experiment_counterbalance, commitment_experiment.codeversion AS commitment_experiment_codeversion, commitment_experiment.beginhit AS commitment_experiment_beginhit, commitment_experiment.beginexp AS commitment_experiment_beginexp, commitment_experiment.endhit AS commitment_experiment_endhit, commitment_experiment.bonus AS commitment_experiment_bonus, commitment_experiment.status AS commitment_experiment_status, commitment_experiment.mode AS commitment_experiment_mode 
FROM commitment_experiment 
WHERE commitment_experiment.workerid = ?]
[parameters: ('debugX97VM7',)]
(Background on this error at: http://sqlalche.me/e/13/e3q8)
[2022-04-27 23:36:18 +0800] [68720] [INFO] Handling signal: term
[2022-04-27 23:36:18 +0800] [68734] [INFO] Worker exiting (pid: 68734)
[2022-04-27 23:36:18 +0800] [68733] [INFO] Worker exiting (pid: 68733)
[2022-04-27 23:36:18 +0800] [68732] [INFO] Worker exiting (pid: 68732)
[2022-04-27 23:36:18 +0800] [68736] [INFO] Worker exiting (pid: 68736)
[2022-04-27 23:36:18 +0800] [68735] [INFO] Worker exiting (pid: 68735)
[2022-04-27 23:36:18 +0800] [70042] [INFO] Worker exiting (pid: 70042)
[2022-04-27 23:36:18 +0800] [68731] [INFO] Worker exiting (pid: 68731)
[2022-04-27 23:36:18 +0800] [68730] [INFO] Worker exiting (pid: 68730)
[2022-04-27 23:36:19 +0800] [68729] [INFO] Worker exiting (pid: 68729)
[2022-04-27 23:36:19 +0800] [68720] [INFO] Shutting down: Master
[2022-04-27 23:36:24 +0800] [74425] [INFO] Starting gunicorn 20.0.4
[2022-04-27 23:36:24 +0800] [74425] [INFO] Listening at: http://0.0.0.0:50003 (74425)
[2022-04-27 23:36:24 +0800] [74425] [INFO] Using worker: gevent
[2022-04-27 23:36:24 +0800] [74429] [INFO] Booting worker with pid: 74429
[2022-04-27 23:36:24 +0800] [74430] [INFO] Booting worker with pid: 74430
[2022-04-27 23:36:24 +0800] [74431] [INFO] Booting worker with pid: 74431
[2022-04-27 23:36:24 +0800] [74432] [INFO] Booting worker with pid: 74432
[2022-04-27 23:36:24 +0800] [74433] [INFO] Booting worker with pid: 74433
[2022-04-27 23:36:24 +0800] [74434] [INFO] Booting worker with pid: 74434
[2022-04-27 23:36:24 +0800] [74435] [INFO] Booting worker with pid: 74435
[2022-04-27 23:36:24 +0800] [74437] [INFO] Booting worker with pid: 74437
[2022-04-27 23:36:24 +0800] [74439] [INFO] Booting worker with pid: 74439
2022-04-27 23:36:26,468 Starting scheduler in 'paused' mode -- it will not run any tasks, but it can be used to create, modify, or delete tasks.
2022-04-27 23:36:26,479 Scheduler started
2022-04-27 23:36:26,581 /Library/Frameworks/Python.framework/Versions/3.6/lib/python3.6/site-packages/psiturk/psiturk_js/psiturk.js
2022-04-27 23:36:27,049 Starting scheduler in 'paused' mode -- it will not run any tasks, but it can be used to create, modify, or delete tasks.
2022-04-27 23:36:27,055 Scheduler started
2022-04-27 23:36:27,061 /Library/Frameworks/Python.framework/Versions/3.6/lib/python3.6/site-packages/psiturk/psiturk_js/psiturk.js
2022-04-27 23:36:27,116 Starting scheduler in 'paused' mode -- it will not run any tasks, but it can be used to create, modify, or delete tasks.
2022-04-27 23:36:27,141 Scheduler started
2022-04-27 23:36:27,143 /Library/Frameworks/Python.framework/Versions/3.6/lib/python3.6/site-packages/psiturk/psiturk_js/psiturk.js
2022-04-27 23:36:27,217 Starting scheduler in 'paused' mode -- it will not run any tasks, but it can be used to create, modify, or delete tasks.
2022-04-27 23:36:27,221 Scheduler started
2022-04-27 23:36:27,263 /Library/Frameworks/Python.framework/Versions/3.6/lib/python3.6/site-packages/psiturk/psiturk_js/psiturk.js
2022-04-27 23:36:27,385 Starting scheduler in 'paused' mode -- it will not run any tasks, but it can be used to create, modify, or delete tasks.
2022-04-27 23:36:27,388 Scheduler started
2022-04-27 23:36:27,395 /Library/Frameworks/Python.framework/Versions/3.6/lib/python3.6/site-packages/psiturk/psiturk_js/psiturk.js
2022-04-27 23:36:27,476 Starting scheduler in 'paused' mode -- it will not run any tasks, but it can be used to create, modify, or delete tasks.
2022-04-27 23:36:27,483 Scheduler started
2022-04-27 23:36:27,721 /Library/Frameworks/Python.framework/Versions/3.6/lib/python3.6/site-packages/psiturk/psiturk_js/psiturk.js
2022-04-27 23:36:27,850 Starting scheduler in 'paused' mode -- it will not run any tasks, but it can be used to create, modify, or delete tasks.
2022-04-27 23:36:27,961 Scheduler started
2022-04-27 23:36:28,008 /Library/Frameworks/Python.framework/Versions/3.6/lib/python3.6/site-packages/psiturk/psiturk_js/psiturk.js
2022-04-27 23:36:28,143 Starting scheduler in 'paused' mode -- it will not run any tasks, but it can be used to create, modify, or delete tasks.
2022-04-27 23:36:28,209 Scheduler started
2022-04-27 23:36:28,211 /Library/Frameworks/Python.framework/Versions/3.6/lib/python3.6/site-packages/psiturk/psiturk_js/psiturk.js
2022-04-27 23:36:28,206 Starting scheduler in 'paused' mode -- it will not run any tasks, but it can be used to create, modify, or delete tasks.
2022-04-27 23:36:28,239 Scheduler started
2022-04-27 23:36:28,242 /Library/Frameworks/Python.framework/Versions/3.6/lib/python3.6/site-packages/psiturk/psiturk_js/psiturk.js
2022-04-27 23:36:34,104 Accessing /exp: debugBXFV7S debug5QN1VO debugDO3XYU 
2022-04-27 23:36:34,117 given Counter({(0, 0): 0}) chose (0, 0)
2022-04-27 23:36:34,303 GET /sync route with id: debugDO3XYU:debug5QN1VO
2022-04-27 23:36:46,397 Accessing /exp: debugBXFV7S debug5QN1VO debugDO3XYU 
2022-04-27 23:36:46,557 GET /sync route with id: debugDO3XYU:debug5QN1VO
2022-04-27 23:37:02,821 Accessing /exp: debugBXFV7S debug5QN1VO debugDO3XYU 
2022-04-27 23:37:03,060 GET /sync route with id: debugDO3XYU:debug5QN1VO
2022-04-27 23:37:05,947 PUT /sync route with id: debugDO3XYU:debug5QN1VO
2022-04-27 23:37:05,949 Accessing /inexp
2022-04-27 23:37:05,965 saved data for debugDO3XYU:debug5QN1VO (current trial: 2)
2022-04-27 23:37:34,982 Accessing /exp: debugBXFV7S debug5QN1VO debugDO3XYU 
2022-04-27 23:37:35,243 GET /sync route with id: debugDO3XYU:debug5QN1VO
2022-04-27 23:37:36,887 Accessing /inexp
2022-04-27 23:37:36,887 PUT /sync route with id: debugDO3XYU:debug5QN1VO
2022-04-27 23:37:36,909 saved data for debugDO3XYU:debug5QN1VO (current trial: 4)
2022-04-27 23:37:45,577 Accessing /exp: debugBXFV7S debug5QN1VO debugDO3XYU 
2022-04-27 23:37:45,767 GET /sync route with id: debugDO3XYU:debug5QN1VO
2022-04-27 23:37:47,226 PUT /sync route with id: debugDO3XYU:debug5QN1VO
2022-04-27 23:37:47,240 saved data for debugDO3XYU:debug5QN1VO (current trial: 6)
2022-04-27 23:37:47,243 Accessing /inexp
2022-04-27 23:38:19,909 Accessing /exp: debugBXFV7S debug5QN1VO debugDO3XYU 
2022-04-27 23:38:20,046 GET /sync route with id: debugDO3XYU:debug5QN1VO
2022-04-27 23:38:27,438 Accessing /exp: debugBXFV7S debug5QN1VO debugDO3XYU 
2022-04-27 23:38:27,784 GET /sync route with id: debugDO3XYU:debug5QN1VO
2022-04-27 23:38:32,565 Accessing /exp: debugBXFV7S debug5QN1VO debugDO3XYU 
2022-04-27 23:38:32,783 GET /sync route with id: debugDO3XYU:debug5QN1VO
2022-04-27 23:39:15,356 Accessing /inexp
2022-04-27 23:39:15,357 PUT /sync route with id: debugDO3XYU:debug5QN1VO
2022-04-27 23:39:15,368 saved data for debugDO3XYU:debug5QN1VO (current trial: 8)
[2022-04-27 23:41:34 +0800] [74425] [INFO] Handling signal: term
[2022-04-27 23:41:34 +0800] [74431] [INFO] Worker exiting (pid: 74431)
[2022-04-27 23:41:34 +0800] [74430] [INFO] Worker exiting (pid: 74430)
[2022-04-27 23:41:34 +0800] [74439] [INFO] Worker exiting (pid: 74439)
[2022-04-27 23:41:34 +0800] [74435] [INFO] Worker exiting (pid: 74435)
[2022-04-27 23:41:34 +0800] [74433] [INFO] Worker exiting (pid: 74433)
[2022-04-27 23:41:34 +0800] [74432] [INFO] Worker exiting (pid: 74432)
[2022-04-27 23:41:34 +0800] [74437] [INFO] Worker exiting (pid: 74437)
[2022-04-27 23:41:35 +0800] [74429] [INFO] Worker exiting (pid: 74429)
[2022-04-27 23:41:35 +0800] [74434] [INFO] Worker exiting (pid: 74434)
[2022-04-27 23:41:35 +0800] [74425] [INFO] Shutting down: Master
[2022-04-28 02:21:36 +0800] [10463] [CRITICAL] WORKER TIMEOUT (pid:10470)
[2022-04-28 02:21:36 +0800] [10463] [CRITICAL] WORKER TIMEOUT (pid:10473)
[2022-04-28 02:21:36 +0800] [10463] [CRITICAL] WORKER TIMEOUT (pid:70043)
2022-04-28 02:21:57,810 Starting scheduler in 'paused' mode -- it will not run any tasks, but it can be used to create, modify, or delete tasks.
2022-04-28 02:21:57,818 Starting scheduler in 'paused' mode -- it will not run any tasks, but it can be used to create, modify, or delete tasks.
2022-04-28 02:21:57,823 Scheduler started
2022-04-28 02:21:57,825 Scheduler started
2022-04-28 02:21:57,827 /Library/Frameworks/Python.framework/Versions/3.6/lib/python3.6/site-packages/psiturk/psiturk_js/psiturk.js
2022-04-28 02:21:57,828 /Library/Frameworks/Python.framework/Versions/3.6/lib/python3.6/site-packages/psiturk/psiturk_js/psiturk.js
2022-04-28 02:21:57,839 Starting scheduler in 'paused' mode -- it will not run any tasks, but it can be used to create, modify, or delete tasks.
2022-04-28 02:21:57,845 Scheduler started
2022-04-28 02:21:57,849 /Library/Frameworks/Python.framework/Versions/3.6/lib/python3.6/site-packages/psiturk/psiturk_js/psiturk.js
[2022-04-28 07:19:31 +0800] [10463] [CRITICAL] WORKER TIMEOUT (pid:10472)
2022-04-28 07:19:42,168 Starting scheduler in 'paused' mode -- it will not run any tasks, but it can be used to create, modify, or delete tasks.
2022-04-28 07:19:42,180 Scheduler started
2022-04-28 07:19:42,183 /Library/Frameworks/Python.framework/Versions/3.6/lib/python3.6/site-packages/psiturk/psiturk_js/psiturk.js
[2022-04-28 07:59:04 +0800] [10463] [CRITICAL] WORKER TIMEOUT (pid:18283)
2022-04-28 07:59:09,502 Starting scheduler in 'paused' mode -- it will not run any tasks, but it can be used to create, modify, or delete tasks.
2022-04-28 07:59:09,511 Scheduler started
2022-04-28 07:59:09,512 /Library/Frameworks/Python.framework/Versions/3.6/lib/python3.6/site-packages/psiturk/psiturk_js/psiturk.js
[2022-04-28 21:55:38 +0800] [11554] [INFO] Starting gunicorn 20.0.4
[2022-04-28 21:55:38 +0800] [11554] [INFO] Listening at: http://0.0.0.0:50003 (11554)
[2022-04-28 21:55:38 +0800] [11554] [INFO] Using worker: gevent
[2022-04-28 21:55:38 +0800] [11557] [INFO] Booting worker with pid: 11557
[2022-04-28 21:55:38 +0800] [11558] [INFO] Booting worker with pid: 11558
[2022-04-28 21:55:39 +0800] [11559] [INFO] Booting worker with pid: 11559
[2022-04-28 21:55:39 +0800] [11560] [INFO] Booting worker with pid: 11560
[2022-04-28 21:55:39 +0800] [11561] [INFO] Booting worker with pid: 11561
[2022-04-28 21:55:39 +0800] [11562] [INFO] Booting worker with pid: 11562
[2022-04-28 21:55:39 +0800] [11563] [INFO] Booting worker with pid: 11563
[2022-04-28 21:55:39 +0800] [11564] [INFO] Booting worker with pid: 11564
[2022-04-28 21:55:39 +0800] [11565] [INFO] Booting worker with pid: 11565
2022-04-28 21:55:41,573 Starting scheduler in 'paused' mode -- it will not run any tasks, but it can be used to create, modify, or delete tasks.
2022-04-28 21:55:41,578 Scheduler started
2022-04-28 21:55:41,581 /Library/Frameworks/Python.framework/Versions/3.6/lib/python3.6/site-packages/psiturk/psiturk_js/psiturk.js
2022-04-28 21:55:42,664 Starting scheduler in 'paused' mode -- it will not run any tasks, but it can be used to create, modify, or delete tasks.
2022-04-28 21:55:42,667 Scheduler started
2022-04-28 21:55:42,883 /Library/Frameworks/Python.framework/Versions/3.6/lib/python3.6/site-packages/psiturk/psiturk_js/psiturk.js
2022-04-28 21:55:43,607 Starting scheduler in 'paused' mode -- it will not run any tasks, but it can be used to create, modify, or delete tasks.
2022-04-28 21:55:43,625 Scheduler started
2022-04-28 21:55:43,627 /Library/Frameworks/Python.framework/Versions/3.6/lib/python3.6/site-packages/psiturk/psiturk_js/psiturk.js
2022-04-28 21:55:43,692 Starting scheduler in 'paused' mode -- it will not run any tasks, but it can be used to create, modify, or delete tasks.
2022-04-28 21:55:43,695 Scheduler started
2022-04-28 21:55:43,725 Starting scheduler in 'paused' mode -- it will not run any tasks, but it can be used to create, modify, or delete tasks.
2022-04-28 21:55:43,731 /Library/Frameworks/Python.framework/Versions/3.6/lib/python3.6/site-packages/psiturk/psiturk_js/psiturk.js
2022-04-28 21:55:43,746 Scheduler started
2022-04-28 21:55:43,755 /Library/Frameworks/Python.framework/Versions/3.6/lib/python3.6/site-packages/psiturk/psiturk_js/psiturk.js
2022-04-28 21:55:43,767 Starting scheduler in 'paused' mode -- it will not run any tasks, but it can be used to create, modify, or delete tasks.
2022-04-28 21:55:43,805 Scheduler started
2022-04-28 21:55:43,807 /Library/Frameworks/Python.framework/Versions/3.6/lib/python3.6/site-packages/psiturk/psiturk_js/psiturk.js
2022-04-28 21:55:43,851 Starting scheduler in 'paused' mode -- it will not run any tasks, but it can be used to create, modify, or delete tasks.
2022-04-28 21:55:43,859 Scheduler started
2022-04-28 21:55:43,859 Starting scheduler in 'paused' mode -- it will not run any tasks, but it can be used to create, modify, or delete tasks.
2022-04-28 21:55:43,860 /Library/Frameworks/Python.framework/Versions/3.6/lib/python3.6/site-packages/psiturk/psiturk_js/psiturk.js
2022-04-28 21:55:43,861 Scheduler started
2022-04-28 21:55:43,862 Starting scheduler in 'paused' mode -- it will not run any tasks, but it can be used to create, modify, or delete tasks.
2022-04-28 21:55:43,863 /Library/Frameworks/Python.framework/Versions/3.6/lib/python3.6/site-packages/psiturk/psiturk_js/psiturk.js
2022-04-28 21:55:43,873 Scheduler started
2022-04-28 21:55:43,876 /Library/Frameworks/Python.framework/Versions/3.6/lib/python3.6/site-packages/psiturk/psiturk_js/psiturk.js
2022-04-28 21:55:49,441 Accessing /exp: debugOR2A7J debugBMCGJY debug0FST30 
2022-04-28 21:55:49,454 given Counter({(0, 0): 0}) chose (0, 0)
2022-04-28 21:55:49,692 GET /sync route with id: debug0FST30:debugBMCGJY
2022-04-28 21:55:51,608 PUT /sync route with id: debug0FST30:debugBMCGJY
2022-04-28 21:55:51,615 saved data for debug0FST30:debugBMCGJY (current trial: 2)
2022-04-28 21:55:51,617 Accessing /inexp
2022-04-28 21:56:32,207 PUT /sync route with id: debug0FST30:debugBMCGJY
2022-04-28 21:56:32,227 saved data for debug0FST30:debugBMCGJY (current trial: 65)
2022-04-28 21:56:37,237 PUT /sync route with id: debug0FST30:debugBMCGJY
2022-04-28 21:56:37,277 saved data for debug0FST30:debugBMCGJY (current trial: 66)
2022-04-28 21:56:40,597 PUT /sync route with id: debug0FST30:debugBMCGJY
2022-04-28 21:56:40,619 saved data for debug0FST30:debugBMCGJY (current trial: 67)
2022-04-28 21:56:48,168 PUT /sync route with id: debug0FST30:debugBMCGJY
2022-04-28 21:56:48,192 saved data for debug0FST30:debugBMCGJY (current trial: 68)
2022-04-28 21:56:49,533 PUT /sync route with id: debug0FST30:debugBMCGJY
2022-04-28 21:56:49,582 saved data for debug0FST30:debugBMCGJY (current trial: 69)
2022-04-28 21:56:49,803 PUT /sync route with id: debug0FST30:debugBMCGJY
2022-04-28 21:56:49,828 saved data for debug0FST30:debugBMCGJY (current trial: 70)
[2022-04-28 21:57:06 +0800] [11554] [INFO] Handling signal: winch
2022-04-28 21:58:36,234 PUT /sync route with id: debug0FST30:debugBMCGJY
2022-04-28 21:58:36,268 saved data for debug0FST30:debugBMCGJY (current trial: 71)
2022-04-28 21:58:38,671 PUT /sync route with id: debug0FST30:debugBMCGJY
2022-04-28 21:58:38,706 saved data for debug0FST30:debugBMCGJY (current trial: 72)
2022-04-28 22:14:12,791 Accessing /exp: debugPG5USK debugQNJ5BE debugRUUS0G 
2022-04-28 22:14:12,799 given Counter({(0, 0): 1}) chose (0, 0)
2022-04-28 22:14:13,012 GET /sync route with id: debugRUUS0G:debugQNJ5BE
2022-04-28 22:14:14,651 PUT /sync route with id: debugRUUS0G:debugQNJ5BE
2022-04-28 22:14:14,651 Accessing /inexp
2022-04-28 22:14:14,668 saved data for debugRUUS0G:debugQNJ5BE (current trial: 2)
2022-04-28 22:16:04,581 Accessing /exp: debugPG5USK debugQNJ5BE debugRUUS0G 
2022-04-28 22:16:04,767 GET /sync route with id: debugRUUS0G:debugQNJ5BE
2022-04-28 22:16:05,880 PUT /sync route with id: debugRUUS0G:debugQNJ5BE
2022-04-28 22:16:05,881 Accessing /inexp
2022-04-28 22:16:05,890 saved data for debugRUUS0G:debugQNJ5BE (current trial: 4)
2022-04-28 22:16:24,556 PUT /sync route with id: debugRUUS0G:debugQNJ5BE
2022-04-28 22:16:24,572 saved data for debugRUUS0G:debugQNJ5BE (current trial: 55)
2022-04-28 22:25:08,926 Accessing /exp: debugPG5USK debugQNJ5BE debugRUUS0G 
2022-04-28 22:25:59,855 Accessing /exp: debugPG5USK debugQNJ5BE debugRUUS0G 
2022-04-28 22:26:00,245 GET /sync route with id: debugRUUS0G:debugQNJ5BE
2022-04-28 22:26:01,371 PUT /sync route with id: debugRUUS0G:debugQNJ5BE
2022-04-28 22:26:01,393 saved data for debugRUUS0G:debugQNJ5BE (current trial: 57)
2022-04-28 22:26:01,398 Accessing /inexp
2022-04-28 22:26:22,921 PUT /sync route with id: debugRUUS0G:debugQNJ5BE
2022-04-28 22:26:23,028 saved data for debugRUUS0G:debugQNJ5BE (current trial: 113)
2022-04-28 22:29:26,588 Accessing /exp: debugPG5USK debugQNJ5BE debugRUUS0G 
2022-04-28 22:43:05,879 Accessing /exp: debugPG5USK debugQNJ5BE debugRUUS0G 
2022-04-28 22:43:06,140 GET /sync route with id: debugRUUS0G:debugQNJ5BE
2022-04-28 22:43:07,923 PUT /sync route with id: debugRUUS0G:debugQNJ5BE
2022-04-28 22:43:07,925 Accessing /inexp
2022-04-28 22:43:08,004 saved data for debugRUUS0G:debugQNJ5BE (current trial: 115)
2022-04-28 22:43:20,531 PUT /sync route with id: debugRUUS0G:debugQNJ5BE
2022-04-28 22:43:20,562 saved data for debugRUUS0G:debugQNJ5BE (current trial: 118)
2022-04-28 22:48:54,637 Accessing /exp: debugPG5USK debugQNJ5BE debugRUUS0G 
2022-04-28 22:49:18,814 Accessing /exp: debugPG5USK debugQNJ5BE debugRUUS0G 
2022-04-28 22:49:19,761 GET /sync route with id: debugRUUS0G:debugQNJ5BE
2022-04-28 22:49:21,955 Accessing /inexp
2022-04-28 22:49:21,955 PUT /sync route with id: debugRUUS0G:debugQNJ5BE
2022-04-28 22:49:22,099 saved data for debugRUUS0G:debugQNJ5BE (current trial: 120)
2022-04-28 22:50:49,833 Accessing /exp: debugPG5USK debugQNJ5BE debugRUUS0G 
2022-04-28 22:50:50,248 GET /sync route with id: debugRUUS0G:debugQNJ5BE
2022-04-28 22:50:52,125 PUT /sync route with id: debugRUUS0G:debugQNJ5BE
2022-04-28 22:50:52,161 saved data for debugRUUS0G:debugQNJ5BE (current trial: 122)
2022-04-28 22:50:52,173 Accessing /inexp
2022-04-28 22:51:07,961 PUT /sync route with id: debugRUUS0G:debugQNJ5BE
2022-04-28 22:51:08,062 saved data for debugRUUS0G:debugQNJ5BE (current trial: 166)
2022-04-28 22:59:17,965 Accessing /exp: debugPG5USK debugQNJ5BE debugRUUS0G 
2022-04-28 22:59:18,343 GET /sync route with id: debugRUUS0G:debugQNJ5BE
2022-04-28 22:59:24,935 PUT /sync route with id: debugRUUS0G:debugQNJ5BE
2022-04-28 22:59:24,951 Accessing /inexp
2022-04-28 22:59:24,977 saved data for debugRUUS0G:debugQNJ5BE (current trial: 168)
2022-04-28 23:00:33,193 Accessing /exp: debugPG5USK debugQNJ5BE debugRUUS0G 
2022-04-28 23:00:33,355 GET /sync route with id: debugRUUS0G:debugQNJ5BE
2022-04-28 23:00:34,791 Accessing /inexp
2022-04-28 23:00:34,791 PUT /sync route with id: debugRUUS0G:debugQNJ5BE
2022-04-28 23:00:34,818 saved data for debugRUUS0G:debugQNJ5BE (current trial: 170)
2022-04-28 23:00:37,408 Accessing /exp: debugPG5USK debugQNJ5BE debugRUUS0G 
2022-04-28 23:00:37,590 GET /sync route with id: debugRUUS0G:debugQNJ5BE
2022-04-28 23:00:38,489 Accessing /inexp
2022-04-28 23:00:38,489 PUT /sync route with id: debugRUUS0G:debugQNJ5BE
2022-04-28 23:00:38,539 saved data for debugRUUS0G:debugQNJ5BE (current trial: 172)
2022-04-28 23:00:39,337 Accessing /exp: debugPG5USK debugQNJ5BE debugRUUS0G 
2022-04-28 23:00:39,508 GET /sync route with id: debugRUUS0G:debugQNJ5BE
2022-04-28 23:02:08,611 Accessing /exp: debugPG5USK debugQNJ5BE debugRUUS0G 
2022-04-28 23:02:09,029 GET /sync route with id: debugRUUS0G:debugQNJ5BE
2022-04-28 23:02:11,332 PUT /sync route with id: debugRUUS0G:debugQNJ5BE
2022-04-28 23:02:11,332 Accessing /inexp
2022-04-28 23:02:11,380 saved data for debugRUUS0G:debugQNJ5BE (current trial: 174)
2022-04-28 23:02:18,653 Accessing /exp: debugPG5USK debugQNJ5BE debugRUUS0G 
2022-04-28 23:02:18,854 GET /sync route with id: debugRUUS0G:debugQNJ5BE
2022-04-28 23:02:20,465 PUT /sync route with id: debugRUUS0G:debugQNJ5BE
2022-04-28 23:02:20,465 Accessing /inexp
2022-04-28 23:02:20,494 saved data for debugRUUS0G:debugQNJ5BE (current trial: 176)
2022-04-28 23:02:21,263 Accessing /exp: debugPG5USK debugQNJ5BE debugRUUS0G 
2022-04-28 23:02:21,363 GET /sync route with id: debugRUUS0G:debugQNJ5BE
2022-04-28 23:02:29,536 Accessing /exp: debugPG5USK debugQNJ5BE debugRUUS0G 
2022-04-28 23:02:29,832 GET /sync route with id: debugRUUS0G:debugQNJ5BE
2022-04-28 23:02:31,179 PUT /sync route with id: debugRUUS0G:debugQNJ5BE
2022-04-28 23:02:31,211 saved data for debugRUUS0G:debugQNJ5BE (current trial: 178)
2022-04-28 23:02:31,220 Accessing /inexp
2022-04-28 23:02:32,630 Accessing /exp: debugPG5USK debugQNJ5BE debugRUUS0G 
2022-04-28 23:02:32,957 GET /sync route with id: debugRUUS0G:debugQNJ5BE
2022-04-28 23:06:29,313 Accessing /exp: debugPG5USK debugQNJ5BE debugRUUS0G 
2022-04-28 23:06:29,472 GET /sync route with id: debugRUUS0G:debugQNJ5BE
2022-04-28 23:06:40,774 PUT /sync route with id: debugRUUS0G:debugQNJ5BE
2022-04-28 23:06:40,843 saved data for debugRUUS0G:debugQNJ5BE (current trial: 181)
2022-04-28 23:15:00,428 Accessing /exp: debugPG5USK debugQNJ5BE debugRUUS0G 
2022-04-28 23:15:00,662 GET /sync route with id: debugRUUS0G:debugQNJ5BE
2022-04-28 23:15:11,648 PUT /sync route with id: debugRUUS0G:debugQNJ5BE
2022-04-28 23:15:11,700 saved data for debugRUUS0G:debugQNJ5BE (current trial: 184)
2022-04-28 23:15:17,114 PUT /sync route with id: debugRUUS0G:debugQNJ5BE
2022-04-28 23:15:17,153 saved data for debugRUUS0G:debugQNJ5BE (current trial: 185)
2022-04-28 23:15:45,840 Accessing /exp: debugPG5USK debugQNJ5BE debugRUUS0G 
2022-04-28 23:15:46,853 GET /sync route with id: debugRUUS0G:debugQNJ5BE
2022-04-28 23:15:56,145 PUT /sync route with id: debugRUUS0G:debugQNJ5BE
2022-04-28 23:15:56,268 saved data for debugRUUS0G:debugQNJ5BE (current trial: 188)
2022-04-28 23:15:57,574 PUT /sync route with id: debugRUUS0G:debugQNJ5BE
2022-04-28 23:15:57,670 saved data for debugRUUS0G:debugQNJ5BE (current trial: 189)
2022-04-28 23:15:58,747 PUT /sync route with id: debugRUUS0G:debugQNJ5BE
2022-04-28 23:15:58,855 saved data for debugRUUS0G:debugQNJ5BE (current trial: 190)
2022-04-28 23:15:59,158 PUT /sync route with id: debugRUUS0G:debugQNJ5BE
2022-04-28 23:15:59,326 saved data for debugRUUS0G:debugQNJ5BE (current trial: 191)
2022-04-28 23:15:59,426 PUT /sync route with id: debugRUUS0G:debugQNJ5BE
2022-04-28 23:15:59,818 saved data for debugRUUS0G:debugQNJ5BE (current trial: 192)
[2022-04-28 23:20:32 +0800] [11554] [INFO] Handling signal: term
[2022-04-28 23:20:32 +0800] [11562] [INFO] Worker exiting (pid: 11562)
[2022-04-28 23:20:32 +0800] [11557] [INFO] Worker exiting (pid: 11557)
[2022-04-28 23:20:32 +0800] [11565] [INFO] Worker exiting (pid: 11565)
[2022-04-28 23:20:32 +0800] [11560] [INFO] Worker exiting (pid: 11560)
[2022-04-28 23:20:32 +0800] [11559] [INFO] Worker exiting (pid: 11559)
[2022-04-28 23:20:32 +0800] [11561] [INFO] Worker exiting (pid: 11561)
[2022-04-28 23:20:32 +0800] [11563] [INFO] Worker exiting (pid: 11563)
[2022-04-28 23:20:32 +0800] [11564] [INFO] Worker exiting (pid: 11564)
[2022-04-28 23:20:32 +0800] [11558] [INFO] Worker exiting (pid: 11558)
[2022-04-28 23:20:34 +0800] [11554] [INFO] Shutting down: Master
[2022-04-28 23:31:34 +0800] [22583] [INFO] Starting gunicorn 20.0.4
[2022-04-28 23:31:34 +0800] [22583] [INFO] Listening at: http://0.0.0.0:50003 (22583)
[2022-04-28 23:31:34 +0800] [22583] [INFO] Using worker: gevent
[2022-04-28 23:31:34 +0800] [22586] [INFO] Booting worker with pid: 22586
[2022-04-28 23:31:34 +0800] [22587] [INFO] Booting worker with pid: 22587
[2022-04-28 23:31:34 +0800] [22588] [INFO] Booting worker with pid: 22588
[2022-04-28 23:31:34 +0800] [22589] [INFO] Booting worker with pid: 22589
[2022-04-28 23:31:34 +0800] [22590] [INFO] Booting worker with pid: 22590
[2022-04-28 23:31:34 +0800] [22591] [INFO] Booting worker with pid: 22591
[2022-04-28 23:31:34 +0800] [22592] [INFO] Booting worker with pid: 22592
[2022-04-28 23:31:34 +0800] [22593] [INFO] Booting worker with pid: 22593
[2022-04-28 23:31:34 +0800] [22594] [INFO] Booting worker with pid: 22594
2022-04-28 23:31:38,122 Starting scheduler in 'paused' mode -- it will not run any tasks, but it can be used to create, modify, or delete tasks.
2022-04-28 23:31:38,127 Scheduler started
2022-04-28 23:31:38,129 /Library/Frameworks/Python.framework/Versions/3.6/lib/python3.6/site-packages/psiturk/psiturk_js/psiturk.js
2022-04-28 23:31:38,171 Starting scheduler in 'paused' mode -- it will not run any tasks, but it can be used to create, modify, or delete tasks.
2022-04-28 23:31:38,175 Scheduler started
2022-04-28 23:31:38,178 /Library/Frameworks/Python.framework/Versions/3.6/lib/python3.6/site-packages/psiturk/psiturk_js/psiturk.js
2022-04-28 23:31:38,485 Starting scheduler in 'paused' mode -- it will not run any tasks, but it can be used to create, modify, or delete tasks.
2022-04-28 23:31:38,539 Scheduler started
2022-04-28 23:31:38,541 /Library/Frameworks/Python.framework/Versions/3.6/lib/python3.6/site-packages/psiturk/psiturk_js/psiturk.js
2022-04-28 23:31:39,036 Starting scheduler in 'paused' mode -- it will not run any tasks, but it can be used to create, modify, or delete tasks.
2022-04-28 23:31:39,041 Scheduler started
2022-04-28 23:31:39,042 /Library/Frameworks/Python.framework/Versions/3.6/lib/python3.6/site-packages/psiturk/psiturk_js/psiturk.js
2022-04-28 23:31:39,078 Starting scheduler in 'paused' mode -- it will not run any tasks, but it can be used to create, modify, or delete tasks.
2022-04-28 23:31:39,084 Starting scheduler in 'paused' mode -- it will not run any tasks, but it can be used to create, modify, or delete tasks.
2022-04-28 23:31:39,084 Starting scheduler in 'paused' mode -- it will not run any tasks, but it can be used to create, modify, or delete tasks.
2022-04-28 23:31:39,087 Scheduler started
2022-04-28 23:31:39,088 Scheduler started
2022-04-28 23:31:39,089 /Library/Frameworks/Python.framework/Versions/3.6/lib/python3.6/site-packages/psiturk/psiturk_js/psiturk.js
2022-04-28 23:31:39,091 /Library/Frameworks/Python.framework/Versions/3.6/lib/python3.6/site-packages/psiturk/psiturk_js/psiturk.js
2022-04-28 23:31:39,099 Scheduler started
2022-04-28 23:31:39,104 /Library/Frameworks/Python.framework/Versions/3.6/lib/python3.6/site-packages/psiturk/psiturk_js/psiturk.js
2022-04-28 23:31:39,124 Starting scheduler in 'paused' mode -- it will not run any tasks, but it can be used to create, modify, or delete tasks.
2022-04-28 23:31:39,130 Scheduler started
2022-04-28 23:31:39,134 /Library/Frameworks/Python.framework/Versions/3.6/lib/python3.6/site-packages/psiturk/psiturk_js/psiturk.js
2022-04-28 23:31:39,181 Starting scheduler in 'paused' mode -- it will not run any tasks, but it can be used to create, modify, or delete tasks.
2022-04-28 23:31:39,184 Scheduler started
2022-04-28 23:31:39,186 /Library/Frameworks/Python.framework/Versions/3.6/lib/python3.6/site-packages/psiturk/psiturk_js/psiturk.js
2022-04-28 23:31:41,668 Accessing /exp: debugQ8IUHB debugFFWFZL debugHHL3NR 
2022-04-28 23:31:41,673 given Counter({(0, 0): 0}) chose (0, 0)
2022-04-28 23:31:41,905 GET /sync route with id: debugHHL3NR:debugFFWFZL
[2022-04-29 01:16:50 +0800] [22583] [INFO] Handling signal: winch
[2022-04-29 01:46:52 +0800] [10463] [CRITICAL] WORKER TIMEOUT (pid:10466)
[2022-04-29 01:46:52 +0800] [10463] [CRITICAL] WORKER TIMEOUT (pid:10471)
[2022-04-29 01:46:52 +0800] [10463] [CRITICAL] WORKER TIMEOUT (pid:10474)
[2022-04-29 01:46:52 +0800] [10463] [CRITICAL] WORKER TIMEOUT (pid:88119)
[2022-04-29 01:46:52 +0800] [10463] [CRITICAL] WORKER TIMEOUT (pid:88120)
[2022-04-29 01:46:52 +0800] [10463] [CRITICAL] WORKER TIMEOUT (pid:19368)
[2022-04-29 01:46:52 +0800] [22583] [CRITICAL] WORKER TIMEOUT (pid:22586)
[2022-04-29 01:46:52 +0800] [22586] [INFO] Worker exiting (pid: 22586)
[2022-04-29 01:46:57 +0800] [34329] [INFO] Booting worker with pid: 34329
2022-04-29 01:47:03,444 Starting scheduler in 'paused' mode -- it will not run any tasks, but it can be used to create, modify, or delete tasks.
2022-04-29 01:47:03,445 Starting scheduler in 'paused' mode -- it will not run any tasks, but it can be used to create, modify, or delete tasks.
2022-04-29 01:47:03,455 Scheduler started
2022-04-29 01:47:03,455 Scheduler started
2022-04-29 01:47:03,458 /Library/Frameworks/Python.framework/Versions/3.6/lib/python3.6/site-packages/psiturk/psiturk_js/psiturk.js
2022-04-29 01:47:03,459 /Library/Frameworks/Python.framework/Versions/3.6/lib/python3.6/site-packages/psiturk/psiturk_js/psiturk.js
2022-04-29 01:47:03,499 Starting scheduler in 'paused' mode -- it will not run any tasks, but it can be used to create, modify, or delete tasks.
2022-04-29 01:47:03,503 Scheduler started
2022-04-29 01:47:03,507 /Library/Frameworks/Python.framework/Versions/3.6/lib/python3.6/site-packages/psiturk/psiturk_js/psiturk.js
2022-04-29 01:47:03,551 Starting scheduler in 'paused' mode -- it will not run any tasks, but it can be used to create, modify, or delete tasks.
2022-04-29 01:47:03,555 Scheduler started
2022-04-29 01:47:03,558 Starting scheduler in 'paused' mode -- it will not run any tasks, but it can be used to create, modify, or delete tasks.
2022-04-29 01:47:03,568 Scheduler started
2022-04-29 01:47:03,558 /Library/Frameworks/Python.framework/Versions/3.6/lib/python3.6/site-packages/psiturk/psiturk_js/psiturk.js
2022-04-29 01:47:03,575 Starting scheduler in 'paused' mode -- it will not run any tasks, but it can be used to create, modify, or delete tasks.
2022-04-29 01:47:03,577 /Library/Frameworks/Python.framework/Versions/3.6/lib/python3.6/site-packages/psiturk/psiturk_js/psiturk.js
2022-04-29 01:47:03,579 Scheduler started
2022-04-29 01:47:03,580 /Library/Frameworks/Python.framework/Versions/3.6/lib/python3.6/site-packages/psiturk/psiturk_js/psiturk.js
2022-04-29 01:47:03,831 Starting scheduler in 'paused' mode -- it will not run any tasks, but it can be used to create, modify, or delete tasks.
2022-04-29 01:47:03,840 Scheduler started
2022-04-29 01:47:03,843 /Library/Frameworks/Python.framework/Versions/3.6/lib/python3.6/site-packages/psiturk/psiturk_js/psiturk.js
[2022-04-29 02:28:04 +0800] [22583] [INFO] Handling signal: winch
2022-04-29 02:29:44,906 Accessing /exp: debugQ8IUHB debugFFWFZL debugHHL3NR 
2022-04-29 02:29:45,329 GET /sync route with id: debugHHL3NR:debugFFWFZL
2022-04-29 02:32:33,632 Accessing /exp: debugQ8IUHB debugFFWFZL debugHHL3NR 
2022-04-29 02:32:33,966 GET /sync route with id: debugHHL3NR:debugFFWFZL
2022-04-29 02:33:17,481 Accessing /exp: debugQ8IUHB debugFFWFZL debugHHL3NR 
2022-04-29 02:33:18,037 GET /sync route with id: debugHHL3NR:debugFFWFZL
2022-04-29 02:34:07,111 Accessing /exp: debugQ8IUHB debugFFWFZL debugHHL3NR 
2022-04-29 02:34:07,493 GET /sync route with id: debugHHL3NR:debugFFWFZL
2022-04-29 02:34:22,492 Accessing /exp: debugQ8IUHB debugFFWFZL debugHHL3NR 
2022-04-29 02:34:22,956 GET /sync route with id: debugHHL3NR:debugFFWFZL
2022-04-29 02:34:53,395 Accessing /exp: debugQ8IUHB debugFFWFZL debugHHL3NR 
2022-04-29 02:34:53,743 GET /sync route with id: debugHHL3NR:debugFFWFZL
2022-04-29 02:34:58,099 PUT /sync route with id: debugHHL3NR:debugFFWFZL
2022-04-29 02:34:58,144 saved data for debugHHL3NR:debugFFWFZL (current trial: 1)
2022-04-29 02:35:28,416 Submitted experiment for debugHHL3NR:debugFFWFZL
2022-04-29 02:35:45,142 Accessing /exp: debug6KW1XM debugHFDSYU debugS3RAUT 
2022-04-29 02:35:45,165 given Counter({(0, 0): 1}) chose (0, 0)
2022-04-29 02:35:45,326 GET /sync route with id: debugS3RAUT:debugHFDSYU
2022-04-29 02:35:52,700 PUT /sync route with id: debugS3RAUT:debugHFDSYU
2022-04-29 02:35:52,723 saved data for debugS3RAUT:debugHFDSYU (current trial: 1)
2022-04-29 02:39:51,759 Accessing /exp: debug6KW1XM debugHFDSYU debugS3RAUT 
2022-04-29 02:40:12,270 Accessing /exp: debug6KW1XM debugHFDSYU debugS3RAUT 
2022-04-29 02:40:25,093 Accessing /exp: debug6KW1XM debugHFDSYU debugS3RAUT 
2022-04-29 02:40:25,508 GET /sync route with id: debugS3RAUT:debugHFDSYU
2022-04-29 02:40:32,681 PUT /sync route with id: debugS3RAUT:debugHFDSYU
2022-04-29 02:40:32,768 saved data for debugS3RAUT:debugHFDSYU (current trial: 4)
2022-04-29 02:41:04,528 Accessing /exp: debug6KW1XM debugHFDSYU debugS3RAUT 
2022-04-29 02:41:04,957 GET /sync route with id: debugS3RAUT:debugHFDSYU
2022-04-29 02:41:11,363 PUT /sync route with id: debugS3RAUT:debugHFDSYU
2022-04-29 02:41:11,381 saved data for debugS3RAUT:debugHFDSYU (current trial: 7)
2022-04-29 02:41:12,510 PUT /sync route with id: debugS3RAUT:debugHFDSYU
2022-04-29 02:41:12,521 saved data for debugS3RAUT:debugHFDSYU (current trial: 8)
2022-04-29 02:41:20,591 Accessing /exp: debug6KW1XM debugHFDSYU debugS3RAUT 
2022-04-29 02:41:21,041 GET /sync route with id: debugS3RAUT:debugHFDSYU
2022-04-29 02:41:27,441 PUT /sync route with id: debugS3RAUT:debugHFDSYU
2022-04-29 02:41:27,454 saved data for debugS3RAUT:debugHFDSYU (current trial: 11)
2022-04-29 02:41:28,411 PUT /sync route with id: debugS3RAUT:debugHFDSYU
2022-04-29 02:41:28,439 saved data for debugS3RAUT:debugHFDSYU (current trial: 12)
2022-04-29 02:42:53,955 Accessing /exp: debug6KW1XM debugHFDSYU debugS3RAUT 
2022-04-29 02:42:54,678 GET /sync route with id: debugS3RAUT:debugHFDSYU
2022-04-29 02:42:55,119 Accessing /exp: debug6KW1XM debugHFDSYU debugS3RAUT 
2022-04-29 02:42:56,231 GET /sync route with id: debugS3RAUT:debugHFDSYU
2022-04-29 02:43:02,649 PUT /sync route with id: debugS3RAUT:debugHFDSYU
2022-04-29 02:43:02,729 saved data for debugS3RAUT:debugHFDSYU (current trial: 15)
2022-04-29 02:43:03,754 PUT /sync route with id: debugS3RAUT:debugHFDSYU
2022-04-29 02:43:03,767 saved data for debugS3RAUT:debugHFDSYU (current trial: 16)
2022-04-29 02:43:03,951 PUT /sync route with id: debugS3RAUT:debugHFDSYU
2022-04-29 02:43:03,992 saved data for debugS3RAUT:debugHFDSYU (current trial: 17)
2022-04-29 02:43:04,164 PUT /sync route with id: debugS3RAUT:debugHFDSYU
2022-04-29 02:43:04,200 saved data for debugS3RAUT:debugHFDSYU (current trial: 18)
2022-04-29 02:43:29,475 PUT /sync route with id: debugS3RAUT:debugHFDSYU
2022-04-29 02:43:29,512 saved data for debugS3RAUT:debugHFDSYU (current trial: 19)
2022-04-29 02:43:45,986 Accessing /exp: debug6KW1XM debugHFDSYU debugS3RAUT 
2022-04-29 02:43:46,547 GET /sync route with id: debugS3RAUT:debugHFDSYU
2022-04-29 02:43:53,764 Accessing /exp: debug6KW1XM debugHFDSYU debugS3RAUT 
2022-04-29 02:43:54,037 GET /sync route with id: debugS3RAUT:debugHFDSYU
2022-04-29 02:44:34,342 Accessing /exp: debug6KW1XM debugHFDSYU debugS3RAUT 
2022-04-29 02:44:34,827 GET /sync route with id: debugS3RAUT:debugHFDSYU
2022-04-29 02:45:09,087 Accessing /exp: debug6KW1XM debugHFDSYU debugS3RAUT 
2022-04-29 02:45:09,458 GET /sync route with id: debugS3RAUT:debugHFDSYU
2022-04-29 02:45:14,844 PUT /sync route with id: debugS3RAUT:debugHFDSYU
2022-04-29 02:45:14,858 saved data for debugS3RAUT:debugHFDSYU (current trial: 22)
[2022-04-29 02:45:26 +0800] [22583] [INFO] Handling signal: term
[2022-04-29 02:45:27 +0800] [22590] [INFO] Worker exiting (pid: 22590)
[2022-04-29 02:45:27 +0800] [22592] [INFO] Worker exiting (pid: 22592)
[2022-04-29 02:45:27 +0800] [22588] [INFO] Worker exiting (pid: 22588)
[2022-04-29 02:45:27 +0800] [22589] [INFO] Worker exiting (pid: 22589)
[2022-04-29 02:45:27 +0800] [22587] [INFO] Worker exiting (pid: 22587)
[2022-04-29 02:45:27 +0800] [22594] [INFO] Worker exiting (pid: 22594)
[2022-04-29 02:45:27 +0800] [22591] [INFO] Worker exiting (pid: 22591)
[2022-04-29 02:45:27 +0800] [22593] [INFO] Worker exiting (pid: 22593)
[2022-04-29 02:45:27 +0800] [34329] [INFO] Worker exiting (pid: 34329)
[2022-04-29 02:45:28 +0800] [22583] [INFO] Shutting down: Master
[2022-04-29 04:48:22 +0800] [10463] [CRITICAL] WORKER TIMEOUT (pid:34312)
2022-04-29 04:48:33,657 Starting scheduler in 'paused' mode -- it will not run any tasks, but it can be used to create, modify, or delete tasks.
2022-04-29 04:48:33,665 Scheduler started
2022-04-29 04:48:33,667 /Library/Frameworks/Python.framework/Versions/3.6/lib/python3.6/site-packages/psiturk/psiturk_js/psiturk.js
[2022-04-29 14:24:00 +0800] [18923] [INFO] Starting gunicorn 20.0.4
[2022-04-29 14:24:00 +0800] [18923] [INFO] Listening at: http://0.0.0.0:50003 (18923)
[2022-04-29 14:24:00 +0800] [18923] [INFO] Using worker: gevent
[2022-04-29 14:24:00 +0800] [18931] [INFO] Booting worker with pid: 18931
[2022-04-29 14:24:00 +0800] [18932] [INFO] Booting worker with pid: 18932
[2022-04-29 14:24:01 +0800] [18933] [INFO] Booting worker with pid: 18933
[2022-04-29 14:24:01 +0800] [18934] [INFO] Booting worker with pid: 18934
[2022-04-29 14:24:01 +0800] [18935] [INFO] Booting worker with pid: 18935
[2022-04-29 14:24:01 +0800] [18936] [INFO] Booting worker with pid: 18936
[2022-04-29 14:24:01 +0800] [18937] [INFO] Booting worker with pid: 18937
[2022-04-29 14:24:01 +0800] [18938] [INFO] Booting worker with pid: 18938
[2022-04-29 14:24:01 +0800] [18939] [INFO] Booting worker with pid: 18939
2022-04-29 14:24:03,844 Starting scheduler in 'paused' mode -- it will not run any tasks, but it can be used to create, modify, or delete tasks.
2022-04-29 14:24:03,848 Scheduler started
2022-04-29 14:24:03,850 /Library/Frameworks/Python.framework/Versions/3.6/lib/python3.6/site-packages/psiturk/psiturk_js/psiturk.js
2022-04-29 14:24:04,288 Starting scheduler in 'paused' mode -- it will not run any tasks, but it can be used to create, modify, or delete tasks.
2022-04-29 14:24:04,295 Scheduler started
2022-04-29 14:24:04,297 /Library/Frameworks/Python.framework/Versions/3.6/lib/python3.6/site-packages/psiturk/psiturk_js/psiturk.js
2022-04-29 14:24:05,302 Starting scheduler in 'paused' mode -- it will not run any tasks, but it can be used to create, modify, or delete tasks.
2022-04-29 14:24:05,305 Scheduler started
2022-04-29 14:24:05,307 /Library/Frameworks/Python.framework/Versions/3.6/lib/python3.6/site-packages/psiturk/psiturk_js/psiturk.js
2022-04-29 14:24:05,537 Starting scheduler in 'paused' mode -- it will not run any tasks, but it can be used to create, modify, or delete tasks.
2022-04-29 14:24:05,541 Scheduler started
2022-04-29 14:24:05,563 /Library/Frameworks/Python.framework/Versions/3.6/lib/python3.6/site-packages/psiturk/psiturk_js/psiturk.js
2022-04-29 14:24:05,900 Starting scheduler in 'paused' mode -- it will not run any tasks, but it can be used to create, modify, or delete tasks.
2022-04-29 14:24:05,906 Starting scheduler in 'paused' mode -- it will not run any tasks, but it can be used to create, modify, or delete tasks.
2022-04-29 14:24:05,906 Scheduler started
2022-04-29 14:24:05,909 /Library/Frameworks/Python.framework/Versions/3.6/lib/python3.6/site-packages/psiturk/psiturk_js/psiturk.js
2022-04-29 14:24:05,929 Starting scheduler in 'paused' mode -- it will not run any tasks, but it can be used to create, modify, or delete tasks.
2022-04-29 14:24:05,940 Scheduler started
2022-04-29 14:24:05,940 Scheduler started
2022-04-29 14:24:05,944 /Library/Frameworks/Python.framework/Versions/3.6/lib/python3.6/site-packages/psiturk/psiturk_js/psiturk.js
2022-04-29 14:24:05,952 /Library/Frameworks/Python.framework/Versions/3.6/lib/python3.6/site-packages/psiturk/psiturk_js/psiturk.js
2022-04-29 14:24:06,154 Starting scheduler in 'paused' mode -- it will not run any tasks, but it can be used to create, modify, or delete tasks.
2022-04-29 14:24:06,166 Scheduler started
2022-04-29 14:24:06,169 /Library/Frameworks/Python.framework/Versions/3.6/lib/python3.6/site-packages/psiturk/psiturk_js/psiturk.js
2022-04-29 14:24:06,241 Starting scheduler in 'paused' mode -- it will not run any tasks, but it can be used to create, modify, or delete tasks.
2022-04-29 14:24:06,245 Scheduler started
2022-04-29 14:24:06,249 /Library/Frameworks/Python.framework/Versions/3.6/lib/python3.6/site-packages/psiturk/psiturk_js/psiturk.js
2022-04-29 14:24:09,229 Accessing /exp: debugR3J3W5 debugHH8V0B debugRFKZFQ 
2022-04-29 14:24:09,238 given Counter({(0, 0): 2}) chose (0, 0)
2022-04-29 14:24:09,546 GET /sync route with id: debugRFKZFQ:debugHH8V0B
[2022-04-29 14:54:30 +0800] [2543] [INFO] Starting gunicorn 20.0.4
[2022-04-29 14:54:30 +0800] [2543] [INFO] Listening at: http://0.0.0.0:50003 (2543)
[2022-04-29 14:54:30 +0800] [2543] [INFO] Using worker: gevent
[2022-04-29 14:54:30 +0800] [2546] [INFO] Booting worker with pid: 2546
[2022-04-29 14:54:30 +0800] [2547] [INFO] Booting worker with pid: 2547
[2022-04-29 14:54:30 +0800] [2548] [INFO] Booting worker with pid: 2548
[2022-04-29 14:54:30 +0800] [2549] [INFO] Booting worker with pid: 2549
[2022-04-29 14:54:30 +0800] [2550] [INFO] Booting worker with pid: 2550
[2022-04-29 14:54:30 +0800] [2551] [INFO] Booting worker with pid: 2551
[2022-04-29 14:54:30 +0800] [2552] [INFO] Booting worker with pid: 2552
[2022-04-29 14:54:30 +0800] [2553] [INFO] Booting worker with pid: 2553
[2022-04-29 14:54:30 +0800] [2554] [INFO] Booting worker with pid: 2554
2022-04-29 14:54:35,296 Starting scheduler in 'paused' mode -- it will not run any tasks, but it can be used to create, modify, or delete tasks.
2022-04-29 14:54:35,304 Scheduler started
2022-04-29 14:54:35,312 /Library/Frameworks/Python.framework/Versions/3.6/lib/python3.6/site-packages/psiturk/psiturk_js/psiturk.js
2022-04-29 14:54:36,078 Starting scheduler in 'paused' mode -- it will not run any tasks, but it can be used to create, modify, or delete tasks.
2022-04-29 14:54:36,084 Scheduler started
2022-04-29 14:54:36,088 /Library/Frameworks/Python.framework/Versions/3.6/lib/python3.6/site-packages/psiturk/psiturk_js/psiturk.js
2022-04-29 14:54:36,198 Starting scheduler in 'paused' mode -- it will not run any tasks, but it can be used to create, modify, or delete tasks.
2022-04-29 14:54:36,211 Scheduler started
2022-04-29 14:54:36,226 /Library/Frameworks/Python.framework/Versions/3.6/lib/python3.6/site-packages/psiturk/psiturk_js/psiturk.js
2022-04-29 14:54:36,233 Starting scheduler in 'paused' mode -- it will not run any tasks, but it can be used to create, modify, or delete tasks.
2022-04-29 14:54:36,244 Scheduler started
2022-04-29 14:54:36,253 /Library/Frameworks/Python.framework/Versions/3.6/lib/python3.6/site-packages/psiturk/psiturk_js/psiturk.js
2022-04-29 14:54:36,345 Starting scheduler in 'paused' mode -- it will not run any tasks, but it can be used to create, modify, or delete tasks.
2022-04-29 14:54:36,432 Starting scheduler in 'paused' mode -- it will not run any tasks, but it can be used to create, modify, or delete tasks.
2022-04-29 14:54:36,446 Scheduler started
2022-04-29 14:54:36,458 /Library/Frameworks/Python.framework/Versions/3.6/lib/python3.6/site-packages/psiturk/psiturk_js/psiturk.js
2022-04-29 14:54:36,486 Scheduler started
2022-04-29 14:54:36,499 /Library/Frameworks/Python.framework/Versions/3.6/lib/python3.6/site-packages/psiturk/psiturk_js/psiturk.js
2022-04-29 14:54:36,570 Starting scheduler in 'paused' mode -- it will not run any tasks, but it can be used to create, modify, or delete tasks.
2022-04-29 14:54:36,576 Scheduler started
2022-04-29 14:54:36,580 /Library/Frameworks/Python.framework/Versions/3.6/lib/python3.6/site-packages/psiturk/psiturk_js/psiturk.js
2022-04-29 14:54:36,633 Starting scheduler in 'paused' mode -- it will not run any tasks, but it can be used to create, modify, or delete tasks.
2022-04-29 14:54:36,642 Scheduler started
2022-04-29 14:54:36,645 /Library/Frameworks/Python.framework/Versions/3.6/lib/python3.6/site-packages/psiturk/psiturk_js/psiturk.js
2022-04-29 14:54:36,663 Starting scheduler in 'paused' mode -- it will not run any tasks, but it can be used to create, modify, or delete tasks.
2022-04-29 14:54:36,672 Scheduler started
2022-04-29 14:54:36,676 /Library/Frameworks/Python.framework/Versions/3.6/lib/python3.6/site-packages/psiturk/psiturk_js/psiturk.js
2022-04-29 14:54:58,639 Accessing /exp: debugLJAEPX debug6ARTEH debugVBXYR7 
2022-04-29 14:54:58,652 given Counter({(0, 0): 2}) chose (0, 0)
2022-04-29 14:54:58,877 GET /sync route with id: debugVBXYR7:debug6ARTEH
2022-04-29 14:55:30,196 PUT /sync route with id: debugVBXYR7:debug6ARTEH
2022-04-29 14:55:30,211 saved data for debugVBXYR7:debug6ARTEH (current trial: 3)
[2022-04-29 15:47:28 +0800] [2543] [INFO] Handling signal: winch
